Workbook

Sheet ReadMe
B2: Model by: | C2: Jay Prakash
B3: Website: | C3: https://jay-finance.github.io/portfolio/

Sheet ERPcalc
B2: ERP Estimation for Rated Countries
B4: Mature Market | C4: United States
B5: Implied ERP of S&P 500 | C5: 0.04 | D5: < Enter the implied ERP of the US.
B6: Country Risk Premium | C6: =VLOOKUP(C4,'ERPsCRPs&Spreads'!$B$8:$K$164,9,FALSE) -> 0.0099868735
B7: Mature Market ERP | C7: =C5-C6 -> 0.030013127
B9: Country | C9: India | D9: < select the country of which you to the ERP of.
B10: Country Rating | C10: =VLOOKUP(C9,'ERPsCRPs&Spreads'!$B$8:$D$164,3,FALSE) -> Baa3
B11: Country Default Spread (Rating-Based) | C11: =VLOOKUP(C9,'ERPsCRPs&Spreads'!$B$8:$K$164,4,FALSE) -> 0.021767594
B12: Country Default Spread (CDS Net of Switzerland) | C12: =VLOOKUP(C9,'ERPsCRPs&Spreads'!$B$8:$K$164,8,FALSE) -> 0.0067
B13: Country Risk Premium 2 (Rating) | C13: =IFERROR(VLOOKUP(ERPcalc!$C$9,'ERPsCRPs&Spreads'!$B$8:$K$164,6,FALSE),"NA") -> 0.065875822
B14: Country Risk Premium 1 (CDS) | C14: =IFERROR(VLOOKUP(ERPcalc!$C$9,'ERPsCRPs&Spreads'!$B$8:$K$164,9,FALSE),"NA") -> 0.02027638
B16: Equity Risk Premium 3 (Default Spread) | C16: =C5+C11 -> 0.061767594
B17: Equity Risk Premium 2 (CRP on Ratings) | C17: =C5+C13 -> 0.10587582
B18: Equity Risk Premium 1 (CRP on CDS) | C18: =IFERROR(C5+C14,"NA") -> 0.06027638 | D18: =IF(C18="NA","< "&C9&" does not have a CDS spread use ERP 1 or 2","")
B20: ERP Estimation for continents
B22: Region | C22: Asia | D22: < select the continent of which you to the ERP of.
B24: GDP | C24: =VLOOKUP($C$22,RegionalERP!$B$14:$F$17,2,FALSE) -> 34857584
B25: Country Risk Premium | C25: =VLOOKUP($C$22,RegionalERP!$B$14:$F$17,3,FALSE) -> 0.022846338
B26: Equity Risk Premium | C26: =VLOOKUP($C$22,RegionalERP!$B$14:$F$17,4,FALSE) -> 0.052859465
B28: ERP Estimation for Frontier Countries (Not Rated)
B30: Country | C30: Haiti | D30: < select the continent of which you to the ERP of.
B31: PRS Score | C31: =VLOOKUP(C30,'ERPsCRPs&Spreads'!$B$169:$I$189,3,FALSE) -> 54.75
B33: Default Spread (PRS) | C33: =VLOOKUP(C30,'ERPsCRPs&Spreads'!$B$169:$I$189,5,FALSE) -> 0.11884874
B34: Country Risk Premium (PRS) | C34: =VLOOKUP(C30,'ERPsCRPs&Spreads'!$B$169:$I$189,7,FALSE) -> 0.35967494
B35: Equity Risk Premium (PRS) | C35: =C5+C34 -> 0.39967494

Sheet RelativeVolatility
B2: Relative Volatility for Equity Markets
B4: Year | C4: Stdev (ACWI) | D4: Stdev (JPM Bond) | E4: Relative Volatility
B6: 2020 | C6: =_xlfn.STDEV.S(D23:D275)*SQRT(253) -> 0.3213956 | D6: =_xlfn.STDEV.S(H23:H274)*SQRT(252) -> 0.068708372 | E6: =C6/D6 -> 4.6776774
B7: 2021 | C7: =_xlfn.STDEV.S(D277:D528)*SQRT(252) -> 0.12656485 | D7: =_xlfn.STDEV.S(H276:H530)*SQRT(255) -> 0.036745396 | E7: =C7/D7 -> 3.444373
B8: 2022 | C8: =_xlfn.STDEV.S(D530:D780)*SQRT(251) -> 0.22780804 | D8: =_xlfn.STDEV.S(H532:H782)*SQRT(251) -> 0.068330013 | E8: =C8/D8 -> 3.3339382
B9: 2023 | C9: =_xlfn.STDEV.S(D782:D1031)*SQRT(250) -> 0.12757646 | D9: =_xlfn.STDEV.S(H784:H1033)*SQRT(250) -> 0.07319222 | E9: =C9/D9 -> 1.7430331
B10: 2024 | C10: =_xlfn.STDEV.S(D1033:D1284)*SQRT(252) -> 0.11947819 | D10: =_xlfn.STDEV.S(H1035:H1284)*SQRT(250) -> 0.05630262 | E10: =C10/D10 -> 2.1220716
B11: 2025 | C11: =_xlfn.STDEV.S(D1286:D1535)*SQRT(250) -> 0.1717051 | D11: =_xlfn.STDEV.S(H1286:H1531)*SQRT(246) -> 0.051144433 | E11: =C11/D11 -> 3.3572588
B12: 2026 | C12: =_xlfn.STDEV.S(D1537:D1612)*SQRT(76) -> 0.090046943 | D12: =_xlfn.STDEV.S(H1533:H1607)*SQRT(75) -> 0.037000559 | E12: =C12/D12 -> 2.4336644
B13: Avg Volatility | C13: =AVERAGE(C6:C12) -> 0.16922503 | D13: =AVERAGE(D6:D12) -> 0.055917659 | E13: =C13/D13 -> 3.0263253
B16: Index: | C16: iShares MSCI ACWI ETF (ACWI) | F16: Index: | G16: JPMorgan Funds - Global Aggregate Bond Fund
B17: Period: | C17: 5 Years (1st Jan 2020 - April 2026) | F17: Period: | G17: 5 Years (1st Jan 2020 - April 2026)
B18: Interval: | C18: Daily | F18: Interval: | G18: Daily
B20: Date | C20: Adj Close | D20: Return | F20: Date | G20: Adj Close | H20: Return
B22: 43830 | C22: 79.25 | F22: 31.12.2019 | G22: 13.54
B23: 43832 | C23: 80.07 | D23: =C23/C22-1 -> 0.010347003 | F23: 02.01.2020 | G23: 13.55 | H23: =G23/G22-1 -> 0.00073855244
B24: 43833 | C24: 79.38 | D24: =C24/C23-1 -> -0.0086174597 | F24: 03.01.2020 | G24: 13.57 | H24: =G24/G23-1 -> 0.0014760148
B25: 43836 | C25: 79.56 | D25: =C25/C24-1 -> 0.0022675737 | F25: 06.01.2020 | G25: 13.6 | H25: =G25/G24-1 -> 0.002210759
B26: 43837 | C26: 79.36 | D26: =C26/C25-1 -> -0.002513826 | F26: 07.01.2020 | G26: 13.55 | H26: =G26/G25-1 -> -0.0036764706
B27: 43838 | C27: 79.75 | D27: =C27/C26-1 -> 0.0049143145 | F27: 08.01.2020 | G27: 13.53 | H27: =G27/G26-1 -> -0.0014760148
B28: 43839 | C28: 80.2 | D28: =C28/C27-1 -> 0.0056426332 | F28: 09.01.2020 | G28: 13.5 | H28: =G28/G27-1 -> -0.0022172949
B29: 43840 | C29: 80.02 | D29: =C29/C28-1 -> -0.002244389 | F29: 10.01.2020 | G29: 13.52 | H29: =G29/G28-1 -> 0.0014814815
B30: 43843 | C30: 80.62 | D30: =C30/C29-1 -> 0.0074981255 | F30: 13.01.2020 | G30: 13.51 | H30: =G30/G29-1 -> -0.00073964497
B31: 43844 | C31: 80.55 | D31: =C31/C30-1 -> -0.0008682709 | F31: 14.01.2020 | G31: 13.52 | H31: =G31/G30-1 -> 0.00074019245
B32: 43845 | C32: 80.5 | D32: =C32/C31-1 -> -0.00062073246 | F32: 15.01.2020 | G32: 13.54 | H32: =G32/G31-1 -> 0.0014792899
B33: 43846 | C33: 81.09 | D33: =C33/C32-1 -> 0.0073291925 | F33: 16.01.2020 | G33: 13.54 | H33: =G33/G32-1 -> 0
B34: 43847 | C34: 81.31 | D34: =C34/C33-1 -> 0.0027130349 | F34: 17.01.2020 | G34: 13.53 | H34: =G34/G33-1 -> -0.00073855244
... B274: 44195 | C274: 90.66 | D274: =C274/C273-1 -> 0.0033200531 | F274: 31.12.2020 | G274: 15.02 | H274: =G274/G273-1 -> 0.00066622252
B275: 44196 | C275: 90.72 | D275: =C275/C274-1 -> 0.00066181337
F276: 04.01.2021 | G276: 15.04 | H276: =G276/G274-1 -> 0.0013315579
B277: 44200 | C277: 90.22 | D277: =C277/C275-1 -> -0.0055114638 | F277: 05.01.2021 | G277: 15.03 | H277: =G277/G276-1 -> -0.00066489362
B278: 44201 | C278: 91.15 | D278: =C278/C277-1 -> 0.010308136 | F278: 06.01.2021 | G278: 15 | H278: =G278/G277-1 -> -0.001996008
B279: 44202 | C279: 91.66 | D279: =C279/C278-1 -> 0.0055951728 | F279: 07.01.2021 | G279: 14.96 | H279: =G279/G278-1 -> -0.0026666667
B280: 44203 | C280: 92.62 | D280: =C280/C279-1 -> 0.010473489 | F280: 08.01.2021 | G280: 14.96 | H280: =G280/G279-1 -> 0
B281: 44204 | C281: 93.44 | D281: =C281/C280-1 -> 0.0088533794 | F281: 11.01.2021 | G281: 14.88 | H281: =G281/G280-1 -> -0.0053475936
B282: 44207 | C282: 92.62 | D282: =C282/C281-1 -> -0.0087756849 | F282: 12.01.2021 | G282: 14.87 | H282: =G282/G281-1 -> -0.00067204301
B283: 44208 | C283: 92.95 | D283: =C283/C282-1 -> 0.0035629454 | F283: 13.01.2021 | G283: 14.9 | H283: =G283/G282-1 -> 0.0020174849
B284: 44209 | C284: 93.01 | D284: =C284/C283-1 -> 0.00064550834 | F284: 14.01.2021 | G284: 14.9 | H284: =G284/G283-1 -> 0
B285: 44210 | C285: 93.15 | D285: =C285/C284-1 -> 0.0015052145 | F285: 15.01.2021 | G285: 14.88 | H285: =G285/G284-1 -> -0.0013422819
B286: 44211 | C286: 92.17 | D286: =C286/C285-1 -> -0.010520666 | F286: 19.01.2021 | G286: 14.89 | H286: =G286/G285-1 -> 0.00067204301
...

Sheet ERPsCRPs&Spreads
B2: Country and Equity Risk Premiums
B3: Current Equity Risk Premium of Mature Market | E3: =ERPcalc!C7 -> 0.030013127
B4: Multiplier to use on Default Spread for estimating Country Risk Premium | E4: =RelativeVolatility!E13 -> 3.0263253 | F4: < Relavtive volatility on equity markets
A7: # | B7: Country | C7: Region | D7: Moody's rating | E7: Rating-based Default Spread | F7: Equity Risk Premium 3 | G7: Country Risk Premium 2 | H7: Equity Risk Premium 2 | I7: CDS, net of Switzerland | J7: Country Risk Premium 1 | K7: Equity Risk Premium 1 | M7: S&P | N7: Moody's | O7: Default Spread
B8: Abu Dhabi | C8: =VLOOKUP(B8,RegionLookup!$B$3:$C$184,2,FALSE) -> Middle East | D8: =VLOOKUP(B8,'Ratings&PRS'!$B$4:$C$160,2,FALSE) -> Aa2 | E8: =VLOOKUP(D8,$N$8:$O$30,2,FALSE)/10000 -> 0.0048889784 | F8: =$E$3+E8 -> 0.034902105 | G8: =E8*$E$4 -> 0.014795639 | H8: =$E$3+G8 -> 0.044808766 | I8: =IFERROR(VLOOKUP(B8,CDS!$B$8:$D$97,3,FALSE),"NA") -> 0.0051 | J8: =IF(I8="NA","NA",$E$4*I8) -> 0.015434259 | K8: =IF(J8="NA","NA",$E$3+J8) -> 0.045447386 | M8: =[1]RatingSpreads!B8 -> AAA | N8: =[1]RatingSpreads!C8 -> Aaa | O8: =[1]RatingSpreads!D8 -> 0
B9: Albania | C9: =VLOOKUP(B9,RegionLookup!$B$3:$C$184,2,FALSE) -> Eastern Europe & Russia | D9: =VLOOKUP(B9,'Ratings&PRS'!$B$4:$C$160,2,FALSE) -> Ba3 | E9: =VLOOKUP(D9,$N$8:$O$30,2,FALSE)/10000 -> 0.0356197 | F9: =$E$3+E9 -> 0.065632826 | G9: =E9*$E$4 -> 0.1077968 | H9: =$E$3+G9 -> 0.13780993 | I9: =IFERROR(VLOOKUP(B9,CDS!$B$8:$D$97,3,FALSE),"NA") -> NA | J9: =IF(I9="NA","NA",$E$4*I9) -> NA | K9: =IF(J9="NA","NA",$E$3+J9) -> NA | M9: =[1]RatingSpreads!B9 -> AA+ | N9: =[1]RatingSpreads!C9 -> Aa1 | O9: =[1]RatingSpreads!D9 -> 39.577444
B10: Andorra (Principality of) | C10: =VLOOKUP(B10,RegionLookup!$B$3:$C$184,2,FALSE) -> Western Europe | D10: =VLOOKUP(B10,'Ratings&PRS'!$B$4:$C$160,2,FALSE) -> Baa1 | E10: =VLOOKUP(D10,$N$8:$O$30,2,FALSE)/10000 -> 0.015830978 | F10: =$E$3+E10 -> 0.045844104 | G10: =E10*$E$4 -> 0.047909689 | H10: =$E$3+G10 -> 0.077922815 | I10: =IFERROR(VLOOKUP(B10,CDS!$B$8:$D$97,3,FALSE),"NA") -> NA | J10: =IF(I10="NA","NA",$E$4*I10) -> NA | K10: =IF(J10="NA","NA",$E$3+J10) -> NA | M10: =[1]RatingSpreads!B10 -> AA | N10: =[1]RatingSpreads!C10 -> Aa2 | O10: =[1]RatingSpreads!D10 -> 48.889784
B11: Angola | C11: =VLOOKUP(B11,RegionLookup!$B$3:$C$184,2,FALSE) -> Africa | D11: =VLOOKUP(B11,'Ratings&PRS'!$B$4:$C$160,2,FALSE) -> B3 | E11: =VLOOKUP(D11,$N$8:$O$30,2,FALSE)/10000 -> 0.064371549 | F11: =$E$3+E11 -> 0.094384676 | G11: =E11*$E$4 -> 0.19480925 | H11: =$E$3+G11 -> 0.22482237 | I11: =IFERROR(VLOOKUP(B11,CDS!$B$8:$D$97,3,FALSE),"NA") -> 0.0699 | J11: =IF(I11="NA","NA",$E$4*I11) -> 0.21154014 | K11: =IF(J11="NA","NA",$E$3+J11) -> 0.24155327 | M11: =[1]RatingSpreads!B11 -> AA- | N11: =[1]RatingSpreads!C11 -> Aa3 | O11: =[1]RatingSpreads!D11 -> 59.366167
B12: Argentina | C12: =VLOOKUP(B12,RegionLookup!$B$3:$C$184,2,FALSE) -> Central and South America | D12: =VLOOKUP(B12,'Ratings&PRS'!$B$4:$C$160,2,FALSE) -> Ca | E12: =VLOOKUP(D12,$N$8:$O$30,2,FALSE)/10000 -> 0.11884874 | F12: =$E$3+E12 -> 0.14886186 | G12: =E12*$E$4 -> 0.35967494 | H12: =$E$3+G12 -> 0.38968807 | I12: =IFERROR(VLOOKUP(B12,CDS!$B$8:$D$97,3,FALSE),"NA") -> 0.082 | J12: =IF(I12="NA","NA",$E$4*I12) -> 0.24815867 | K12: =IF(J12="NA","NA",$E$3+J12) -> 0.2781718 | M12: =[1]RatingSpreads!B12 -> A+ | N12: =[1]RatingSpreads!C12 -> A1 | O12: =[1]RatingSpreads!D12 -> 69.842549
B13: Armenia | C13: =VLOOKUP(B13,RegionLookup!$B$3:$C$184,2,FALSE) -> Eastern Europe & Russia | D13: =VLOOKUP(B13,'Ratings&PRS'!$B$4:$C$160,2,FALSE) -> Ba3 | E13: =VLOOKUP(D13,$N$8:$O$30,2,FALSE)/10000 -> 0.0356197 | F13: =$E$3+E13 -> 0.065632826 | G13: =E13*$E$4 -> 0.1077968 | H13: =$E$3+G13 -> 0.13780993 | I13: =IFERROR(VLOOKUP(B13,CDS!$B$8:$D$97,3,FALSE),"NA") -> NA | J13: =IF(I13="NA","NA",$E$4*I13) -> NA | K13: =IF(J13="NA","NA",$E$3+J13) -> NA | M13: =[1]RatingSpreads!B13 -> A | N13: =[1]RatingSpreads!C13 -> A2 | O13: =[1]RatingSpreads!D13 -> 83.811059
B14: Aruba | C14: =VLOOKUP(B14,RegionLookup!$B$3:$C$184,2,FALSE) -> Caribbean | D14: =VLOOKUP(B14,'Ratings&PRS'!$B$4:$C$160,2,FALSE) -> Baa3 | E14: =VLOOKUP(D14,$N$8:$O$30,2,FALSE)/10000 -> 0.021767594 | F14: =$E$3+E14 -> 0.051780721 | G14: =E14*$E$4 -> 0.065875822 | H14: =$E$3+G14 -> 0.095888948 | I14: =IFERROR(VLOOKUP(B14,CDS!$B$8:$D$97,3,FALSE),"NA") -> NA | J14: =IF(I14="NA","NA",$E$4*I14) -> NA | K14: =IF(J14="NA","NA",$E$3+J14) -> NA | M14: =[1]RatingSpreads!B14 -> A- | N14: =[1]RatingSpreads!C14 -> A3 | O14: =[1]RatingSpreads!D14 -> 118.73233
B15: Australia | C15: =VLOOKUP(B15,RegionLookup!$B$3:$C$184,2,FALSE) -> Australia & New Zealand | D15: =VLOOKUP(B15,'Ratings&PRS'!$B$4:$C$160,2,FALSE) -> Aaa | E15: =VLOOKUP(D15,$N$8:$O$30,2,FALSE)/10000 -> 0 | F15: =$E$3+E15 -> 0.030013127 | G15: =E15*$E$4 -> 0 | H15: =$E$3+G15 -> 0.030013127 | I15: =IFERROR(VLOOKUP(B15,CDS!$B$8:$D$97,3,FALSE),"NA") -> 0.0001 | J15: =IF(I15="NA","NA",$E$4*I15) -> 0.00030263253 | K15: =IF(J15="NA","NA",$E$3+J15) -> 0.030315759 | M15: =[1]RatingSpreads!B15 -> BBB+ | N15: =[1]RatingSpreads!C15 -> Baa1 | O15: =[1]RatingSpreads!D15 -> 158.30978
B16: Austria | C16: =VLOOKUP(B16,RegionLookup!$B$3:$C$184,2,FALSE) -> Western Europe | D16: =VLOOKUP(B16,'Ratings&PRS'!$B$4:$C$160,2,FALSE) -> Aa1 | E16: =VLOOKUP(D16,$N$8:$O$30,2,FALSE)/10000 -> 0.0039577444 | F16: =$E$3+E16 -> 0.033970871 | G16: =E16*$E$4 -> 0.011977422 | H16: =$E$3+G16 -> 0.041990549 | I16: =IFERROR(VLOOKUP(B16,CDS!$B$8:$D$97,3,FALSE),"NA") -> 0.0015 | J16: =IF(I16="NA","NA",$E$4*I16) -> 0.004539488 | K16: =IF(J16="NA","NA",$E$3+J16) -> 0.034552614 | M16: =[1]RatingSpreads!B16 -> BBB | N16: =[1]RatingSpreads!C16 -> Baa2 | O16: =[1]RatingSpreads!D16 -> 188.57488
B17: Azerbaijan | C17: =VLOOKUP(B17,RegionLookup!$B$3:$C$184,2,FALSE) -> Eastern Europe & Russia | D17: =VLOOKUP(B17,'Ratings&PRS'!$B$4:$C$160,2,FALSE) -> Ba1 | E17: =VLOOKUP(D17,$N$8:$O$30,2,FALSE)/10000 -> 0.024794105 | F17: =$E$3+E17 -> 0.054807231 | G17: =E17*$E$4 -> 0.075035027 | H17: =$E$3+G17 -> 0.10504815 | I17: =IFERROR(VLOOKUP(B17,CDS!$B$8:$D$97,3,FALSE),"NA") -> NA | J17: =IF(I17="NA","NA",$E$4*I17) -> NA | K17: =IF(J17="NA","NA",$E$3+J17) -> NA | M17: =[1]RatingSpreads!B17 -> BBB- | N17: =[1]RatingSpreads!C17 -> Baa3 | O17: =[1]RatingSpreads!D17 -> 217.67594
B18: Bahamas | C18: =VLOOKUP(B18,RegionLookup!$B$3:$C$184,2,FALSE) -> Caribbean | D18: =VLOOKUP(B18,'Ratings&PRS'!$B$4:$C$160,2,FALSE) -> B1 | E18: =VLOOKUP(D18,$N$8:$O$30,2,FALSE)/10000 -> 0.044582827 | F18: =$E$3+E18 -> 0.074595954 | G18: =E18*$E$4 -> 0.13492214 | H18: =$E$3+G18 -> 0.16493526 | I18: =IFERROR(VLOOKUP(B18,CDS!$B$8:$D$97,3,FALSE),"NA") -> NA | J18: =IF(I18="NA","NA",$E$4*I18) -> NA | K18: =IF(J18="NA","NA",$E$3+J18) -> NA | M18: =[1]RatingSpreads!B18 -> BB+ | N18: =[1]RatingSpreads!C18 -> Ba1 | O18: =[1]RatingSpreads!D18 -> 247.94105
B19: Bahrain | C19: =VLOOKUP(B19,RegionLookup!$B$3:$C$184,2,FALSE) -> Middle East | D19: =VLOOKUP(B19,'Ratings&PRS'!$B$4:$C$160,2,FALSE) -> B2 | E19: =VLOOKUP(D19,$N$8:$O$30,2,FALSE)/10000 -> 0.054477188 | F19: =$E$3+E19 -> 0.084490315 | G19: =E19*$E$4 -> 0.16486569 | H19: =$E$3+G19 -> 0.19487882 | I19: =IFERROR(VLOOKUP(B19,CDS!$B$8:$D$97,3,FALSE),"NA") -> 0.0262 | J19: =IF(I19="NA","NA",$E$4*I19) -> 0.079289723 | K19: =IF(J19="NA","NA",$E$3+J19) -> 0.10930285 | M19: =[1]RatingSpreads!B19 -> BB | N19: =[1]RatingSpreads!C19 -> Ba2 | O19: =[1]RatingSpreads!D19 -> 297.99488
... B30: Brazil | C30: =VLOOKUP(B30,RegionLookup!$B$3:$C$184,2,FALSE) -> Central and South America | D30: =VLOOKUP(B30,'Ratings&PRS'!$B$4:$C$160,2,FALSE) -> Ba1 | E30: =VLOOKUP(D30,$N$8:$O$30,2,FALSE)/10000 -> 0.024794105 | F30: =$E$3+E30 -> 0.054807231 | G30: =E30*$E$4 -> 0.075035027 | H30: =$E$3+G30 -> 0.10504815 | I30: =IFERROR(VLOOKUP(B30,CDS!$B$8:$D$97,3,FALSE),"NA") -> 0.0238 | J30: =IF(I30="NA","NA",$E$4*I30) -> 0.072026542 | K30: =IF(J30="NA","NA",$E$3+J30) -> 0.10203967 | M30: =[1]RatingSpreads!B30 -> NR | N30: =[1]RatingSpreads!C30 -> NR | O30: =[1]RatingSpreads!D30 -> NA
B31: Bulgaria | C31: =VLOOKUP(B31,RegionLookup!$B$3:$C$184,2,FALSE) -> Eastern Europe & Russia | D31: =VLOOKUP(B31,'Ratings&PRS'!$B$4:$C$160,2,FALSE) -> Baa1 | E31: =VLOOKUP(D31,$N$8:$O$30,2,FALSE)/10000 -> 0.015830978 | F31: =$E$3+E31 -> 0.045844104 | G31: =E31*$E$4 -> 0.047909689 | H31: =$E$3+G31 -> 0.077922815 | I31: =IFERROR(VLOOKUP(B31,CDS!$B$8:$D$97,3,FALSE),"NA") -> 0.0095 | J31: =IF(I31="NA","NA",$E$4*I31) -> 0.02875009 | K31: =IF(J31="NA","NA",$E$3+J31) -> 0.058763217
B32: Burkina Faso | C32: =VLOOKUP(B32,RegionLookup!$B$3:$C$184,2,FALSE) -> Africa | D32: =VLOOKUP(B32,'Ratings&PRS'!$B$4:$C$160,2,FALSE) -> Caa1 | E32: =VLOOKUP(D32,$N$8:$O$30,2,FALSE)/10000 -> 0.07426591 | F32: =$E$3+E32 -> 0.10427904 | G32: =E32*$E$4 -> 0.2247528 | H32: =$E$3+G32 -> 0.25476593 | I32: =IFERROR(VLOOKUP(B32,CDS!$B$8:$D$97,3,FALSE),"NA") -> NA | J32: =IF(I32="NA","NA",$E$4*I32) -> NA | K32: =IF(J32="NA","NA",$E$3+J32) -> NA
B33: Cambodia | C33: =VLOOKUP(B33,RegionLookup!$B$3:$C$184,2,FALSE) -> Asia | D33: =VLOOKUP(B33,'Ratings&PRS'!$B$4:$C$160,2,FALSE) -> B2 | E33: =VLOOKUP(D33,$N$8:$O$30,2,FALSE)/10000 -> 0.054477188 | F33: =$E$3+E33 -> 0.084490315 | G33: =E33*$E$4 -> 0.16486569 | H33: =$E$3+G33 -> 0.19487882 | I33: =IFERROR(VLOOKUP(B33,CDS!$B$8:$D$97,3,FALSE),"NA") -> NA | J33: =IF(I33="NA","NA",$E$4*I33) -> NA | K33: =IF(J33="NA","NA",$E$3+J33) -> NA
B34: Cameroon | C34: =VLOOKUP(B34,RegionLookup!$B$3:$C$184,2,FALSE) -> Africa | D34: =VLOOKUP(B34,'Ratings&PRS'!$B$4:$C$160,2,FALSE) -> Caa1 | E34: =VLOOKUP(D34,$N$8:$O$30,2,FALSE)/10000 -> 0.07426591 | F34: =$E$3+E34 -> 0.10427904 | G34: =E34*$E$4 -> 0.2247528 | H34: =$E$3+G34 -> 0.25476593 | I34: =IFERROR(VLOOKUP(B34,CDS!$B$8:$D$97,3,FALSE),"NA") -> 0.0786 | J34: =IF(I34="NA","NA",$E$4*I34) -> 0.23786917 | K34: =IF(J34="NA","NA",$E$3+J34) -> 0.2678823
B35: Canada | C35: =VLOOKUP(B35,RegionLookup!$B$3:$C$184,2,FALSE) -> North America | D35: =VLOOKUP(B35,'Ratings&PRS'!$B$4:$C$160,2,FALSE) -> Aaa | E35: =VLOOKUP(D35,$N$8:$O$30,2,FALSE)/10000 -> 0 | F35: =$E$3+E35 -> 0.030013127 | G35: =E35*$E$4 -> 0 | H35: =$E$3+G35 -> 0.030013127 | I35: =IFERROR(VLOOKUP(B35,CDS!$B$8:$D$97,3,FALSE),"NA") -> 0.002 | J35: =IF(I35="NA","NA",$E$4*I35) -> 0.0060526506 | K35: =IF(J35="NA","NA",$E$3+J35) -> 0.036065777
B36: Cape Verde | C36: =VLOOKUP(B36,RegionLookup!$B$3:$C$184,2,FALSE) -> Africa | D36: =VLOOKUP(B36,'Ratings&PRS'!$B$4:$C$160,2,FALSE) -> B2 | E36: =VLOOKUP(D36,$N$8:$O$30,2,FALSE)/10000 -> 0.054477188 | F36: =$E$3+E36 -> 0.084490315 | G36: =E36*$E$4 -> 0.16486569 | H36: =$E$3+G36 -> 0.19487882 | I36: =IFERROR(VLOOKUP(B36,CDS!$B$8:$D$97,3,FALSE),"NA") -> NA | J36: =IF(I36="NA","NA",$E$4*I36) -> NA | K36: =IF(J36="NA","NA",$E$3+J36) -> NA
B37: Cayman Islands | C37: =VLOOKUP(B37,RegionLookup!$B$3:$C$184,2,FALSE) -> Caribbean | D37: =VLOOKUP(B37,'Ratings&PRS'!$B$4:$C$160,2,FALSE) -> Aa3 | E37: =VLOOKUP(D37,$N$8:$O$30,2,FALSE)/10000 -> 0.0059366167 | F37: =$E$3+E37 -> 0.035949743 | G37: =E37*$E$4 -> 0.017966133 | H37: =$E$3+G37 -> 0.04797926 | I37: =IFERROR(VLOOKUP(B37,CDS!$B$8:$D$97,3,FALSE),"NA") -> NA | J37: =IF(I37="NA","NA",$E$4*I37) -> NA | K37: =IF(J37="NA","NA",$E$3+J37) -> NA
B38: Chile | C38: =VLOOKUP(B38,RegionLookup!$B$3:$C$184,2,FALSE) -> Central and South America | D38: =VLOOKUP(B38,'Ratings&PRS'!$B$4:$C$160,2,FALSE) -> A2 | E38: =VLOOKUP(D38,$N$8:$O$30,2,FALSE)/10000 -> 0.0083811059 | F38: =$E$3+E38 -> 0.038394232 | G38: =E38*$E$4 -> 0.025363953 | H38: =$E$3+G38 -> 0.055377079 | I38: =IFERROR(VLOOKUP(B38,CDS!$B$8:$D$97,3,FALSE),"NA") -> 0.0087 | J38: =IF(I38="NA","NA",$E$4*I38) -> 0.02632903 | K38: =IF(J38="NA","NA",$E$3+J38) -> 0.056342157
B39: China | C39: =VLOOKUP(B39,RegionLookup!$B$3:$C$184,2,FALSE) -> Asia | D39: =VLOOKUP(B39,'Ratings&PRS'!$B$4:$C$160,2,FALSE) -> A1 | E39: =VLOOKUP(D39,$N$8:$O$30,2,FALSE)/10000 -> 0.0069842549 | F39: =$E$3+E39 -> 0.036997381 | G39: =E39*$E$4 -> 0.021136627 | H39: =$E$3+G39 -> 0.051149754 | I39: =IFERROR(VLOOKUP(B39,CDS!$B$8:$D$97,3,FALSE),"NA") -> 0.0058 | J39: =IF(I39="NA","NA",$E$4*I39) -> 0.017552687 | K39: =IF(J39="NA","NA",$E$3+J39) -> 0.047565813
B40: Colombia | C40: =VLOOKUP(B40,RegionLookup!$B$3:$C$184,2,FALSE) -> Central and South America | D40: =VLOOKUP(B40,'Ratings&PRS'!$B$4:$C$160,2,FALSE) -> Baa2 | E40: =VLOOKUP(D40,$N$8:$O$30,2,FALSE)/10000 -> 0.018857488 | F40: =$E$3+E40 -> 0.048870615 | G40: =E40*$E$4 -> 0.057068894 | H40: =$E$3+G40 -> 0.08708202 | I40: =IFERROR(VLOOKUP(B40,CDS!$B$8:$D$97,3,FALSE),"NA") -> 0.0331 | J40: =IF(I40="NA","NA",$E$4*I40) -> 0.10017137 | K40: =IF(J40="NA","NA",$E$3+J40) -> 0.13018449
B41: Congo (Democratic Republic of) | C41: =VLOOKUP(B41,RegionLookup!$B$3:$C$184,2,FALSE) -> Africa | D41: =VLOOKUP(B41,'Ratings&PRS'!$B$4:$C$160,2,FALSE) -> B3 | E41: =VLOOKUP(D41,$N$8:$O$30,2,FALSE)/10000 -> 0.064371549 | F41: =$E$3+E41 -> 0.094384676 | G41: =E41*$E$4 -> 0.19480925 | H41: =$E$3+G41 -> 0.22482237 | I41: =IFERROR(VLOOKUP(B41,CDS!$B$8:$D$97,3,FALSE),"NA") -> NA | J41: =IF(I41="NA","NA",$E$4*I41) -> NA | K41: =IF(J41="NA","NA",$E$3+J41) -> NA
B42: Congo (Republic of) | C42: =VLOOKUP(B42,RegionLookup!$B$3:$C$184,2,FALSE) -> Africa | D42: =VLOOKUP(B42,'Ratings&PRS'!$B$4:$C$160,2,FALSE) -> Caa2 | E42: =VLOOKUP(D42,$N$8:$O$30,2,FALSE)/10000 -> 0.089165654 | F42: =$E$3+E42 -> 0.11917878 | G42: =E42*$E$4 -> 0.26984428 | H42: =$E$3+G42 -> 0.2998574 | I42: =IFERROR(VLOOKUP(B42,CDS!$B$8:$D$97,3,FALSE),"NA") -> NA | J42: =IF(I42="NA","NA",$E$4*I42) -> NA | K42: =IF(J42="NA","NA",$E$3+J42) -> NA
... B164: Zambia | C164: =VLOOKUP(B164,RegionLookup!$B$3:$C$184,2,FALSE) -> Africa | D164: =VLOOKUP(B164,'Ratings&PRS'!$B$4:$C$160,2,FALSE) -> Caa2 | E164: =VLOOKUP(D164,$N$8:$O$30,2,FALSE)/10000 -> 0.089165654 | F164: =$E$3+E164 -> 0.11917878 | G164: =E164*$E$4 -> 0.26984428 | H164: =$E$3+G164 -> 0.2998574 | I164: =IFERROR(VLOOKUP(B164,CDS!$B$8:$D$97,3,FALSE),"NA") -> NA | J164: =IF(I164="NA","NA",$E$4*I164) -> NA | K164: =IF(J164="NA","NA",$E$3+J164) -> NA
A166: # | B166: ERP estimation for Frontier Markets with no sovereign Ratings | K166: PRS Score Lookup Table
B168: Country | C168: Region | D168: PRS Score | E168: Synthetic Rating | F168: Default Spread on PRS Score | G168: Total Equity Risk Premium1 | H168: Country Risk Premium | I168: Total Equity Risk Premium2 | K168: More than | L168: Less than | M168: Synthetic Rating | N168: Default Spread | O168: ERP
B169: Algeria | C169: =VLOOKUP(B169,RegionLookup!$B$3:$C$184,2,FALSE) -> Africa | D169: =VLOOKUP(B169,'Ratings&PRS'!$G$4:$H$144,2,FALSE) -> 69.25 | E169: =VLOOKUP(D169,$K$169:$O$184,5) -> 0.11333128 | F169: =VLOOKUP(D169,$K$169:$O$184,4) -> 0.029799488 | G169: =$E$3+F169 -> 0.059812614 | H169: =F169*$E$4 -> 0.090182943 | I169: =$E$3+H169 -> 0.12019607 | K169: 0 | L169: 50 | M169: Below Ca | N169: 0.175 | O169: 0.46187346
B170: Brunei | C170: =VLOOKUP(B170,RegionLookup!$B$3:$C$184,2,FALSE) -> Asia | D170: =VLOOKUP(B170,'Ratings&PRS'!$G$4:$H$144,2,FALSE) -> 81.75 | E170: =VLOOKUP(D170,$K$169:$O$184,5) -> 0.056050372 | F170: =VLOOKUP(D170,$K$169:$O$184,4) -> 0.0059366167 | G170: =$E$3+F170 -> 0.035949743 | H170: =F170*$E$4 -> 0.017966133 | I170: =$E$3+H170 -> 0.04797926 | K170: 50.001 | L170: 55 | M170: Ca | N170: 0.11884874 | O170: 0.32708686
B171: Gambia | C171: =VLOOKUP(B171,RegionLookup!$B$3:$C$184,2,FALSE) -> Africa | D171: =VLOOKUP(B171,'Ratings&PRS'!$G$4:$H$144,2,FALSE) -> 67.5 | E171: =VLOOKUP(D171,$K$169:$O$184,5) -> 0.1488175 | F171: =VLOOKUP(D171,$K$169:$O$184,4) -> 0.044582827 | G171: =$E$3+F171 -> 0.074595954 | H171: =F171*$E$4 -> 0.13492214 | I171: =$E$3+H171 -> 0.16493526 | K171: 55.001 | L171: 57 | M171: Caa3 | N171: 0.099060015 | O171: 0.27958562
B172: Guinea | C172: =VLOOKUP(B172,RegionLookup!$B$3:$C$184,2,FALSE) -> Africa | D172: =VLOOKUP(B172,'Ratings&PRS'!$G$4:$H$144,2,FALSE) -> 57.75 | E172: =VLOOKUP(D172,$K$169:$O$184,5) -> 0.255835 | F172: =VLOOKUP(D172,$K$169:$O$184,4) -> 0.089165654 | G172: =$E$3+F172 -> 0.11917878 | H172: =F172*$E$4 -> 0.26984428 | I172: =$E$3+H172 -> 0.2998574 | K172: 57.001 | L172: 60 | M172: Caa2 | N172: 0.089165654 | O172: 0.255835
B173: Guinea-Bissau | C173: =VLOOKUP(B173,RegionLookup!$B$3:$C$184,2,FALSE) -> Africa | D173: =VLOOKUP(B173,'Ratings&PRS'!$G$4:$H$144,2,FALSE) -> 63.25 | E173: =VLOOKUP(D173,$K$169:$O$184,5) -> 0.19631874 | F173: =VLOOKUP(D173,$K$169:$O$184,4) -> 0.064371549 | G173: =$E$3+F173 -> 0.094384676 | H173: =F173*$E$4 -> 0.19480925 | I173: =$E$3+H173 -> 0.22482237 | K173: 60.001 | L173: 62 | M173: Caa1 | N173: 0.07426591 | O173: 0.22006936
B174: Guyana | C174: =VLOOKUP(B174,RegionLookup!$B$3:$C$184,2,FALSE) -> Central and South America | D174: =VLOOKUP(B174,'Ratings&PRS'!$G$4:$H$144,2,FALSE) -> 75.75 | E174: =VLOOKUP(D174,$K$169:$O$184,5) -> 0.094051365 | F174: =VLOOKUP(D174,$K$169:$O$184,4) -> 0.021767594 | G174: =$E$3+F174 -> 0.051780721 | H174: =F174*$E$4 -> 0.065875822 | I174: =$E$3+H174 -> 0.095888948 | K174: 62.001 | L174: 64 | M174: B3 | N174: 0.064371549 | O174: 0.19631874
B175: Haiti | C175: =VLOOKUP(B175,RegionLookup!$B$3:$C$184,2,FALSE) -> Caribbean | D175: =VLOOKUP(B175,'Ratings&PRS'!$G$4:$H$144,2,FALSE) -> 54.75 | E175: =VLOOKUP(D175,$K$169:$O$184,5) -> 0.32708686 | F175: =VLOOKUP(D175,$K$169:$O$184,4) -> 0.11884874 | G175: =$E$3+F175 -> 0.14886186 | H175: =F175*$E$4 -> 0.35967494 | I175: =$E$3+H175 -> 0.38968807 | K175: 64.001 | L175: 66 | M175: B2 | N175: 0.054477188 | O175: 0.17256812
B176: Iran | C176: =VLOOKUP(B176,RegionLookup!$B$3:$C$184,2,FALSE) -> Middle East | D176: =VLOOKUP(B176,'Ratings&PRS'!$G$4:$H$144,2,FALSE) -> 63.75 | E176: =VLOOKUP(D176,$K$169:$O$184,5) -> 0.19631874 | F176: =VLOOKUP(D176,$K$169:$O$184,4) -> 0.064371549 | G176: =$E$3+F176 -> 0.094384676 | H176: =F176*$E$4 -> 0.19480925 | I176: =$E$3+H176 -> 0.22482237 | K176: 66.001 | L176: 68 | M176: B1 | N176: 0.044582827 | O176: 0.1488175
...

Sheet CtryERP&CRP
B3: Asia | D3: ERP (CDS CRP) | E3: ERP (Ratings CRP) | F3: ERP (PRS Score) | G3: ERP (Final) | I3: CRP (CDS) | J3: CRP (Ratings) | K3: CRP (PRS) | L3: CRP (Final)
B4: Bangladesh | D4: =IFERROR(VLOOKUP(B4,'ERPsCRPs&Spreads'!$B$8:$K$164,10,FALSE),"NA") -> NA | E4: =IFERROR(VLOOKUP(B4,'ERPsCRPs&Spreads'!$B$8:$H$164,7,FALSE),"NA") -> 0.19487882 | F4: =IFERROR(VLOOKUP(B4,'ERPsCRPs&Spreads'!$B$169:$I$189,8,FALSE),"NA") -> NA | G4: =IF(D4<>"NA",D4,IF(E4<>"NA",E4,F4)) -> 0.19487882 | I4: =IFERROR(VLOOKUP(B4,'ERPsCRPs&Spreads'!$B$8:$K$164,9,FALSE),"NA") -> NA | J4: =IFERROR(VLOOKUP(B4,'ERPsCRPs&Spreads'!$B$8:$K$164,6,FALSE),"NA") -> 0.16486569 | K4: =IFERROR(VLOOKUP('CtryERP&CRP'!B4,'ERPsCRPs&Spreads'!$B$169:$I$189,7,FALSE),"NA") -> NA | L4: =IF(I4<>"NA",I4,IF(J4<>"NA",J4,K4)) -> 0.16486569
B5: Brunei | D5: =IFERROR(VLOOKUP(B5,'ERPsCRPs&Spreads'!$B$8:$K$164,10,FALSE),"NA") -> NA | E5: =IFERROR(VLOOKUP(B5,'ERPsCRPs&Spreads'!$B$8:$H$164,7,FALSE),"NA") -> NA | F5: =IFERROR(VLOOKUP(B5,'ERPsCRPs&Spreads'!$B$169:$I$189,8,FALSE),"NA") -> 0.04797926 | G5: =IF(D5<>"NA",D5,IF(E5<>"NA",E5,F5)) -> 0.04797926 | I5: =IFERROR(VLOOKUP(B5,'ERPsCRPs&Spreads'!$B$8:$K$164,9,FALSE),"NA") -> NA | J5: =IFERROR(VLOOKUP(B5,'ERPsCRPs&Spreads'!$B$8:$K$164,6,FALSE),"NA") -> NA | K5: =IFERROR(VLOOKUP('CtryERP&CRP'!B5,'ERPsCRPs&Spreads'!$B$169:$I$189,7,FALSE),"NA") -> 0.017966133 | L5: =IF(I5<>"NA",I5,IF(J5<>"NA",J5,K5)) -> 0.017966133
B6: Cambodia | D6: =IFERROR(VLOOKUP(B6,'ERPsCRPs&Spreads'!$B$8:$K$164,10,FALSE),"NA") -> NA | E6: =IFERROR(VLOOKUP(B6,'ERPsCRPs&Spreads'!$B$8:$H$164,7,FALSE),"NA") -> 0.19487882 | F6: =IFERROR(VLOOKUP(B6,'ERPsCRPs&Spreads'!$B$169:$I$189,8,FALSE),"NA") -> NA | G6: =IF(D6<>"NA",D6,IF(E6<>"NA",E6,F6)) -> 0.19487882 | I6: =IFERROR(VLOOKUP(B6,'ERPsCRPs&Spreads'!$B$8:$K$164,9,FALSE),"NA") -> NA | J6: =IFERROR(VLOOKUP(B6,'ERPsCRPs&Spreads'!$B$8:$K$164,6,FALSE),"NA") -> 0.16486569 | K6: =IFERROR(VLOOKUP('CtryERP&CRP'!B6,'ERPsCRPs&Spreads'!$B$169:$I$189,7,FALSE),"NA") -> NA | L6: =IF(I6<>"NA",I6,IF(J6<>"NA",J6,K6)) -> 0.16486569
B7: China | D7: =IFERROR(VLOOKUP(B7,'ERPsCRPs&Spreads'!$B$8:$K$164,10,FALSE),"NA") -> 0.047565813 | E7: =IFERROR(VLOOKUP(B7,'ERPsCRPs&Spreads'!$B$8:$H$164,7,FALSE),"NA") -> 0.051149754 | F7: =IFERROR(VLOOKUP(B7,'ERPsCRPs&Spreads'!$B$169:$I$189,8,FALSE),"NA") -> NA | G7: =IF(D7<>"NA",D7,IF(E7<>"NA",E7,F7)) -> 0.047565813 | I7: =IFERROR(VLOOKUP(B7,'ERPsCRPs&Spreads'!$B$8:$K$164,9,FALSE),"NA") -> 0.017552687 | J7: =IFERROR(VLOOKUP(B7,'ERPsCRPs&Spreads'!$B$8:$K$164,6,FALSE),"NA") -> 0.021136627 | K7: =IFERROR(VLOOKUP('CtryERP&CRP'!B7,'ERPsCRPs&Spreads'!$B$169:$I$189,7,FALSE),"NA") -> NA | L7: =IF(I7<>"NA",I7,IF(J7<>"NA",J7,K7)) -> 0.017552687
B8: Fiji | D8: =IFERROR(VLOOKUP(B8,'ERPsCRPs&Spreads'!$B$8:$K$164,10,FALSE),"NA") -> NA | E8: =IFERROR(VLOOKUP(B8,'ERPsCRPs&Spreads'!$B$8:$H$164,7,FALSE),"NA") -> 0.16493526 | F8: =IFERROR(VLOOKUP(B8,'ERPsCRPs&Spreads'!$B$169:$I$189,8,FALSE),"NA") -> NA | G8: =IF(D8<>"NA",D8,IF(E8<>"NA",E8,F8)) -> 0.16493526 | I8: =IFERROR(VLOOKUP(B8,'ERPsCRPs&Spreads'!$B$8:$K$164,9,FALSE),"NA") -> NA | J8: =IFERROR(VLOOKUP(B8,'ERPsCRPs&Spreads'!$B$8:$K$164,6,FALSE),"NA") -> 0.13492214 | K8: =IFERROR(VLOOKUP('CtryERP&CRP'!B8,'ERPsCRPs&Spreads'!$B$169:$I$189,7,FALSE),"NA") -> NA | L8: =IF(I8<>"NA",I8,IF(J8<>"NA",J8,K8)) -> 0.13492214
B9: Hong Kong | D9: =IFERROR(VLOOKUP(B9,'ERPsCRPs&Spreads'!$B$8:$K$164,10,FALSE),"NA") -> 0.042723693 | E9: =IFERROR(VLOOKUP(B9,'ERPsCRPs&Spreads'!$B$8:$H$164,7,FALSE),"NA") -> 0.04797926 | F9: =IFERROR(VLOOKUP(B9,'ERPsCRPs&Spreads'!$B$169:$I$189,8,FALSE),"NA") -> NA | G9: =IF(D9<>"NA",D9,IF(E9<>"NA",E9,F9)) -> 0.042723693 | I9: =IFERROR(VLOOKUP(B9,'ERPsCRPs&Spreads'!$B$8:$K$164,9,FALSE),"NA") -> 0.012710566 | J9: =IFERROR(VLOOKUP(B9,'ERPsCRPs&Spreads'!$B$8:$K$164,6,FALSE),"NA") -> 0.017966133 | K9: =IFERROR(VLOOKUP('CtryERP&CRP'!B9,'ERPsCRPs&Spreads'!$B$169:$I$189,7,FALSE),"NA") -> NA | L9: =IF(I9<>"NA",I9,IF(J9<>"NA",J9,K9)) -> 0.012710566
B10: India | D10: =IFERROR(VLOOKUP(B10,'ERPsCRPs&Spreads'!$B$8:$K$164,10,FALSE),"NA") -> 0.050289506 | E10: =IFERROR(VLOOKUP(B10,'ERPsCRPs&Spreads'!$B$8:$H$164,7,FALSE),"NA") -> 0.095888948 | F10: =IFERROR(VLOOKUP(B10,'ERPsCRPs&Spreads'!$B$169:$I$189,8,FALSE),"NA") -> NA | G10: =IF(D10<>"NA",D10,IF(E10<>"NA",E10,F10)) -> 0.050289506 | I10: =IFERROR(VLOOKUP(B10,'ERPsCRPs&Spreads'!$B$8:$K$164,9,FALSE),"NA") -> 0.02027638 | J10: =IFERROR(VLOOKUP(B10,'ERPsCRPs&Spreads'!$B$8:$K$164,6,FALSE),"NA") -> 0.065875822 | K10: =IFERROR(VLOOKUP('CtryERP&CRP'!B10,'ERPsCRPs&Spreads'!$B$169:$I$189,7,FALSE),"NA") -> NA | L10: =IF(I10<>"NA",I10,IF(J10<>"NA",J10,K10)) -> 0.02027638
B11: Indonesia | D11: =IFERROR(VLOOKUP(B11,'ERPsCRPs&Spreads'!$B$8:$K$164,10,FALSE),"NA") -> 0.065421133 | E11: =IFERROR(VLOOKUP(B11,'ERPsCRPs&Spreads'!$B$8:$H$164,7,FALSE),"NA") -> 0.08708202 | F11: =IFERROR(VLOOKUP(B11,'ERPsCRPs&Spreads'!$B$169:$I$189,8,FALSE),"NA") -> NA | G11: =IF(D11<>"NA",D11,IF(E11<>"NA",E11,F11)) -> 0.065421133 | I11: =IFERROR(VLOOKUP(B11,'ERPsCRPs&Spreads'!$B$8:$K$164,9,FALSE),"NA") -> 0.035408006 | J11: =IFERROR(VLOOKUP(B11,'ERPsCRPs&Spreads'!$B$8:$K$164,6,FALSE),"NA") -> 0.057068894 | K11: =IFERROR(VLOOKUP('CtryERP&CRP'!B11,'ERPsCRPs&Spreads'!$B$169:$I$189,7,FALSE),"NA") -> NA | L11: =IF(I11<>"NA",I11,IF(J11<>"NA",J11,K11)) -> 0.035408006
B12: Japan | D12: =IFERROR(VLOOKUP(B12,'ERPsCRPs&Spreads'!$B$8:$K$164,10,FALSE),"NA") -> 0.035763145 | E12: =IFERROR(VLOOKUP(B12,'ERPsCRPs&Spreads'!$B$8:$H$164,7,FALSE),"NA") -> 0.051149754 | F12: =IFERROR(VLOOKUP(B12,'ERPsCRPs&Spreads'!$B$169:$I$189,8,FALSE),"NA") -> NA | G12: =IF(D12<>"NA",D12,IF(E12<>"NA",E12,F12)) -> 0.035763145 | I12: =IFERROR(VLOOKUP(B12,'ERPsCRPs&Spreads'!$B$8:$K$164,9,FALSE),"NA") -> 0.0057500181 | J12: =IFERROR(VLOOKUP(B12,'ERPsCRPs&Spreads'!$B$8:$K$164,6,FALSE),"NA") -> 0.021136627 | K12: =IFERROR(VLOOKUP('CtryERP&CRP'!B12,'ERPsCRPs&Spreads'!$B$169:$I$189,7,FALSE),"NA") -> NA | L12: =IF(I12<>"NA",I12,IF(J12<>"NA",J12,K12)) -> 0.0057500181
B13: Korea | D13: =IFERROR(VLOOKUP(B13,'ERPsCRPs&Spreads'!$B$8:$K$164,10,FALSE),"NA") -> 0.036065777 | E13: =IFERROR(VLOOKUP(B13,'ERPsCRPs&Spreads'!$B$8:$H$164,7,FALSE),"NA") -> 0.044808766 | F13: =IFERROR(VLOOKUP(B13,'ERPsCRPs&Spreads'!$B$169:$I$189,8,FALSE),"NA") -> NA | G13: =IF(D13<>"NA",D13,IF(E13<>"NA",E13,F13)) -> 0.036065777 | I13: =IFERROR(VLOOKUP(B13,'ERPsCRPs&Spreads'!$B$8:$K$164,9,FALSE),"NA") -> 0.0060526506 | J13: =IFERROR(VLOOKUP(B13,'ERPsCRPs&Spreads'!$B$8:$K$164,6,FALSE),"NA") -> 0.014795639 | K13: =IFERROR(VLOOKUP('CtryERP&CRP'!B13,'ERPsCRPs&Spreads'!$B$169:$I$189,7,FALSE),"NA") -> NA | L13: =IF(I13<>"NA",I13,IF(J13<>"NA",J13,K13)) -> 0.0060526506
B14: Korea, D.P.R. | D14: =IFERROR(VLOOKUP(B14,'ERPsCRPs&Spreads'!$B$8:$K$164,10,FALSE),"NA") -> NA | E14: =IFERROR(VLOOKUP(B14,'ERPsCRPs&Spreads'!$B$8:$H$164,7,FALSE),"NA") -> NA | F14: =IFERROR(VLOOKUP(B14,'ERPsCRPs&Spreads'!$B$169:$I$189,8,FALSE),"NA") -> 0.38968807 | G14: =IF(D14<>"NA",D14,IF(E14<>"NA",E14,F14)) -> 0.38968807 | I14: =IFERROR(VLOOKUP(B14,'ERPsCRPs&Spreads'!$B$8:$K$164,9,FALSE),"NA") -> NA | J14: =IFERROR(VLOOKUP(B14,'ERPsCRPs&Spreads'!$B$8:$K$164,6,FALSE),"NA") -> NA | K14: =IFERROR(VLOOKUP('CtryERP&CRP'!B14,'ERPsCRPs&Spreads'!$B$169:$I$189,7,FALSE),"NA") -> 0.35967494 | L14: =IF(I14<>"NA",I14,IF(J14<>"NA",J14,K14)) -> 0.35967494
B15: Laos | D15: =IFERROR(VLOOKUP(B15,'ERPsCRPs&Spreads'!$B$8:$K$164,10,FALSE),"NA") -> NA | E15: =IFERROR(VLOOKUP(B15,'ERPsCRPs&Spreads'!$B$8:$H$164,7,FALSE),"NA") -> 0.32980096 | F15: =IFERROR(VLOOKUP(B15,'ERPsCRPs&Spreads'!$B$169:$I$189,8,FALSE),"NA") -> NA | G15: =IF(D15<>"NA",D15,IF(E15<>"NA",E15,F15)) -> 0.32980096 | I15: =IFERROR(VLOOKUP(B15,'ERPsCRPs&Spreads'!$B$8:$K$164,9,FALSE),"NA") -> NA | J15: =IFERROR(VLOOKUP(B15,'ERPsCRPs&Spreads'!$B$8:$K$164,6,FALSE),"NA") -> 0.29978783 | K15: =IFERROR(VLOOKUP('CtryERP&CRP'!B15,'ERPsCRPs&Spreads'!$B$169:$I$189,7,FALSE),"NA") -> NA | L15: =IF(I15<>"NA",I15,IF(J15<>"NA",J15,K15)) -> 0.29978783
... B30: Vietnam | D30: =IFERROR(VLOOKUP(B30,'ERPsCRPs&Spreads'!$B$8:$K$164,10,FALSE),"NA") -> 0.072381681 | E30: =IFERROR(VLOOKUP(B30,'ERPsCRPs&Spreads'!$B$8:$H$164,7,FALSE),"NA") -> 0.12019607 | F30: =IFERROR(VLOOKUP(B30,'ERPsCRPs&Spreads'!$B$169:$I$189,8,FALSE),"NA") -> NA | G30: =IF(D30<>"NA",D30,IF(E30<>"NA",E30,F30)) -> 0.072381681 | I30: =IFERROR(VLOOKUP(B30,'ERPsCRPs&Spreads'!$B$8:$K$164,9,FALSE),"NA") -> 0.042368554 | J30: =IFERROR(VLOOKUP(B30,'ERPsCRPs&Spreads'!$B$8:$K$164,6,FALSE),"NA") -> 0.090182943 | K30: =IFERROR(VLOOKUP('CtryERP&CRP'!B30,'ERPsCRPs&Spreads'!$B$169:$I$189,7,FALSE),"NA") -> NA | L30: =IF(I30<>"NA",I30,IF(J30<>"NA",J30,K30)) -> 0.042368554
B32: Middle East | D32: ERP (CDS CRP) | E32: ERP (Ratings CRP) | F32: ERP (PRS Score) | G32: ERP (Final) | I32: CRP (CDS) | J32: CRP (Ratings) | K32: CRP (PRS) | L32: CRP (Final)
B33: Abu Dhabi | D33: =IFERROR(VLOOKUP(B33,'ERPsCRPs&Spreads'!$B$8:$K$164,10,FALSE),"NA") -> 0.045447386 | E33: =IFERROR(VLOOKUP(B33,'ERPsCRPs&Spreads'!$B$8:$H$164,7,FALSE),"NA") -> 0.044808766 | F33: =IFERROR(VLOOKUP(B33,'ERPsCRPs&Spreads'!$B$169:$I$189,8,FALSE),"NA") -> NA | G33: =IF(D33<>"NA",D33,IF(E33<>"NA",E33,F33)) -> 0.045447386 | I33: =IFERROR(VLOOKUP(B33,'ERPsCRPs&Spreads'!$B$8:$K$164,9,FALSE),"NA") -> 0.015434259 | J33: =IFERROR(VLOOKUP(B33,'ERPsCRPs&Spreads'!$B$8:$K$164,6,FALSE),"NA") -> 0.014795639 | K33: =IFERROR(VLOOKUP('CtryERP&CRP'!B33,'ERPsCRPs&Spreads'!$B$169:$I$189,7,FALSE),"NA") -> NA | L33: =IF(I33<>"NA",I33,IF(J33<>"NA",J33,K33)) -> 0.015434259
B34: Bahrain | D34: =IFERROR(VLOOKUP(B34,'ERPsCRPs&Spreads'!$B$8:$K$164,10,FALSE),"NA") -> 0.10930285 | E34: =IFERROR(VLOOKUP(B34,'ERPsCRPs&Spreads'!$B$8:$H$164,7,FALSE),"NA") -> 0.19487882 | F34: =IFERROR(VLOOKUP(B34,'ERPsCRPs&Spreads'!$B$169:$I$189,8,FALSE),"NA") -> NA | G34: =IF(D34<>"NA",D34,IF(E34<>"NA",E34,F34)) -> 0.10930285 | I34: =IFERROR(VLOOKUP(B34,'ERPsCRPs&Spreads'!$B$8:$K$164,9,FALSE),"NA") -> 0.079289723 | J34: =IFERROR(VLOOKUP(B34,'ERPsCRPs&Spreads'!$B$8:$K$164,6,FALSE),"NA") -> 0.16486569 | K34: =IFERROR(VLOOKUP('CtryERP&CRP'!B34,'ERPsCRPs&Spreads'!$B$169:$I$189,7,FALSE),"NA") -> NA | L34: =IF(I34<>"NA",I34,IF(J34<>"NA",J34,K34)) -> 0.079289723
B35: Iran | D35: =IFERROR(VLOOKUP(B35,'ERPsCRPs&Spreads'!$B$8:$K$164,10,FALSE),"NA") -> NA | E35: =IFERROR(VLOOKUP(B35,'ERPsCRPs&Spreads'!$B$8:$H$164,7,FALSE),"NA") -> NA | F35: =IFERROR(VLOOKUP(B35,'ERPsCRPs&Spreads'!$B$169:$I$189,8,FALSE),"NA") -> 0.22482237 | G35: =IF(D35<>"NA",D35,IF(E35<>"NA",E35,F35)) -> 0.22482237 | I35: =IFERROR(VLOOKUP(B35,'ERPsCRPs&Spreads'!$B$8:$K$164,9,FALSE),"NA") -> NA | J35: =IFERROR(VLOOKUP(B35,'ERPsCRPs&Spreads'!$B$8:$K$164,6,FALSE),"NA") -> NA | K35: =IFERROR(VLOOKUP('CtryERP&CRP'!B35,'ERPsCRPs&Spreads'!$B$169:$I$189,7,FALSE),"NA") -> 0.19480925 | L35: =IF(I35<>"NA",I35,IF(J35<>"NA",J35,K35)) -> 0.19480925
B36: Iraq | D36: =IFERROR(VLOOKUP(B36,'ERPsCRPs&Spreads'!$B$8:$K$164,10,FALSE),"NA") -> 0.14743455 | E36: =IFERROR(VLOOKUP(B36,'ERPsCRPs&Spreads'!$B$8:$H$164,7,FALSE),"NA") -> 0.25476593 | F36: =IFERROR(VLOOKUP(B36,'ERPsCRPs&Spreads'!$B$169:$I$189,8,FALSE),"NA") -> NA | G36: =IF(D36<>"NA",D36,IF(E36<>"NA",E36,F36)) -> 0.14743455 | I36: =IFERROR(VLOOKUP(B36,'ERPsCRPs&Spreads'!$B$8:$K$164,9,FALSE),"NA") -> 0.11742142 | J36: =IFERROR(VLOOKUP(B36,'ERPsCRPs&Spreads'!$B$8:$K$164,6,FALSE),"NA") -> 0.2247528 | K36: =IFERROR(VLOOKUP('CtryERP&CRP'!B36,'ERPsCRPs&Spreads'!$B$169:$I$189,7,FALSE),"NA") -> NA | L36: =IF(I36<>"NA",I36,IF(J36<>"NA",J36,K36)) -> 0.11742142
B37: Israel | D37: =IFERROR(VLOOKUP(B37,'ERPsCRPs&Spreads'!$B$8:$K$164,10,FALSE),"NA") -> 0.066934295 | E37: =IFERROR(VLOOKUP(B37,'ERPsCRPs&Spreads'!$B$8:$H$164,7,FALSE),"NA") -> 0.077922815 | F37: =IFERROR(VLOOKUP(B37,'ERPsCRPs&Spreads'!$B$169:$I$189,8,FALSE),"NA") -> NA | G37: =IF(D37<>"NA",D37,IF(E37<>"NA",E37,F37)) -> 0.066934295 | I37: =IFERROR(VLOOKUP(B37,'ERPsCRPs&Spreads'!$B$8:$K$164,9,FALSE),"NA") -> 0.036921169 | J37: =IFERROR(VLOOKUP(B37,'ERPsCRPs&Spreads'!$B$8:$K$164,6,FALSE),"NA") -> 0.047909689 | K37: =IFERROR(VLOOKUP('CtryERP&CRP'!B37,'ERPsCRPs&Spreads'!$B$169:$I$189,7,FALSE),"NA") -> NA | L37: =IF(I37<>"NA",I37,IF(J37<>"NA",J37,K37)) -> 0.036921169
B38: Jordan | D38: =IFERROR(VLOOKUP(B38,'ERPsCRPs&Spreads'!$B$8:$K$164,10,FALSE),"NA") -> NA | E38: =IFERROR(VLOOKUP(B38,'ERPsCRPs&Spreads'!$B$8:$H$164,7,FALSE),"NA") -> 0.13780993 | F38: =IFERROR(VLOOKUP(B38,'ERPsCRPs&Spreads'!$B$169:$I$189,8,FALSE),"NA") -> NA | G38: =IF(D38<>"NA",D38,IF(E38<>"NA",E38,F38)) -> 0.13780993 | I38: =IFERROR(VLOOKUP(B38,'ERPsCRPs&Spreads'!$B$8:$K$164,9,FALSE),"NA") -> NA | J38: =IFERROR(VLOOKUP(B38,'ERPsCRPs&Spreads'!$B$8:$K$164,6,FALSE),"NA") -> 0.1077968 | K38: =IFERROR(VLOOKUP('CtryERP&CRP'!B38,'ERPsCRPs&Spreads'!$B$169:$I$189,7,FALSE),"NA") -> NA | L38: =IF(I38<>"NA",I38,IF(J38<>"NA",J38,K38)) -> 0.1077968
B39: Kuwait | D39: =IFERROR(VLOOKUP(B39,'ERPsCRPs&Spreads'!$B$8:$K$164,10,FALSE),"NA") -> 0.051197404 | E39: =IFERROR(VLOOKUP(B39,'ERPsCRPs&Spreads'!$B$8:$H$164,7,FALSE),"NA") -> 0.051149754 | F39: =IFERROR(VLOOKUP(B39,'ERPsCRPs&Spreads'!$B$169:$I$189,8,FALSE),"NA") -> NA | G39: =IF(D39<>"NA",D39,IF(E39<>"NA",E39,F39)) -> 0.051197404 | I39: =IFERROR(VLOOKUP(B39,'ERPsCRPs&Spreads'!$B$8:$K$164,9,FALSE),"NA") -> 0.021184277 | J39: =IFERROR(VLOOKUP(B39,'ERPsCRPs&Spreads'!$B$8:$K$164,6,FALSE),"NA") -> 0.021136627 | K39: =IFERROR(VLOOKUP('CtryERP&CRP'!B39,'ERPsCRPs&Spreads'!$B$169:$I$189,7,FALSE),"NA") -> NA | L39: =IF(I39<>"NA",I39,IF(J39<>"NA",J39,K39)) -> 0.021184277
B40: Lebanon | D40: =IFERROR(VLOOKUP(B40,'ERPsCRPs&Spreads'!$B$8:$K$164,10,FALSE),"NA") -> NA | E40: =IFERROR(VLOOKUP(B40,'ERPsCRPs&Spreads'!$B$8:$H$164,7,FALSE),"NA") -> 0.55962005 | F40: =IFERROR(VLOOKUP(B40,'ERPsCRPs&Spreads'!$B$169:$I$189,8,FALSE),"NA") -> NA | G40: =IF(D40<>"NA",D40,IF(E40<>"NA",E40,F40)) -> 0.55962005 | I40: =IFERROR(VLOOKUP(B40,'ERPsCRPs&Spreads'!$B$8:$K$164,9,FALSE),"NA") -> NA | J40: =IFERROR(VLOOKUP(B40,'ERPsCRPs&Spreads'!$B$8:$K$164,6,FALSE),"NA") -> 0.52960693 | K40: =IFERROR(VLOOKUP('CtryERP&CRP'!B40,'ERPsCRPs&Spreads'!$B$169:$I$189,7,FALSE),"NA") -> NA | L40: =IF(I40<>"NA",I40,IF(J40<>"NA",J40,K40)) -> 0.52960693
B41: Oman | D41: =IFERROR(VLOOKUP(B41,'ERPsCRPs&Spreads'!$B$8:$K$164,10,FALSE),"NA") -> 0.075105373 | E41: =IFERROR(VLOOKUP(B41,'ERPsCRPs&Spreads'!$B$8:$H$164,7,FALSE),"NA") -> 0.10504815 | F41: =IFERROR(VLOOKUP(B41,'ERPsCRPs&Spreads'!$B$169:$I$189,8,FALSE),"NA") -> NA | G41: =IF(D41<>"NA",D41,IF(E41<>"NA",E41,F41)) -> 0.075105373 | I41: =IFERROR(VLOOKUP(B41,'ERPsCRPs&Spreads'!$B$8:$K$164,9,FALSE),"NA") -> 0.045092247 | J41: =IFERROR(VLOOKUP(B41,'ERPsCRPs&Spreads'!$B$8:$K$164,6,FALSE),"NA") -> 0.075035027 | K41: =IFERROR(VLOOKUP('CtryERP&CRP'!B41,'ERPsCRPs&Spreads'!$B$169:$I$189,7,FALSE),"NA") -> NA | L41: =IF(I41<>"NA",I41,IF(J41<>"NA",J41,K41)) -> 0.045092247
B42: Qatar | D42: =IFERROR(VLOOKUP(B42,'ERPsCRPs&Spreads'!$B$8:$K$164,10,FALSE),"NA") -> 0.045447386 | E42: =IFERROR(VLOOKUP(B42,'ERPsCRPs&Spreads'!$B$8:$H$164,7,FALSE),"NA") -> 0.044808766 | F42: =IFERROR(VLOOKUP(B42,'ERPsCRPs&Spreads'!$B$169:$I$189,8,FALSE),"NA") -> NA | G42: =IF(D42<>"NA",D42,IF(E42<>"NA",E42,F42)) -> 0.045447386 | I42: =IFERROR(VLOOKUP(B42,'ERPsCRPs&Spreads'!$B$8:$K$164,9,FALSE),"NA") -> 0.015434259 | J42: =IFERROR(VLOOKUP(B42,'ERPsCRPs&Spreads'!$B$8:$K$164,6,FALSE),"NA") -> 0.014795639 | K42: =IFERROR(VLOOKUP('CtryERP&CRP'!B42,'ERPsCRPs&Spreads'!$B$169:$I$189,7,FALSE),"NA") -> NA | L42: =IF(I42<>"NA",I42,IF(J42<>"NA",J42,K42)) -> 0.015434259
B43: Ras Al Khaimah (Emirate of) | D43: =IFERROR(VLOOKUP(B43,'ERPsCRPs&Spreads'!$B$8:$K$164,10,FALSE),"NA") -> NA | E43: =IFERROR(VLOOKUP(B43,'ERPsCRPs&Spreads'!$B$8:$H$164,7,FALSE),"NA") -> 0.065945393 | F43: =IFERROR(VLOOKUP(B43,'ERPsCRPs&Spreads'!$B$169:$I$189,8,FALSE),"NA") -> NA | G43: =IF(D43<>"NA",D43,IF(E43<>"NA",E43,F43)) -> 0.065945393 | I43: =IFERROR(VLOOKUP(B43,'ERPsCRPs&Spreads'!$B$8:$K$164,9,FALSE),"NA") -> NA | J43: =IFERROR(VLOOKUP(B43,'ERPsCRPs&Spreads'!$B$8:$K$164,6,FALSE),"NA") -> 0.035932266 | K43: =IFERROR(VLOOKUP('CtryERP&CRP'!B43,'ERPsCRPs&Spreads'!$B$169:$I$189,7,FALSE),"NA") -> NA | L43: =IF(I43<>"NA",I43,IF(J43<>"NA",J43,K43)) -> 0.035932266
B44: Saudi Arabia | D44: =IFERROR(VLOOKUP(B44,'ERPsCRPs&Spreads'!$B$8:$K$164,10,FALSE),"NA") -> 0.058763217 | E44: =IFERROR(VLOOKUP(B44,'ERPsCRPs&Spreads'!$B$8:$H$164,7,FALSE),"NA") -> 0.04797926 | F44: =IFERROR(VLOOKUP(B44,'ERPsCRPs&Spreads'!$B$169:$I$189,8,FALSE),"NA") -> NA | G44: =IF(D44<>"NA",D44,IF(E44<>"NA",E44,F44)) -> 0.058763217 | I44: =IFERROR(VLOOKUP(B44,'ERPsCRPs&Spreads'!$B$8:$K$164,9,FALSE),"NA") -> 0.02875009 | J44: =IFERROR(VLOOKUP(B44,'ERPsCRPs&Spreads'!$B$8:$K$164,6,FALSE),"NA") -> 0.017966133 | K44: =IFERROR(VLOOKUP('CtryERP&CRP'!B44,'ERPsCRPs&Spreads'!$B$169:$I$189,7,FALSE),"NA") -> NA | L44: =IF(I44<>"NA",I44,IF(J44<>"NA",J44,K44)) -> 0.02875009
... B48: Yemen, Republic | D48: =IFERROR(VLOOKUP(B48,'ERPsCRPs&Spreads'!$B$8:$K$164,10,FALSE),"NA") -> NA | E48: =IFERROR(VLOOKUP(B48,'ERPsCRPs&Spreads'!$B$8:$H$164,7,FALSE),"NA") -> NA | F48: =IFERROR(VLOOKUP(B48,'ERPsCRPs&Spreads'!$B$169:$I$189,8,FALSE),"NA") -> 0.38968807 | G48: =IF(D48<>"NA",D48,IF(E48<>"NA",E48,F48)) -> 0.38968807 | I48: =IFERROR(VLOOKUP(B48,'ERPsCRPs&Spreads'!$B$8:$K$164,9,FALSE),"NA") -> NA | J48: =IFERROR(VLOOKUP(B48,'ERPsCRPs&Spreads'!$B$8:$K$164,6,FALSE),"NA") -> NA | K48: =IFERROR(VLOOKUP('CtryERP&CRP'!B48,'ERPsCRPs&Spreads'!$B$169:$I$189,7,FALSE),"NA") -> 0.35967494 | L48: =IF(I48<>"NA",I48,IF(J48<>"NA",J48,K48)) -> 0.35967494
B50: Africa | D50: ERP (CDS CRP) | E50: ERP (Ratings CRP) | F50: ERP (PRS Score) | G50: ERP (Final) | I50: CRP (CDS) | J50: CRP (Ratings) | K50: CRP (PRS) | L50: CRP (Final)
B51: Algeria | D51: =IFERROR(VLOOKUP(B51,'ERPsCRPs&Spreads'!$B$8:$K$164,10,FALSE),"NA") -> NA | E51: =IFERROR(VLOOKUP(B51,'ERPsCRPs&Spreads'!$B$8:$H$164,7,FALSE),"NA") -> NA | F51: =IFERROR(VLOOKUP(B51,'ERPsCRPs&Spreads'!$B$169:$I$189,8,FALSE),"NA") -> 0.12019607 | G51: =IF(D51<>"NA",D51,IF(E51<>"NA",E51,F51)) -> 0.12019607 | I51: =IFERROR(VLOOKUP(B51,'ERPsCRPs&Spreads'!$B$8:$K$164,9,FALSE),"NA") -> NA | J51: =IFERROR(VLOOKUP(B51,'ERPsCRPs&Spreads'!$B$8:$K$164,6,FALSE),"NA") -> NA | K51: =IFERROR(VLOOKUP('CtryERP&CRP'!B51,'ERPsCRPs&Spreads'!$B$169:$I$189,7,FALSE),"NA") -> 0.090182943 | L51: =IF(I51<>"NA",I51,IF(J51<>"NA",J51,K51)) -> 0.090182943
B52: Angola | D52: =IFERROR(VLOOKUP(B52,'ERPsCRPs&Spreads'!$B$8:$K$164,10,FALSE),"NA") -> 0.24155327 | E52: =IFERROR(VLOOKUP(B52,'ERPsCRPs&Spreads'!$B$8:$H$164,7,FALSE),"NA") -> 0.22482237 | F52: =IFERROR(VLOOKUP(B52,'ERPsCRPs&Spreads'!$B$169:$I$189,8,FALSE),"NA") -> NA | G52: =IF(D52<>"NA",D52,IF(E52<>"NA",E52,F52)) -> 0.24155327 | I52: =IFERROR(VLOOKUP(B52,'ERPsCRPs&Spreads'!$B$8:$K$164,9,FALSE),"NA") -> 0.21154014 | J52: =IFERROR(VLOOKUP(B52,'ERPsCRPs&Spreads'!$B$8:$K$164,6,FALSE),"NA") -> 0.19480925 | K52: =IFERROR(VLOOKUP('CtryERP&CRP'!B52,'ERPsCRPs&Spreads'!$B$169:$I$189,7,FALSE),"NA") -> NA | L52: =IF(I52<>"NA",I52,IF(J52<>"NA",J52,K52)) -> 0.21154014
B53: Benin | D53: =IFERROR(VLOOKUP(B53,'ERPsCRPs&Spreads'!$B$8:$K$164,10,FALSE),"NA") -> NA | E53: =IFERROR(VLOOKUP(B53,'ERPsCRPs&Spreads'!$B$8:$H$164,7,FALSE),"NA") -> 0.16493526 | F53: =IFERROR(VLOOKUP(B53,'ERPsCRPs&Spreads'!$B$169:$I$189,8,FALSE),"NA") -> NA | G53: =IF(D53<>"NA",D53,IF(E53<>"NA",E53,F53)) -> 0.16493526 | I53: =IFERROR(VLOOKUP(B53,'ERPsCRPs&Spreads'!$B$8:$K$164,9,FALSE),"NA") -> NA | J53: =IFERROR(VLOOKUP(B53,'ERPsCRPs&Spreads'!$B$8:$K$164,6,FALSE),"NA") -> 0.13492214 | K53: =IFERROR(VLOOKUP('CtryERP&CRP'!B53,'ERPsCRPs&Spreads'!$B$169:$I$189,7,FALSE),"NA") -> NA | L53: =IF(I53<>"NA",I53,IF(J53<>"NA",J53,K53)) -> 0.13492214
B54: Botswana | D54: =IFERROR(VLOOKUP(B54,'ERPsCRPs&Spreads'!$B$8:$K$164,10,FALSE),"NA") -> NA | E54: =IFERROR(VLOOKUP(B54,'ERPsCRPs&Spreads'!$B$8:$H$164,7,FALSE),"NA") -> 0.065945393 | F54: =IFERROR(VLOOKUP(B54,'ERPsCRPs&Spreads'!$B$169:$I$189,8,FALSE),"NA") -> NA | G54: =IF(D54<>"NA",D54,IF(E54<>"NA",E54,F54)) -> 0.065945393 | I54: =IFERROR(VLOOKUP(B54,'ERPsCRPs&Spreads'!$B$8:$K$164,9,FALSE),"NA") -> NA | J54: =IFERROR(VLOOKUP(B54,'ERPsCRPs&Spreads'!$B$8:$K$164,6,FALSE),"NA") -> 0.035932266 | K54: =IFERROR(VLOOKUP('CtryERP&CRP'!B54,'ERPsCRPs&Spreads'!$B$169:$I$189,7,FALSE),"NA") -> NA | L54: =IF(I54<>"NA",I54,IF(J54<>"NA",J54,K54)) -> 0.035932266
B55: Burkina Faso | D55: =IFERROR(VLOOKUP(B55,'ERPsCRPs&Spreads'!$B$8:$K$164,10,FALSE),"NA") -> NA | E55: =IFERROR(VLOOKUP(B55,'ERPsCRPs&Spreads'!$B$8:$H$164,7,FALSE),"NA") -> 0.25476593 | F55: =IFERROR(VLOOKUP(B55,'ERPsCRPs&Spreads'!$B$169:$I$189,8,FALSE),"NA") -> NA | G55: =IF(D55<>"NA",D55,IF(E55<>"NA",E55,F55)) -> 0.25476593 | I55: =IFERROR(VLOOKUP(B55,'ERPsCRPs&Spreads'!$B$8:$K$164,9,FALSE),"NA") -> NA | J55: =IFERROR(VLOOKUP(B55,'ERPsCRPs&Spreads'!$B$8:$K$164,6,FALSE),"NA") -> 0.2247528 | K55: =IFERROR(VLOOKUP('CtryERP&CRP'!B55,'ERPsCRPs&Spreads'!$B$169:$I$189,7,FALSE),"NA") -> NA | L55: =IF(I55<>"NA",I55,IF(J55<>"NA",J55,K55)) -> 0.2247528
B56: Cameroon | D56: =IFERROR(VLOOKUP(B56,'ERPsCRPs&Spreads'!$B$8:$K$164,10,FALSE),"NA") -> 0.2678823 | E56: =IFERROR(VLOOKUP(B56,'ERPsCRPs&Spreads'!$B$8:$H$164,7,FALSE),"NA") -> 0.25476593 | F56: =IFERROR(VLOOKUP(B56,'ERPsCRPs&Spreads'!$B$169:$I$189,8,FALSE),"NA") -> NA | G56: =IF(D56<>"NA",D56,IF(E56<>"NA",E56,F56)) -> 0.2678823 | I56: =IFERROR(VLOOKUP(B56,'ERPsCRPs&Spreads'!$B$8:$K$164,9,FALSE),"NA") -> 0.23786917 | J56: =IFERROR(VLOOKUP(B56,'ERPsCRPs&Spreads'!$B$8:$K$164,6,FALSE),"NA") -> 0.2247528 | K56: =IFERROR(VLOOKUP('CtryERP&CRP'!B56,'ERPsCRPs&Spreads'!$B$169:$I$189,7,FALSE),"NA") -> NA | L56: =IF(I56<>"NA",I56,IF(J56<>"NA",J56,K56)) -> 0.23786917
B57: Cape Verde | D57: =IFERROR(VLOOKUP(B57,'ERPsCRPs&Spreads'!$B$8:$K$164,10,FALSE),"NA") -> NA | E57: =IFERROR(VLOOKUP(B57,'ERPsCRPs&Spreads'!$B$8:$H$164,7,FALSE),"NA") -> 0.19487882 | F57: =IFERROR(VLOOKUP(B57,'ERPsCRPs&Spreads'!$B$169:$I$189,8,FALSE),"NA") -> NA | G57: =IF(D57<>"NA",D57,IF(E57<>"NA",E57,F57)) -> 0.19487882 | I57: =IFERROR(VLOOKUP(B57,'ERPsCRPs&Spreads'!$B$8:$K$164,9,FALSE),"NA") -> NA | J57: =IFERROR(VLOOKUP(B57,'ERPsCRPs&Spreads'!$B$8:$K$164,6,FALSE),"NA") -> 0.16486569 | K57: =IFERROR(VLOOKUP('CtryERP&CRP'!B57,'ERPsCRPs&Spreads'!$B$169:$I$189,7,FALSE),"NA") -> NA | L57: =IF(I57<>"NA",I57,IF(J57<>"NA",J57,K57)) -> 0.16486569
B58: Congo (Democratic Republic of) | D58: =IFERROR(VLOOKUP(B58,'ERPsCRPs&Spreads'!$B$8:$K$164,10,FALSE),"NA") -> NA | E58: =IFERROR(VLOOKUP(B58,'ERPsCRPs&Spreads'!$B$8:$H$164,7,FALSE),"NA") -> 0.22482237 | F58: =IFERROR(VLOOKUP(B58,'ERPsCRPs&Spreads'!$B$169:$I$189,8,FALSE),"NA") -> NA | G58: =IF(D58<>"NA",D58,IF(E58<>"NA",E58,F58)) -> 0.22482237 | I58: =IFERROR(VLOOKUP(B58,'ERPsCRPs&Spreads'!$B$8:$K$164,9,FALSE),"NA") -> NA | J58: =IFERROR(VLOOKUP(B58,'ERPsCRPs&Spreads'!$B$8:$K$164,6,FALSE),"NA") -> 0.19480925 | K58: =IFERROR(VLOOKUP('CtryERP&CRP'!B58,'ERPsCRPs&Spreads'!$B$169:$I$189,7,FALSE),"NA") -> NA | L58: =IF(I58<>"NA",I58,IF(J58<>"NA",J58,K58)) -> 0.19480925
B59: Congo (Republic of) | D59: =IFERROR(VLOOKUP(B59,'ERPsCRPs&Spreads'!$B$8:$K$164,10,FALSE),"NA") -> NA | E59: =IFERROR(VLOOKUP(B59,'ERPsCRPs&Spreads'!$B$8:$H$164,7,FALSE),"NA") -> 0.2998574 | F59: =IFERROR(VLOOKUP(B59,'ERPsCRPs&Spreads'!$B$169:$I$189,8,FALSE),"NA") -> NA | G59: =IF(D59<>"NA",D59,IF(E59<>"NA",E59,F59)) -> 0.2998574 | I59: =IFERROR(VLOOKUP(B59,'ERPsCRPs&Spreads'!$B$8:$K$164,9,FALSE),"NA") -> NA | J59: =IFERROR(VLOOKUP(B59,'ERPsCRPs&Spreads'!$B$8:$K$164,6,FALSE),"NA") -> 0.26984428 | K59: =IFERROR(VLOOKUP('CtryERP&CRP'!B59,'ERPsCRPs&Spreads'!$B$169:$I$189,7,FALSE),"NA") -> NA | L59: =IF(I59<>"NA",I59,IF(J59<>"NA",J59,K59)) -> 0.26984428
B60: Côte d'Ivoire | D60: =IFERROR(VLOOKUP(B60,'ERPsCRPs&Spreads'!$B$8:$K$164,10,FALSE),"NA") -> NA | E60: =IFERROR(VLOOKUP(B60,'ERPsCRPs&Spreads'!$B$8:$H$164,7,FALSE),"NA") -> 0.12019607 | F60: =IFERROR(VLOOKUP(B60,'ERPsCRPs&Spreads'!$B$169:$I$189,8,FALSE),"NA") -> NA | G60: =IF(D60<>"NA",D60,IF(E60<>"NA",E60,F60)) -> 0.12019607 | I60: =IFERROR(VLOOKUP(B60,'ERPsCRPs&Spreads'!$B$8:$K$164,9,FALSE),"NA") -> NA | J60: =IFERROR(VLOOKUP(B60,'ERPsCRPs&Spreads'!$B$8:$K$164,6,FALSE),"NA") -> 0.090182943 | K60: =IFERROR(VLOOKUP('CtryERP&CRP'!B60,'ERPsCRPs&Spreads'!$B$169:$I$189,7,FALSE),"NA") -> NA | L60: =IF(I60<>"NA",I60,IF(J60<>"NA",J60,K60)) -> 0.090182943
B61: Egypt | D61: =IFERROR(VLOOKUP(B61,'ERPsCRPs&Spreads'!$B$8:$K$164,10,FALSE),"NA") -> 0.22490848 | E61: =IFERROR(VLOOKUP(B61,'ERPsCRPs&Spreads'!$B$8:$H$164,7,FALSE),"NA") -> 0.25476593 | F61: =IFERROR(VLOOKUP(B61,'ERPsCRPs&Spreads'!$B$169:$I$189,8,FALSE),"NA") -> NA | G61: =IF(D61<>"NA",D61,IF(E61<>"NA",E61,F61)) -> 0.22490848 | I61: =IFERROR(VLOOKUP(B61,'ERPsCRPs&Spreads'!$B$8:$K$164,9,FALSE),"NA") -> 0.19489535 | J61: =IFERROR(VLOOKUP(B61,'ERPsCRPs&Spreads'!$B$8:$K$164,6,FALSE),"NA") -> 0.2247528 | K61: =IFERROR(VLOOKUP('CtryERP&CRP'!B61,'ERPsCRPs&Spreads'!$B$169:$I$189,7,FALSE),"NA") -> NA | L61: =IF(I61<>"NA",I61,IF(J61<>"NA",J61,K61)) -> 0.19489535
...

Sheet RegionalERP
B2: Estimation of Regional Risk Premiums
B4: Regions | C4: GDP | D4: CRP | E4: ERP
B6: =AP21 -> Australia & New Zealand | C6: =AQ25 -> 2017879 | D6: =AR25 -> 0.00054337531 | E6: =AS25 -> 0.030556502
B7: =RegionalERP!AK21 -> Central and South America | C7: =AL42 -> 6563149.6 | D7: =AM42 -> 0.097716976 | E7: =AN42 -> 0.1277301
B8: =AF21 -> Caribbean | C8: =AG37 -> 356923.79 | D8: =AH37 -> 0.19981023 | E8: =AI37 -> 0.22982335
B9: =AA21 -> North America | C9: =AB24 -> 30994593 | D9: =AC24 -> 0.0097020829 | E9: =AD24 -> 0.039715209
B10: =V21 -> Westeren Europe | C10: =W48 -> 23566520 | D10: =X48 -> 0.0146739 | E10: =Y48 -> 0.044687027
B11: =Q21 -> Eastern Europe & Russia | C11: =R49 -> 5665313 | D11: =S49 -> 0.079495036 | E11: =T49 -> 0.10950816
B12: =L21 -> Africa | C12: =M64 -> 2794308.2 | D12: =N64 -> 0.16470493 | E12: =O64 -> 0.19471805
B13: =G21 -> Middle East | C13: =H38 -> 4099199.4 | D13: =I38 -> 0.060828079 | E13: =J38 -> 0.090841206
B14: =B21 -> Asia | C14: =C49 -> 34857584 | D14: =D49 -> 0.022846338 | E14: =E49 -> 0.052859465
B16: World | C16: =SUM(C6:C14) -> 1.1091547e+08 | D16: =SUMPRODUCT(C6:C14,D6:D14)/C16 -> 0.029901912 | E16: =SUMPRODUCT(C6:C14,E6:E14)/C16 -> 0.059915039
B18: Figures in USD mln
B19: GDP of countries with no ERP data are ignored
B21: Asia | C21: GDP | D21: CRP | E21: ERP | G21: Middle East | H21: GDP | I21: CRP | J21: ERP | L21: Africa | M21: GDP | N21: CRP | O21: ERP | Q21: Eastern Europe & Russia | R21: GDP | S21: CRP | T21: ERP | V21: Westeren Europe | W21: GDP | X21: CRP | Y21: ERP | AA21: North America | AB21: GDP | AC21: CRP | AD21: ERP | AF21: Caribbean | AG21: GDP | AH21: CRP | AI21: ERP | AK21: Central and South America | AL21: GDP | AM21: CRP | AN21: ERP | AP21: Australia & New Zealand | AQ21: GDP | AR21: CRP | AS21: ERP
B22: Bangladesh | C22: =VLOOKUP(B22,GDP!$B$7:$C$200,2,FALSE) -> 450119.43 | D22: =VLOOKUP(B22,'CtryERP&CRP'!$B$3:$L$197,11,FALSE) -> 0.16486569 | E22: =VLOOKUP(B22,'CtryERP&CRP'!$B$3:$L$197,6,FALSE) -> 0.19487882 | G22: Abu Dhabi | H22: =VLOOKUP(G22,GDP!$B$7:$C$200,2,FALSE) -> 308000 | I22: =VLOOKUP(G22,'CtryERP&CRP'!$B$3:$L$197,11,FALSE) -> 0.015434259 | J22: =VLOOKUP(G22,'CtryERP&CRP'!$B$3:$L$197,6,FALSE) -> 0.045447386 | L22: Algeria | M22: =VLOOKUP(L22,GDP!$B$7:$C$200,2,FALSE) -> 269322.28 | N22: =VLOOKUP(L22,'CtryERP&CRP'!$B$3:$L$197,11,FALSE) -> 0.090182943 | O22: =VLOOKUP(L22,'CtryERP&CRP'!$B$3:$L$197,6,FALSE) -> 0.12019607 | Q22: Albania | R22: =VLOOKUP(Q22,GDP!$B$7:$C$200,2,FALSE) -> 27046.43 | S22: =VLOOKUP(Q22,'CtryERP&CRP'!$B$3:$L$197,11,FALSE) -> 0.1077968 | T22: =VLOOKUP(Q22,'CtryERP&CRP'!$B$3:$L$197,6,FALSE) -> 0.13780993 | V22: Andorra (Principality of) | W22: =VLOOKUP(V22,GDP!$B$7:$C$200,2,FALSE) -> 4039.84 | X22: =VLOOKUP(V22,'CtryERP&CRP'!$B$3:$L$197,11,FALSE) -> 0.047909689 | Y22: =VLOOKUP(V22,'CtryERP&CRP'!$B$3:$L$197,6,FALSE) -> 0.077922815 | AA22: Canada | AB22: =VLOOKUP(AA22,GDP!$B$7:$C$200,2,FALSE) -> 2243636.8 | AC22: =VLOOKUP(AA22,'CtryERP&CRP'!$B$3:$L$197,11,FALSE) -> 0.0060526506 | AD22: =VLOOKUP(AA22,'CtryERP&CRP'!$B$3:$L$197,6,FALSE) -> 0.036065777 | AF22: Aruba | AG22: =VLOOKUP(AF22,GDP!$B$7:$C$200,2,FALSE) -> 4265.65 | AH22: =VLOOKUP(AF22,'CtryERP&CRP'!$B$3:$L$197,11,FALSE) -> 0.065875822 | AI22: =VLOOKUP(AF22,'CtryERP&CRP'!$B$3:$L$197,6,FALSE) -> 0.095888948 | AK22: Argentina | AL22: =VLOOKUP(AK22,GDP!$B$7:$C$200,2,FALSE) -> 638365.46 | AM22: =VLOOKUP(AK22,'CtryERP&CRP'!$B$3:$L$197,11,FALSE) -> 0.24815867 | AN22: =VLOOKUP(AK22,'CtryERP&CRP'!$B$3:$L$197,6,FALSE) -> 0.2781718 | AP22: Australia | AQ22: =VLOOKUP(AP22,GDP!$B$7:$C$200,2,FALSE) -> 1757022.4 | AR22: =VLOOKUP(AP22,'CtryERP&CRP'!$B$3:$L$197,11,FALSE) -> 0.00030263253 | AS22: =VLOOKUP(AP22,'CtryERP&CRP'!$B$3:$L$197,6,FALSE) -> 0.030315759
B23: Brunei | C23: =VLOOKUP(B23,GDP!$B$7:$C$200,2,FALSE) -> 15340.81 | D23: =VLOOKUP(B23,'CtryERP&CRP'!$B$3:$L$197,11,FALSE) -> 0.017966133 | E23: =VLOOKUP(B23,'CtryERP&CRP'!$B$3:$L$197,6,FALSE) -> 0.04797926 | G23: Bahrain | H23: =VLOOKUP(G23,GDP!$B$7:$C$200,2,FALSE) -> 47109.73 | I23: =VLOOKUP(G23,'CtryERP&CRP'!$B$3:$L$197,11,FALSE) -> 0.079289723 | J23: =VLOOKUP(G23,'CtryERP&CRP'!$B$3:$L$197,6,FALSE) -> 0.10930285 | L23: Angola | M23: =VLOOKUP(L23,GDP!$B$7:$C$200,2,FALSE) -> 100998.92 | N23: =VLOOKUP(L23,'CtryERP&CRP'!$B$3:$L$197,11,FALSE) -> 0.21154014 | O23: =VLOOKUP(L23,'CtryERP&CRP'!$B$3:$L$197,6,FALSE) -> 0.24155327 | Q23: Armenia | R23: =VLOOKUP(Q23,GDP!$B$7:$C$200,2,FALSE) -> 25955.28 | S23: =VLOOKUP(Q23,'CtryERP&CRP'!$B$3:$L$197,11,FALSE) -> 0.1077968 | T23: =VLOOKUP(Q23,'CtryERP&CRP'!$B$3:$L$197,6,FALSE) -> 0.13780993 | V23: Austria | W23: =VLOOKUP(V23,GDP!$B$7:$C$200,2,FALSE) -> 534790.72 | X23: =VLOOKUP(V23,'CtryERP&CRP'!$B$3:$L$197,11,FALSE) -> 0.004539488 | Y23: =VLOOKUP(V23,'CtryERP&CRP'!$B$3:$L$197,6,FALSE) -> 0.034552614 | AA23: United States | AB23: =VLOOKUP(AA23,GDP!$B$7:$C$200,2,FALSE) -> 28750956 | AC23: =VLOOKUP(AA23,'CtryERP&CRP'!$B$3:$L$197,11,FALSE) -> 0.0099868735 | AD23: =VLOOKUP(AA23,'CtryERP&CRP'!$B$3:$L$197,6,FALSE) -> 0.04 | AF23: Bahamas | AG23: =VLOOKUP(AF23,GDP!$B$7:$C$200,2,FALSE) -> 15832.8 | AH23: =VLOOKUP(AF23,'CtryERP&CRP'!$B$3:$L$197,11,FALSE) -> 0.13492214 | AI23: =VLOOKUP(AF23,'CtryERP&CRP'!$B$3:$L$197,6,FALSE) -> 0.16493526 | AK23: Belize | AL23: =VLOOKUP(AK23,GDP!$B$7:$C$200,2,FALSE) -> 3203.63 | AM23: =VLOOKUP(AK23,'CtryERP&CRP'!$B$3:$L$197,11,FALSE) -> 0.2247528 | AN23: =VLOOKUP(AK23,'CtryERP&CRP'!$B$3:$L$197,6,FALSE) -> 0.25476593 | AP23: Cook Islands | AQ23: =VLOOKUP(AP23,GDP!$B$7:$C$200,2,FALSE) -> 684.2 | AR23: =VLOOKUP(AP23,'CtryERP&CRP'!$B$3:$L$197,11,FALSE) -> 0.13492214 | AS23: =VLOOKUP(AP23,'CtryERP&CRP'!$B$3:$L$197,6,FALSE) -> 0.16493526
B24: Cambodia | C24: =VLOOKUP(B24,GDP!$B$7:$C$200,2,FALSE) -> 46352.65 | D24: =VLOOKUP(B24,'CtryERP&CRP'!$B$3:$L$197,11,FALSE) -> 0.16486569 | E24: =VLOOKUP(B24,'CtryERP&CRP'!$B$3:$L$197,6,FALSE) -> 0.19487882 | G24: Iran | H24: =VLOOKUP(G24,GDP!$B$7:$C$200,2,FALSE) -> 475252.09 | I24: =VLOOKUP(G24,'CtryERP&CRP'!$B$3:$L$197,11,FALSE) -> 0.19480925 | J24: =VLOOKUP(G24,'CtryERP&CRP'!$B$3:$L$197,6,FALSE) -> 0.22482237 | L24: Benin | M24: =VLOOKUP(L24,GDP!$B$7:$C$200,2,FALSE) -> 21482.64 | N24: =VLOOKUP(L24,'CtryERP&CRP'!$B$3:$L$197,11,FALSE) -> 0.13492214 | O24: =VLOOKUP(L24,'CtryERP&CRP'!$B$3:$L$197,6,FALSE) -> 0.16493526 | Q24: Azerbaijan | R24: =VLOOKUP(Q24,GDP!$B$7:$C$200,2,FALSE) -> 74315.88 | S24: =VLOOKUP(Q24,'CtryERP&CRP'!$B$3:$L$197,11,FALSE) -> 0.075035027 | T24: =VLOOKUP(Q24,'CtryERP&CRP'!$B$3:$L$197,6,FALSE) -> 0.10504815 | V24: Belgium | W24: =VLOOKUP(V24,GDP!$B$7:$C$200,2,FALSE) -> 671370.08 | X24: =VLOOKUP(V24,'CtryERP&CRP'!$B$3:$L$197,11,FALSE) -> 0.0099868735 | Y24: =VLOOKUP(V24,'CtryERP&CRP'!$B$3:$L$197,6,FALSE) -> 0.04 | AA24: =AA21 -> North America | AB24: =SUM(AB22:AB23) -> 30994593 | AC24: =SUMPRODUCT(AC22:AC23,AB22:AB23)/AB24 -> 0.0097020829 | AD24: =SUMPRODUCT(AD22:AD23,AB22:AB23)/AB24 -> 0.039715209 | AF24: Barbados | AG24: =VLOOKUP(AF24,GDP!$B$7:$C$200,2,FALSE) -> 7498.05 | AH24: =VLOOKUP(AF24,'CtryERP&CRP'!$B$3:$L$197,11,FALSE) -> 0.19480925 | AI24: =VLOOKUP(AF24,'CtryERP&CRP'!$B$3:$L$197,6,FALSE) -> 0.22482237 | AK24: Bolivia | AL24: =VLOOKUP(AK24,GDP!$B$7:$C$200,2,FALSE) -> 54881.33 | AM24: =VLOOKUP(AK24,'CtryERP&CRP'!$B$3:$L$197,11,FALSE) -> 0.29978783 | AN24: =VLOOKUP(AK24,'CtryERP&CRP'!$B$3:$L$197,6,FALSE) -> 0.32980096 | AP24: New Zealand | AQ24: =VLOOKUP(AP24,GDP!$B$7:$C$200,2,FALSE) -> 260172.39 | AR24: =VLOOKUP(AP24,'CtryERP&CRP'!$B$3:$L$197,11,FALSE) -> 0.0018157952 | AS24: =VLOOKUP(AP24,'CtryERP&CRP'!$B$3:$L$197,6,FALSE) -> 0.031828922
B25: China | C25: =VLOOKUP(B25,GDP!$B$7:$C$200,2,FALSE) -> 18743803 | D25: =VLOOKUP(B25,'CtryERP&CRP'!$B$3:$L$197,11,FALSE) -> 0.017552687 | E25: =VLOOKUP(B25,'CtryERP&CRP'!$B$3:$L$197,6,FALSE) -> 0.047565813 | G25: Iraq | H25: =VLOOKUP(G25,GDP!$B$7:$C$200,2,FALSE) -> 279641.26 | I25: =VLOOKUP(G25,'CtryERP&CRP'!$B$3:$L$197,11,FALSE) -> 0.11742142 | J25: =VLOOKUP(G25,'CtryERP&CRP'!$B$3:$L$197,6,FALSE) -> 0.14743455 | L25: Botswana | M25: =VLOOKUP(L25,GDP!$B$7:$C$200,2,FALSE) -> 19402.06 | N25: =VLOOKUP(L25,'CtryERP&CRP'!$B$3:$L$197,11,FALSE) -> 0.035932266 | O25: =VLOOKUP(L25,'CtryERP&CRP'!$B$3:$L$197,6,FALSE) -> 0.065945393 | Q25: Belarus | R25: =VLOOKUP(Q25,GDP!$B$7:$C$200,2,FALSE) -> 75961.87 | S25: =VLOOKUP(Q25,'CtryERP&CRP'!$B$3:$L$197,11,FALSE) -> 0.52960693 | T25: =VLOOKUP(Q25,'CtryERP&CRP'!$B$3:$L$197,6,FALSE) -> 0.55962005 | V25: Cyprus | W25: =VLOOKUP(V25,GDP!$B$7:$C$200,2,FALSE) -> 37634.53 | X25: =VLOOKUP(V25,'CtryERP&CRP'!$B$3:$L$197,11,FALSE) -> 0.019671114 | Y25: =VLOOKUP(V25,'CtryERP&CRP'!$B$3:$L$197,6,FALSE) -> 0.049684241 | AF25: Bermuda | AG25: =VLOOKUP(AF25,GDP!$B$7:$C$200,2,FALSE) -> 9233.6 | AH25: =VLOOKUP(AF25,'CtryERP&CRP'!$B$3:$L$197,11,FALSE) -> 0.025363953 | AI25: =VLOOKUP(AF25,'CtryERP&CRP'!$B$3:$L$197,6,FALSE) -> 0.055377079 | AK25: Brazil | AL25: =VLOOKUP(AK25,GDP!$B$7:$C$200,2,FALSE) -> 2185821.6 | AM25: =VLOOKUP(AK25,'CtryERP&CRP'!$B$3:$L$197,11,FALSE) -> 0.072026542 | AN25: =VLOOKUP(AK25,'CtryERP&CRP'!$B$3:$L$197,6,FALSE) -> 0.10203967 | AP25: =AP21 -> Australia & New Zealand | AQ25: =SUM(AQ22:AQ24) -> 2017879 | AR25: =SUMPRODUCT(AR22:AR24,AQ22:AQ24)/AQ25 -> 0.00054337531 | AS25: =SUMPRODUCT(AS22:AS24,AQ22:AQ24)/AQ25 -> 0.030556502
