Workbook

Sheet ReadMe
B2: Model by: | C2: Jay Prakash
B3: Website: | C3: https://jay-finance.github.io/portfolio/

Sheet ERPcalcINDIA
B2: ERP Calculation: | C2: India
B4: Mature Market | C4: United States
B5: Implied ERP of S&P 500 | C5: 0.0418
B6: Country Risk Premium | C6: =VLOOKUP(ERPcalcINDIA!C4,CDS!$B$8:$D$97,3,FALSE) -> 0.0033
B7: Mature Market ERP | C7: =C5-C6 -> 0.0385
B9: India's Rating | C9: =VLOOKUP(C2,Ratings!$B$4:$E$160,2,FALSE) -> Baa3
B10: Relative Volatility for Equity Market | C10: =RelativeVolatility!E11 -> 2.1734065
B12: Default Spread 1 (Rating) | C12: =VLOOKUP($C$9,Spreads!$C$8:$D$30,2,FALSE)/10000 -> 0.021767594
B13: Country Risk Premium 1 (Rating) | C13: =$C$10*C12 -> 0.04730983
B14: ERP 1 (Rating) | C14: =$C$7+C13 -> 0.08580983
B16: Default Spread 2 (CDS) | C16: =VLOOKUP($C$2,CDS!$B$8:$D$97,3,FALSE) -> 0.0067
B17: Country Risk Premium 2 (CDS) | C17: =$C$10*C16 -> 0.014561823
B18: ERP 2 (CDS) | C18: =$C$7+C17 -> 0.053061823

Sheet RelativeVolatility
B2: Relative Volatility for India
B4: Year | C4: Stdev (Nifty50) | D4: Stdev (GovBond) | E4: Relative Volatility
B6: 2020 | C6: =_xlfn.STDEV.S(D20:D271)*SQRT(252) -> 0.31223943 | D6: =_xlfn.STDEV.S(H20:H264)*SQRT(246) -> 0.12338549 | E6: =C6/D6 -> 2.5306009
B7: 2021 | C7: =_xlfn.STDEV.S(D273:D520)*SQRT(248) -> 0.15528737 | D7: =_xlfn.STDEV.S(H266:H506)*SQRT(241) -> 0.069604425 | E7: =C7/D7 -> 2.2309985
B8: 2022 | C8: =_xlfn.STDEV.S(D522:D769)*SQRT(248) -> 0.17189383 | D8: =_xlfn.STDEV.S(H508:H750)*SQRT(243) -> 0.10636233 | E8: =C8/D8 -> 1.6161157
B9: 2023 | C9: =_xlfn.STDEV.S(D771:D1016)*SQRT(246) -> 0.097007226 | D9: =_xlfn.STDEV.S(H752:H994)*SQRT(243) -> 0.056755855 | E9: =C9/D9 -> 1.7092021
B10: 2024 | C10: =_xlfn.STDEV.S(D1018:D1266)*SQRT(249) -> 0.13866747 | D10: =_xlfn.STDEV.S(H996:H1235)*SQRT(240) -> 0.046529577 | E10: =C10/D10 -> 2.9802004
B11: Avg Volatility (5Y) | C11: =AVERAGE(C6:C10) -> 0.17501906 | D11: =AVERAGE(D6:D10) -> 0.080527535 | E11: =C11/D11 -> 2.1734065
B13: Index: | C13: NIFTY 50 INDEX | F13: 10 Year Government Bond Yield
B14: Period: | C14: 5 Years (1st Jan 2020 - 31st Dec 2024) | F14: Period: | G14: 5 Years (1st Jan 2020 - 31st Dec 2024)
B15: Interval: | C15: Daily | F15: Interval: | G15: Daily
F16: ind bond
B17: Date | C17: Price | D17: Return | F17: Date | G17: Yield | H17: Return
B19: 43830 | C19: 12168.45 | F19: 43830 | G19: 6.554
B20: 43831 | C20: 12182.5 | D20: =C20/C19-1 -> 0.0011546253 | F20: 43831 | G20: 6.501 | H20: =G20/G19-1 -> -0.0080866646
B21: 43832 | C21: 12282.2 | D21: =C21/C20-1 -> 0.0081838703 | F21: 43832 | G21: 6.502 | H21: =G21/G20-1 -> 0.00015382249
B22: 43833 | C22: 12226.65 | D22: =C22/C21-1 -> -0.0045228054 | F22: 43833 | G22: 6.51 | H22: =G22/G21-1 -> 0.0012303906
B23: 43836 | C23: 11993.05 | D23: =C23/C22-1 -> -0.019105806 | F23: 43836 | G23: 6.565 | H23: =G23/G22-1 -> 0.0084485407
B24: 43837 | C24: 12052.95 | D24: =C24/C23-1 -> 0.0049945593 | F24: 43837 | G24: 6.55 | H24: =G24/G23-1 -> -0.0022848439
B25: 43838 | C25: 12025.35 | D25: =C25/C24-1 -> -0.0022898958 | F25: 43838 | G25: 6.557 | H25: =G25/G24-1 -> 0.0010687023
B26: 43839 | C26: 12215.9 | D26: =C26/C25-1 -> 0.015845693 | F26: 43839 | G26: 6.524 | H26: =G26/G25-1 -> -0.0050327894
B27: 43840 | C27: 12256.8 | D27: =C27/C26-1 -> 0.0033480955 | F27: 43840 | G27: 6.585 | H27: =G27/G26-1 -> 0.009350092
B28: 43843 | C28: 12329.55 | D28: =C28/C27-1 -> 0.0059354807 | F28: 43843 | G28: 6.592 | H28: =G28/G27-1 -> 0.001063022
B29: 43844 | C29: 12362.3 | D29: =C29/C28-1 -> 0.0026562202 | F29: 43844 | G29: 6.662 | H29: =G29/G28-1 -> 0.010618932
B30: 43845 | C30: 12343.3 | D30: =C30/C29-1 -> -0.0015369308 | F30: 43845 | G30: 6.623 | H30: =G30/G29-1 -> -0.0058540979
B31: 43846 | C31: 12355.5 | D31: =C31/C30-1 -> 0.00098839046 | F31: 43846 | G31: 6.598 | H31: =G31/G30-1 -> -0.0037747244
... B264: 44186 | C264: 13328.4 | D264: =C264/C263-1 -> -0.031404995 | F264: 44196 | G264: 5.894 | H264: =G264/G263-1 -> -0.00084760129
B265: 44187 | C265: 13466.3 | D265: =C265/C264-1 -> 0.010346328
B266: 44188 | C266: 13601.1 | D266: =C266/C265-1 -> 0.010010174 | F266: 44197 | G266: 5.898 | H266: =G266/G264-1 -> 0.00067865626
B267: 44189 | C267: 13749.25 | D267: =C267/C266-1 -> 0.010892501 | F267: 44200 | G267: 5.858 | H267: =G267/G266-1 -> -0.00678196
B268: 44193 | C268: 13873.2 | D268: =C268/C267-1 -> 0.0090150372 | F268: 44201 | G268: 5.85 | H268: =G268/G267-1 -> -0.0013656538
B269: 44194 | C269: 13932.6 | D269: =C269/C268-1 -> 0.0042816365 | F269: 44202 | G269: 5.894 | H269: =G269/G268-1 -> 0.0075213675
B270: 44195 | C270: 13981.95 | D270: =C270/C269-1 -> 0.0035420525 | F270: 44203 | G270: 5.892 | H270: =G270/G269-1 -> -0.00033932813
B271: 44196 | C271: 13981.75 | D271: =C271/C270-1 -> -1.4304156e-05 | F271: 44204 | G271: 5.892 | H271: =G271/G270-1 -> 0
F272: 44207 | G272: 5.924 | H272: =G272/G271-1 -> 0.005431093
B273: 44197 | C273: 14018.5 | D273: =C273/C271-1 -> 0.0026284263 | F273: 44208 | G273: 5.931 | H273: =G273/G272-1 -> 0.001181634
B274: 44200 | C274: 14132.9 | D274: =C274/C273-1 -> 0.0081606449 | F274: 44209 | G274: 5.947 | H274: =G274/G273-1 -> 0.0026976901
B275: 44201 | C275: 14199.5 | D275: =C275/C274-1 -> 0.0047124086 | F275: 44210 | G275: 5.924 | H275: =G275/G274-1 -> -0.0038674962
B276: 44202 | C276: 14146.25 | D276: =C276/C275-1 -> -0.003750132 | F276: 44211 | G276: 5.988 | H276: =G276/G275-1 -> 0.010803511
B277: 44203 | C277: 14137.35 | D277: =C277/C276-1 -> -0.000629142 | F277: 44214 | G277: 5.957 | H277: =G277/G276-1 -> -0.0051770207
...

Sheet Data>

Sheet CDS
B2: 10 Year Credit Default Spread
B4: Switzerland CDS | C4: 0.0017
B6: Country | C6: CDS November 2025 | D6: Net of Switzerland
B8: Abu Dhabi | C8: 0.0068 | D8: 0.0051 | F8: Source: NYU Stern website, Damodaran online
B9: Algeria | C9: 0.014 | D9: 0.0123
B10: Angola | C10: 0.0716 | D10: 0.0699
B11: Argentina | C11: 0.0837 | D11: 0.082
B12: Australia | C12: 0.0018 | D12: 0.0001
B13: Austria | C13: 0.0032 | D13: 0.0015
B14: Bahrain | C14: 0.0279 | D14: 0.0262
B15: Belgium | C15: 0.005 | D15: 0.0033
B16: Brazil | C16: 0.0255 | D16: 0.0238
B17: Bulgaria | C17: 0.0112 | D17: 0.0095
B18: Cameroon | C18: 0.0803 | D18: 0.0786
B19: Canada | C19: 0.0037 | D19: 0.002
B20: Chile | C20: 0.0104 | D20: 0.0087
... B32: Estonia | C32: 0.0093 | D32: 0.0076
B33: Ethiopia | C33: NA | D33: NA
B34: Finland | C34: 0.0032 | D34: 0.0015
B35: France | C35: 0.0068 | D35: 0.0051
B36: Gabon | C36: 0.0786 | D36: 0.0769
B37: Germany | C37: 0.0024 | D37: 0.0007
B38: Greece | C38: 0.0104 | D38: 0.0087
B39: Guatemala | C39: 0.0221 | D39: 0.0204
B40: Hong Kong | C40: 0.0059 | D40: 0.0042
B41: Hungary | C41: 0.0183 | D41: 0.0166
B42: Iceland | C42: 0.0047 | D42: 0.003
B43: India | C43: 0.0084 | D43: 0.0067
B44: Indonesia | C44: 0.0134 | D44: 0.0117
B45: Iraq | C45: 0.0405 | D45: 0.0388
... B54: Latvia | C54: 0.0098 | D54: 0.0081
B55: Lebanon | C55: NA | D55: NA
B56: Lithuania | C56: 0.009 | D56: 0.0073
B57: Malaysia | C57: 0.0081 | D57: 0.0064
B58: Mexico | C58: 0.0186 | D58: 0.0169
B59: Mongolia | C59: 0.0438 | D59: 0.0421
B60: Morocco | C60: 0.016 | D60: 0.0143
B61: Namibia | C61: 0.0365 | D61: 0.0348
B62: Netherlands | C62: 0.0025 | D62: 0.0008
B63: New Zealand | C63: 0.0023 | D63: 0.0006
...

Sheet Ratings
B2: Country | C2: Moody's Rating | D2: S&P Rating | E2: FITCH Rating
B4: Abu Dhabi | C4: Aa2 | D4: NR | E4: NR | G4: Source: NYU Stern website, Damodaran online
B5: Albania | C5: Ba3 | D5: BB- | E5: NR
B6: Andorra (Principality of) | C6: Baa1 | D6: A- | E6: A-
B7: Angola | C7: B3 | D7: B- | E7: B-
B8: Argentina | C8: Ca | D8: CCC | E8: CCC
B9: Armenia | C9: Ba3 | D9: BB- | E9: B+
B10: Aruba | C10: Baa3 | D10: BBB | E10: NR
B11: Australia | C11: Aaa | D11: AAA | E11: AAA
B12: Austria | C12: Aa1 | D12: AA+ | E12: AA+
B13: Azerbaijan | C13: Ba1 | D13: BB+ | E13: BB+
B14: Bahamas | C14: B1 | D14: B+ | E14: NR
B15: Bahrain | C15: B2 | D15: B+ | E15: B+
B16: Bangladesh | C16: B2 | D16: B+ | E16: B+
... B42: Croatia | C42: A3 | D42: A- | E42: BBB+
B43: Cuba | C43: Ca | D43: 0 | E43: NR
B44: Curacao | C44: Baa3 | D44: BBB- | E44: NR
B45: Cyprus | C45: A3 | D45: A- | E45: A-
B46: Czech Republic | C46: Aa3 | D46: AA- | E46: AA-
B47: Denmark | C47: Aaa | D47: AAA | E47: AAA
B48: Dominican Republic | C48: Ba3 | D48: BB | E48: BB-
B49: Ecuador | C49: Caa3 | D49: B- | E49: CCC+
B50: Egypt | C50: Caa1 | D50: B- | E50: B-
B51: El Salvador | C51: B3 | D51: B- | E51: CC
B52: Estonia | C52: A1 | D52: NR | E52: AA-
B53: Ethiopia | C53: Caa2 | D53: SD | E53: NR
B54: Fiji | C54: B1 | D54: B+ | E54: NR
B55: Finland | C55: Aa1 | D55: AA+ | E55: AA+
... B83: Kyrgyzstan | C83: B3 | D83: NR | E83: NR
B84: Laos | C84: Caa3 | D84: 0 | E84: CCC-
B85: Latvia | C85: A3 | D85: A | E85: A-
B86: Lebanon | C86: C | D86: D | E86: NR
B87: Liechtenstein | C87: Aaa | D87: AAA | E87: NR
B88: Lithuania | C88: A2 | D88: A | E88: A
B89: Luxembourg | C89: Aaa | D89: AAA | E89: AAA
B90: Macao | C90: Aa3 | D90: NR | E90: NR
B91: Macedonia | C91: Ba3 | D91: BB- | E91: NR
B92: Malaysia | C92: A3 | D92: A- | E92: BBB+
B93: Maldives | C93: Caa2 | D93: 0 | E93: CC
B94: Mali | C94: Caa2 | D94: 0 | E94: NR
...

Sheet Spreads
B2: Rating Based Default Spread for countries and corporates
B4: Country Default Spread's based on their Ratings
B6: Ratings | C6: Moody's Ratings | D6: Rating-basedDefault Spread
B8: AAA | C8: Aaa | D8: 0
B9: AA+ | C9: Aa1 | D9: 39.577444
B10: AA | C10: Aa2 | D10: 48.889784
B11: AA- | C11: Aa3 | D11: 59.366167
B12: A+ | C12: A1 | D12: 69.842549
B13: A | C13: A2 | D13: 83.811059
B14: A- | C14: A3 | D14: 118.73233
B15: BBB+ | C15: Baa1 | D15: 158.30978
B16: BBB | C16: Baa2 | D16: 188.57488
B17: BBB- | C17: Baa3 | D17: 217.67594
B18: BB+ | C18: Ba1 | D18: 247.94105
B19: BB | C19: Ba2 | D19: 297.99488
... B29: D | C29: C | D29: 1750
B30: NR | C30: NR | D30: NA
