Workbook

Sheet StartHere
B2: Model by: Jay Prakash
B3: Website: https://jay-finance.github.io/portfolio/ | C3: https://jay-finance.github.io/portfolio/

Sheet AutoGovYield
A1: Column1 | B1: Column2 | C1: Column3 | D1: Column4 | E1: Column5 | F1: Column6 | G1: Column7 | H1: Column8 | I1: Column9
C2: Rating | D2: 10Y Bond | E2: 10Y Bond | F2: Bank | G2: Spread vs | H2: Spread vs | I2: Spread vs | K2: DO NOT MAKE ANY CHANGES IN THIS SHEET
B3: Country | C3: S&P | D3: Yield▴ | F3: Rate | G3: Bund | H3: T-Note | I3: Bank Rate
B4: Switzerland | C4: AAA | D4: 0.161% | F4: 0.00% | G4: -254.3 bp | H4: -396.1 bp | I4: 16.1 bp | K4: This is the data of government bond yields collected from world government bonds.
B5: Taiwan | C5: AA+ | D5: 1.320% | F5: 2.00% | G5: -138.4 bp | H5: -280.2 bp | I5: -68.0 bp | K5: I've used power query on the world government bond yield website to automate the data scraping.
B6: Thailand | C6: BBB+ | D6: 1.662% | F6: 1.50% | G6: -104.2 bp | H6: -246.0 bp | I6: 16.2 bp | K6: This table automatically updates the changes in bond yields, so the users will not have to update bond yields. Just refresh the table and you'll have the latest bond yields.
B7: Japan | C7: A+ | D7: 1.771% | F7: 0.50% | G7: -93.3 bp | H7: -235.1 bp | I7: 127.1 bp
B8: China | C8: A+ | D8: 1.815% | F8: 3.00% | G8: -88.9 bp | H8: -230.7 bp | I8: -118.5 bp | K8: Refresh the table when you open the file. | P8: Data > Queries &Connections > Yield's on Government Bonds > Refresh | X8: If you get error, CTRL+Z and Refresh again.
B9: Singapore | C9: AAA | D9: 1.953% | F9: 1.16% | G9: -75.1 bp | H9: -216.9 bp | I9: 79.3 bp
B10: Denmark | C10: AAA | D10: 2.625% | F10: 1.60% | G10: -7.9 bp | H10: -149.7 bp | I10: 102.5 bp | K10: Go to the next sheet for Risk-Free Rate estimations for these countries.
B11: Sweden | C11: AAA | D11: 2.673% | F11: 1.75% | G11: -3.1 bp | H11: -144.9 bp | I11: 92.3 bp | K11: Source: | L11: https://www.worldgovernmentbonds.com/
B12: Germany | C12: AAA | D12: 2.704% | F12: 2.15% | G12: 0.0 bp | H12: -141.8 bp | I12: 55.4 bp
B13: Netherlands | C13: AAA | D13: 2.859% | F13: 2.15% | G13: 15.5 bp | H13: -126.3 bp | I13: 70.9 bp
B14: Ireland | C14: AA | D14: 2.926% | F14: 2.15% | G14: 22.2 bp | H14: -119.6 bp | I14: 77.6 bp
B15: Morocco | C15: BBB- | D15: 2.946% | F15: 2.25% | G15: 24.2 bp | H15: -117.6 bp | I15: 69.6 bp
B16: Hong Kong | C16: AA+ | D16: 2.946% | F16: 4.25% | G16: 24.2 bp | H16: -117.6 bp | I16: -130.4 bp
B17: Austria | C17: AA+ | D17: 2.987% | F17: 2.15% | G17: 28.3 bp | H17: -113.5 bp | I17: 83.7 bp
B18: Slovenia | C18: AA | D18: 2.988% | F18: 2.15% | G18: 28.4 bp | H18: -113.4 bp | I18: 83.8 bp
B19: Cyprus | C19: A- | D19: 3.012% | F19: 2.15% | G19: 30.8 bp | H19: -111.0 bp | I19: 86.2 bp
B20: Portugal | C20: A+ | D20: 3.042% | F20: 2.15% | G20: 33.8 bp | H20: -108.0 bp | I20: 89.2 bp
B21: Finland | C21: AA+ | D21: 3.058% | F21: 2.15% | G21: 35.4 bp | H21: -106.4 bp | I21: 90.8 bp
B22: Croatia | C22: A- | D22: 3.060% | F22: 2.15% | G22: 35.6 bp | H22: -106.2 bp | I22: 91.0 bp
B23: Spain | C23: A+ | D23: 3.202% | F23: 2.15% | G23: 49.8 bp | H23: -92.0 bp | I23: 105.2 bp
... B73: Turkey | C73: BB- | D73: 32.760% | F73: 39.50% | G73: 3005.6 bp | H73: 2863.8 bp | I73: -674.0 bp

Sheet RfrCalculator
B2: Risk-Free Rate Estimation
B4: Country | C4: India
B6: Country 10 Year Government Bond | C6: =VLOOKUP(C4,AutoGovYield!$B$4:$D$73,3,FALSE) -> 6.524%
B7: Country Rating | C7: =IFERROR(VLOOKUP(C4,Ratings!$B$4:$C$160,2,FALSE),VLOOKUP(C4,AutoGovYield!$B$4:$C$73,2,FALSE)) -> Baa3
B9: CDS Net of Switzerland Spread | C9: =VLOOKUP($C$4,RfrCountries!$B$9:$I$78,7,FALSE) -> 0.0067
B10: Rating Based Default Spread | C10: =VLOOKUP($C$4,RfrCountries!$B$9:$I$78,5,FALSE) -> 0.021767594
B12: Risk-Free Rate (Rating) | C12: =VLOOKUP($C$4,RfrCountries!$B$9:$I$78,6,FALSE) -> 0.043472406
B14: Risk-Free Rate (CDS) | C14: =VLOOKUP($C$4,RfrCountries!$B$9:$I$78,8,FALSE) -> 0.05854

Sheet RfrCountries
B2: ="10YR Bond Yields - "&TEXT(TODAY(),"DD MMMM YYYY") -> 10YR Bond Yields - 19 November 2025 | K2: Damodaran lookup table
B4: Country | C4: S&P | D4: Moody's | E4: Yield | F4: Ratings Method | H4: CDS Method | K4: S&P | L4: Moody's | M4: Rating-based
B5: Names | C5: Ratings | D5: Ratings | E5: Rate | F5: Default Spread | G5: Risk Free Rate | H5: CDS Net of US | I5: Risk Free Rate | K5: Ratings | L5: Ratings | M5: Default Spread
B7: =B$58 -> India | C7: =C$58 -> BBB | D7: =D$58 -> Baa3 | E7: =E$58 -> 6.524% | F7: =F$58 -> 0.021767594 | G7: =G$58 -> 0.043472406 | H7: =H$58 -> 0.0067 | I7: =I$58 -> 0.05854
B9: =[1]AutoGovYield!B4 -> Switzerland | C9: =VLOOKUP($B9,AutoGovYield!$B$4:$D$73,2,FALSE) -> AAA | D9: =IFERROR(VLOOKUP(B9,Ratings!$B$4:$C$160,2,FALSE),"NA") -> Aaa | E9: =VLOOKUP($B9,AutoGovYield!$B$4:$D$73,3,FALSE) -> 0.161% | F9: =IFERROR(VLOOKUP(D9,$L$9:$M$31,2,0)/10000,"NA") -> 0 | G9: =IFERROR(E9-F9,"NA") -> 0.00161 | H9: =IFERROR(VLOOKUP(B9,'10yrCDS'!$B$6:$D$95,3,FALSE),"NA") -> 0 | I9: =IFERROR(E9-H9,"NA") -> 0.00161 | K9: ='[1]ERPsCRPs&Spreads'!M8 -> AAA | L9: ='[1]ERPsCRPs&Spreads'!N8 -> Aaa | M9: ='[1]ERPsCRPs&Spreads'!O8 -> 0
B10: =[1]AutoGovYield!B5 -> Taiwan | C10: =VLOOKUP($B10,AutoGovYield!$B$4:$D$73,2,FALSE) -> AA+ | D10: =IFERROR(VLOOKUP(B10,Ratings!$B$4:$C$160,2,FALSE),"NA") -> Aa3 | E10: =VLOOKUP($B10,AutoGovYield!$B$4:$D$73,3,FALSE) -> 1.320% | F10: =IFERROR(VLOOKUP(D10,$L$9:$M$31,2,0)/10000,"NA") -> 0.0059366167 | G10: =IFERROR(E10-F10,"NA") -> 0.0072633833 | H10: =IFERROR(VLOOKUP(B10,'10yrCDS'!$B$6:$D$95,3,FALSE),"NA") -> NA | I10: =IFERROR(E10-H10,"NA") -> NA | K10: ='[1]ERPsCRPs&Spreads'!M9 -> AA+ | L10: ='[1]ERPsCRPs&Spreads'!N9 -> Aa1 | M10: ='[1]ERPsCRPs&Spreads'!O9 -> 39.577444
B11: =[1]AutoGovYield!B6 -> Japan | C11: =VLOOKUP($B11,AutoGovYield!$B$4:$D$73,2,FALSE) -> A+ | D11: =IFERROR(VLOOKUP(B11,Ratings!$B$4:$C$160,2,FALSE),"NA") -> A1 | E11: =VLOOKUP($B11,AutoGovYield!$B$4:$D$73,3,FALSE) -> 1.771% | F11: =IFERROR(VLOOKUP(D11,$L$9:$M$31,2,0)/10000,"NA") -> 0.0069842549 | G11: =IFERROR(E11-F11,"NA") -> 0.010725745 | H11: =IFERROR(VLOOKUP(B11,'10yrCDS'!$B$6:$D$95,3,FALSE),"NA") -> 0.0019 | I11: =IFERROR(E11-H11,"NA") -> 0.01581 | K11: ='[1]ERPsCRPs&Spreads'!M10 -> AA | L11: ='[1]ERPsCRPs&Spreads'!N10 -> Aa2 | M11: ='[1]ERPsCRPs&Spreads'!O10 -> 48.889784
B12: =[1]AutoGovYield!B7 -> Thailand | C12: =VLOOKUP($B12,AutoGovYield!$B$4:$D$73,2,FALSE) -> BBB+ | D12: =IFERROR(VLOOKUP(B12,Ratings!$B$4:$C$160,2,FALSE),"NA") -> Baa1 | E12: =VLOOKUP($B12,AutoGovYield!$B$4:$D$73,3,FALSE) -> 1.662% | F12: =IFERROR(VLOOKUP(D12,$L$9:$M$31,2,0)/10000,"NA") -> 0.015830978 | G12: =IFERROR(E12-F12,"NA") -> 0.00078902223 | H12: =IFERROR(VLOOKUP(B12,'10yrCDS'!$B$6:$D$95,3,FALSE),"NA") -> 0.0055 | I12: =IFERROR(E12-H12,"NA") -> 0.01112 | K12: ='[1]ERPsCRPs&Spreads'!M11 -> AA- | L12: ='[1]ERPsCRPs&Spreads'!N11 -> Aa3 | M12: ='[1]ERPsCRPs&Spreads'!O11 -> 59.366167
B13: =[1]AutoGovYield!B8 -> China | C13: =VLOOKUP($B13,AutoGovYield!$B$4:$D$73,2,FALSE) -> A+ | D13: =IFERROR(VLOOKUP(B13,Ratings!$B$4:$C$160,2,FALSE),"NA") -> A1 | E13: =VLOOKUP($B13,AutoGovYield!$B$4:$D$73,3,FALSE) -> 1.815% | F13: =IFERROR(VLOOKUP(D13,$L$9:$M$31,2,0)/10000,"NA") -> 0.0069842549 | G13: =IFERROR(E13-F13,"NA") -> 0.011165745 | H13: =IFERROR(VLOOKUP(B13,'10yrCDS'!$B$6:$D$95,3,FALSE),"NA") -> 0.0058 | I13: =IFERROR(E13-H13,"NA") -> 0.01235 | K13: ='[1]ERPsCRPs&Spreads'!M12 -> A+ | L13: ='[1]ERPsCRPs&Spreads'!N12 -> A1 | M13: ='[1]ERPsCRPs&Spreads'!O12 -> 69.842549
B14: =[1]AutoGovYield!B9 -> Singapore | C14: =VLOOKUP($B14,AutoGovYield!$B$4:$D$73,2,FALSE) -> AAA | D14: =IFERROR(VLOOKUP(B14,Ratings!$B$4:$C$160,2,FALSE),"NA") -> Aaa | E14: =VLOOKUP($B14,AutoGovYield!$B$4:$D$73,3,FALSE) -> 1.953% | F14: =IFERROR(VLOOKUP(D14,$L$9:$M$31,2,0)/10000,"NA") -> 0 | G14: =IFERROR(E14-F14,"NA") -> 0.01953 | H14: =IFERROR(VLOOKUP(B14,'10yrCDS'!$B$6:$D$95,3,FALSE),"NA") -> NA | I14: =IFERROR(E14-H14,"NA") -> NA | K14: ='[1]ERPsCRPs&Spreads'!M13 -> A | L14: ='[1]ERPsCRPs&Spreads'!N13 -> A2 | M14: ='[1]ERPsCRPs&Spreads'!O13 -> 83.811059
B15: =[1]AutoGovYield!B10 -> Denmark | C15: =VLOOKUP($B15,AutoGovYield!$B$4:$D$73,2,FALSE) -> AAA | D15: =IFERROR(VLOOKUP(B15,Ratings!$B$4:$C$160,2,FALSE),"NA") -> Aaa | E15: =VLOOKUP($B15,AutoGovYield!$B$4:$D$73,3,FALSE) -> 2.625% | F15: =IFERROR(VLOOKUP(D15,$L$9:$M$31,2,0)/10000,"NA") -> 0 | G15: =IFERROR(E15-F15,"NA") -> 0.02625 | H15: =IFERROR(VLOOKUP(B15,'10yrCDS'!$B$6:$D$95,3,FALSE),"NA") -> 0.0004 | I15: =IFERROR(E15-H15,"NA") -> 0.02585 | K15: ='[1]ERPsCRPs&Spreads'!M14 -> A- | L15: ='[1]ERPsCRPs&Spreads'!N14 -> A3 | M15: ='[1]ERPsCRPs&Spreads'!O14 -> 118.73233
B16: =[1]AutoGovYield!B11 -> Sweden | C16: =VLOOKUP($B16,AutoGovYield!$B$4:$D$73,2,FALSE) -> AAA | D16: =IFERROR(VLOOKUP(B16,Ratings!$B$4:$C$160,2,FALSE),"NA") -> Aaa | E16: =VLOOKUP($B16,AutoGovYield!$B$4:$D$73,3,FALSE) -> 2.673% | F16: =IFERROR(VLOOKUP(D16,$L$9:$M$31,2,0)/10000,"NA") -> 0 | G16: =IFERROR(E16-F16,"NA") -> 0.02673 | H16: =IFERROR(VLOOKUP(B16,'10yrCDS'!$B$6:$D$95,3,FALSE),"NA") -> 0.0008 | I16: =IFERROR(E16-H16,"NA") -> 0.02593 | K16: ='[1]ERPsCRPs&Spreads'!M15 -> BBB+ | L16: ='[1]ERPsCRPs&Spreads'!N15 -> Baa1 | M16: ='[1]ERPsCRPs&Spreads'!O15 -> 158.30978
B17: =[1]AutoGovYield!B12 -> Germany | C17: =VLOOKUP($B17,AutoGovYield!$B$4:$D$73,2,FALSE) -> AAA | D17: =IFERROR(VLOOKUP(B17,Ratings!$B$4:$C$160,2,FALSE),"NA") -> Aaa | E17: =VLOOKUP($B17,AutoGovYield!$B$4:$D$73,3,FALSE) -> 2.704% | F17: =IFERROR(VLOOKUP(D17,$L$9:$M$31,2,0)/10000,"NA") -> 0 | G17: =IFERROR(E17-F17,"NA") -> 0.02704 | H17: =IFERROR(VLOOKUP(B17,'10yrCDS'!$B$6:$D$95,3,FALSE),"NA") -> 0.0007 | I17: =IFERROR(E17-H17,"NA") -> 0.02634 | K17: ='[1]ERPsCRPs&Spreads'!M16 -> BBB | L17: ='[1]ERPsCRPs&Spreads'!N16 -> Baa2 | M17: ='[1]ERPsCRPs&Spreads'!O16 -> 188.57488
B18: =[1]AutoGovYield!B13 -> Netherlands | C18: =VLOOKUP($B18,AutoGovYield!$B$4:$D$73,2,FALSE) -> AAA | D18: =IFERROR(VLOOKUP(B18,Ratings!$B$4:$C$160,2,FALSE),"NA") -> Aaa | E18: =VLOOKUP($B18,AutoGovYield!$B$4:$D$73,3,FALSE) -> 2.859% | F18: =IFERROR(VLOOKUP(D18,$L$9:$M$31,2,0)/10000,"NA") -> 0 | G18: =IFERROR(E18-F18,"NA") -> 0.02859 | H18: =IFERROR(VLOOKUP(B18,'10yrCDS'!$B$6:$D$95,3,FALSE),"NA") -> 0.0008 | I18: =IFERROR(E18-H18,"NA") -> 0.02779 | K18: ='[1]ERPsCRPs&Spreads'!M17 -> BBB- | L18: ='[1]ERPsCRPs&Spreads'!N17 -> Baa3 | M18: ='[1]ERPsCRPs&Spreads'!O17 -> 217.67594
B19: =[1]AutoGovYield!B14 -> Ireland | C19: =VLOOKUP($B19,AutoGovYield!$B$4:$D$73,2,FALSE) -> AA | D19: =IFERROR(VLOOKUP(B19,Ratings!$B$4:$C$160,2,FALSE),"NA") -> Aa3 | E19: =VLOOKUP($B19,AutoGovYield!$B$4:$D$73,3,FALSE) -> 2.926% | F19: =IFERROR(VLOOKUP(D19,$L$9:$M$31,2,0)/10000,"NA") -> 0.0059366167 | G19: =IFERROR(E19-F19,"NA") -> 0.023323383 | H19: =IFERROR(VLOOKUP(B19,'10yrCDS'!$B$6:$D$95,3,FALSE),"NA") -> 0.0021 | I19: =IFERROR(E19-H19,"NA") -> 0.02716 | K19: ='[1]ERPsCRPs&Spreads'!M18 -> BB+ | L19: ='[1]ERPsCRPs&Spreads'!N18 -> Ba1 | M19: ='[1]ERPsCRPs&Spreads'!O18 -> 247.94105
B20: =[1]AutoGovYield!B15 -> Morocco | C20: =VLOOKUP($B20,AutoGovYield!$B$4:$D$73,2,FALSE) -> BBB- | D20: =IFERROR(VLOOKUP(B20,Ratings!$B$4:$C$160,2,FALSE),"NA") -> Ba1 | E20: =VLOOKUP($B20,AutoGovYield!$B$4:$D$73,3,FALSE) -> 2.946% | F20: =IFERROR(VLOOKUP(D20,$L$9:$M$31,2,0)/10000,"NA") -> 0.024794105 | G20: =IFERROR(E20-F20,"NA") -> 0.0046658951 | H20: =IFERROR(VLOOKUP(B20,'10yrCDS'!$B$6:$D$95,3,FALSE),"NA") -> 0.0143 | I20: =IFERROR(E20-H20,"NA") -> 0.01516 | K20: ='[1]ERPsCRPs&Spreads'!M19 -> BB | L20: ='[1]ERPsCRPs&Spreads'!N19 -> Ba2 | M20: ='[1]ERPsCRPs&Spreads'!O19 -> 297.99488
... B31: =[1]AutoGovYield!B26 -> South Korea | C31: =VLOOKUP($B31,AutoGovYield!$B$4:$D$73,2,FALSE) -> AA | D31: =IFERROR(VLOOKUP(B31,Ratings!$B$4:$C$160,2,FALSE),"NA") -> NA | E31: =VLOOKUP($B31,AutoGovYield!$B$4:$D$73,3,FALSE) -> 3.285% | F31: =IFERROR(VLOOKUP(D31,$L$9:$M$31,2,0)/10000,"NA") -> NA | G31: =IFERROR(E31-F31,"NA") -> NA | H31: =IFERROR(VLOOKUP(B31,'10yrCDS'!$B$6:$D$95,3,FALSE),"NA") -> NA | I31: =IFERROR(E31-H31,"NA") -> NA | K31: ='[1]ERPsCRPs&Spreads'!M30 -> NR | L31: ='[1]ERPsCRPs&Spreads'!N30 -> NR | M31: ='[1]ERPsCRPs&Spreads'!O30 -> NA
B32: =[1]AutoGovYield!B27 -> Malta | C32: =VLOOKUP($B32,AutoGovYield!$B$4:$D$73,2,FALSE) -> A- | D32: =IFERROR(VLOOKUP(B32,Ratings!$B$4:$C$160,2,FALSE),"NA") -> A2 | E32: =VLOOKUP($B32,AutoGovYield!$B$4:$D$73,3,FALSE) -> 3.245% | F32: =IFERROR(VLOOKUP(D32,$L$9:$M$31,2,0)/10000,"NA") -> 0.0083811059 | G32: =IFERROR(E32-F32,"NA") -> 0.024068894 | H32: =IFERROR(VLOOKUP(B32,'10yrCDS'!$B$6:$D$95,3,FALSE),"NA") -> NA | I32: =IFERROR(E32-H32,"NA") -> NA
B33: =[1]AutoGovYield!B28 -> Greece | C33: =VLOOKUP($B33,AutoGovYield!$B$4:$D$73,2,FALSE) -> BBB | D33: =IFERROR(VLOOKUP(B33,Ratings!$B$4:$C$160,2,FALSE),"NA") -> Ba1 | E33: =VLOOKUP($B33,AutoGovYield!$B$4:$D$73,3,FALSE) -> 3.337% | F33: =IFERROR(VLOOKUP(D33,$L$9:$M$31,2,0)/10000,"NA") -> 0.024794105 | G33: =IFERROR(E33-F33,"NA") -> 0.0085758951 | H33: =IFERROR(VLOOKUP(B33,'10yrCDS'!$B$6:$D$95,3,FALSE),"NA") -> 0.0087 | I33: =IFERROR(E33-H33,"NA") -> 0.02467
B34: =[1]AutoGovYield!B29 -> Slovakia | C34: =VLOOKUP($B34,AutoGovYield!$B$4:$D$73,2,FALSE) -> A+ | D34: =IFERROR(VLOOKUP(B34,Ratings!$B$4:$C$160,2,FALSE),"NA") -> A3 | E34: =VLOOKUP($B34,AutoGovYield!$B$4:$D$73,3,FALSE) -> 3.414% | F34: =IFERROR(VLOOKUP(D34,$L$9:$M$31,2,0)/10000,"NA") -> 0.011873233 | G34: =IFERROR(E34-F34,"NA") -> 0.022266767 | H34: =IFERROR(VLOOKUP(B34,'10yrCDS'!$B$6:$D$95,3,FALSE),"NA") -> 0.0044 | I34: =IFERROR(E34-H34,"NA") -> 0.02974
B35: =[1]AutoGovYield!B30 -> Italy | C35: =VLOOKUP($B35,AutoGovYield!$B$4:$D$73,2,FALSE) -> BBB+ | D35: =IFERROR(VLOOKUP(B35,Ratings!$B$4:$C$160,2,FALSE),"NA") -> Baa3 | E35: =VLOOKUP($B35,AutoGovYield!$B$4:$D$73,3,FALSE) -> 3.447% | F35: =IFERROR(VLOOKUP(D35,$L$9:$M$31,2,0)/10000,"NA") -> 0.021767594 | G35: =IFERROR(E35-F35,"NA") -> 0.012702406 | H35: =IFERROR(VLOOKUP(B35,'10yrCDS'!$B$6:$D$95,3,FALSE),"NA") -> 0.0081 | I35: =IFERROR(E35-H35,"NA") -> 0.02637
B36: =[1]AutoGovYield!B31 -> France | C36: =VLOOKUP($B36,AutoGovYield!$B$4:$D$73,2,FALSE) -> A+ | D36: =IFERROR(VLOOKUP(B36,Ratings!$B$4:$C$160,2,FALSE),"NA") -> Aa3 | E36: =VLOOKUP($B36,AutoGovYield!$B$4:$D$73,3,FALSE) -> 3.453% | F36: =IFERROR(VLOOKUP(D36,$L$9:$M$31,2,0)/10000,"NA") -> 0.0059366167 | G36: =IFERROR(E36-F36,"NA") -> 0.028593383 | H36: =IFERROR(VLOOKUP(B36,'10yrCDS'!$B$6:$D$95,3,FALSE),"NA") -> 0.0051 | I36: =IFERROR(E36-H36,"NA") -> 0.02943
B37: =[1]AutoGovYield!B32 -> Lithuania | C37: =VLOOKUP($B37,AutoGovYield!$B$4:$D$73,2,FALSE) -> A | D37: =IFERROR(VLOOKUP(B37,Ratings!$B$4:$C$160,2,FALSE),"NA") -> A2 | E37: =VLOOKUP($B37,AutoGovYield!$B$4:$D$73,3,FALSE) -> 3.530% | F37: =IFERROR(VLOOKUP(D37,$L$9:$M$31,2,0)/10000,"NA") -> 0.0083811059 | G37: =IFERROR(E37-F37,"NA") -> 0.026918894 | H37: =IFERROR(VLOOKUP(B37,'10yrCDS'!$B$6:$D$95,3,FALSE),"NA") -> 0.0073 | I37: =IFERROR(E37-H37,"NA") -> 0.028
B38: =[1]AutoGovYield!B33 -> Malaysia | C38: =VLOOKUP($B38,AutoGovYield!$B$4:$D$73,2,FALSE) -> A- | D38: =IFERROR(VLOOKUP(B38,Ratings!$B$4:$C$160,2,FALSE),"NA") -> A3 | E38: =VLOOKUP($B38,AutoGovYield!$B$4:$D$73,3,FALSE) -> 3.447% | F38: =IFERROR(VLOOKUP(D38,$L$9:$M$31,2,0)/10000,"NA") -> 0.011873233 | G38: =IFERROR(E38-F38,"NA") -> 0.022596767 | H38: =IFERROR(VLOOKUP(B38,'10yrCDS'!$B$6:$D$95,3,FALSE),"NA") -> 0.0064 | I38: =IFERROR(E38-H38,"NA") -> 0.02807
B39: =[1]AutoGovYield!B34 -> Bulgaria | C39: =VLOOKUP($B39,AutoGovYield!$B$4:$D$73,2,FALSE) -> BBB+ | D39: =IFERROR(VLOOKUP(B39,Ratings!$B$4:$C$160,2,FALSE),"NA") -> Baa1 | E39: =VLOOKUP($B39,AutoGovYield!$B$4:$D$73,3,FALSE) -> 3.908% | F39: =IFERROR(VLOOKUP(D39,$L$9:$M$31,2,0)/10000,"NA") -> 0.015830978 | G39: =IFERROR(E39-F39,"NA") -> 0.023249022 | H39: =IFERROR(VLOOKUP(B39,'10yrCDS'!$B$6:$D$95,3,FALSE),"NA") -> 0.0095 | I39: =IFERROR(E39-H39,"NA") -> 0.02958
B40: =[1]AutoGovYield!B35 -> Israel | C40: =VLOOKUP($B40,AutoGovYield!$B$4:$D$73,2,FALSE) -> A | D40: =IFERROR(VLOOKUP(B40,Ratings!$B$4:$C$160,2,FALSE),"NA") -> Baa1 | E40: =VLOOKUP($B40,AutoGovYield!$B$4:$D$73,3,FALSE) -> 3.905% | F40: =IFERROR(VLOOKUP(D40,$L$9:$M$31,2,0)/10000,"NA") -> 0.015830978 | G40: =IFERROR(E40-F40,"NA") -> 0.023219022 | H40: =IFERROR(VLOOKUP(B40,'10yrCDS'!$B$6:$D$95,3,FALSE),"NA") -> 0.0122 | I40: =IFERROR(E40-H40,"NA") -> 0.02685
B41: =[1]AutoGovYield!B36 -> Vietnam | C41: =VLOOKUP($B41,AutoGovYield!$B$4:$D$73,2,FALSE) -> BB+ | D41: =IFERROR(VLOOKUP(B41,Ratings!$B$4:$C$160,2,FALSE),"NA") -> Ba2 | E41: =VLOOKUP($B41,AutoGovYield!$B$4:$D$73,3,FALSE) -> 4.000% | F41: =IFERROR(VLOOKUP(D41,$L$9:$M$31,2,0)/10000,"NA") -> 0.029799488 | G41: =IFERROR(E41-F41,"NA") -> 0.010200512 | H41: =IFERROR(VLOOKUP(B41,'10yrCDS'!$B$6:$D$95,3,FALSE),"NA") -> 0.014 | I41: =IFERROR(E41-H41,"NA") -> 0.026
B42: =[1]AutoGovYield!B37 -> United States | C42: =VLOOKUP($B42,AutoGovYield!$B$4:$D$73,2,FALSE) -> AA+ | D42: =IFERROR(VLOOKUP(B42,Ratings!$B$4:$C$160,2,FALSE),"NA") -> Aaa | E42: =VLOOKUP($B42,AutoGovYield!$B$4:$D$73,3,FALSE) -> 4.122% | F42: =IFERROR(VLOOKUP(D42,$L$9:$M$31,2,0)/10000,"NA") -> 0 | G42: =IFERROR(E42-F42,"NA") -> 0.04122 | H42: =IFERROR(VLOOKUP(B42,'10yrCDS'!$B$6:$D$95,3,FALSE),"NA") -> 0.0033 | I42: =IFERROR(E42-H42,"NA") -> 0.03792
B43: =[1]AutoGovYield!B38 -> Norway | C43: =VLOOKUP($B43,AutoGovYield!$B$4:$D$73,2,FALSE) -> AAA | D43: =IFERROR(VLOOKUP(B43,Ratings!$B$4:$C$160,2,FALSE),"NA") -> Aaa | E43: =VLOOKUP($B43,AutoGovYield!$B$4:$D$73,3,FALSE) -> 4.145% | F43: =IFERROR(VLOOKUP(D43,$L$9:$M$31,2,0)/10000,"NA") -> 0 | G43: =IFERROR(E43-F43,"NA") -> 0.04145 | H43: =IFERROR(VLOOKUP(B43,'10yrCDS'!$B$6:$D$95,3,FALSE),"NA") -> 0.0005 | I43: =IFERROR(E43-H43,"NA") -> 0.04095
... B78: =[1]AutoGovYield!B73 -> Turkey | C78: =VLOOKUP($B78,AutoGovYield!$B$4:$D$73,2,FALSE) -> BB- | D78: =IFERROR(VLOOKUP(B78,Ratings!$B$4:$C$160,2,FALSE),"NA") -> B1 | E78: =VLOOKUP($B78,AutoGovYield!$B$4:$D$73,3,FALSE) -> 32.760% | F78: =IFERROR(VLOOKUP(D78,$L$9:$M$31,2,0)/10000,"NA") -> 0.044582827 | G78: =IFERROR(E78-F78,"NA") -> 0.28301717 | H78: =IFERROR(VLOOKUP(B78,'10yrCDS'!$B$6:$D$95,3,FALSE),"NA") -> 0.0363 | I78: =IFERROR(E78-H78,"NA") -> 0.2913

Sheet 10yrCDS
B3: Switzerland | C3: 0.0017
B5: Country | C5: 44377 | D5: CDS Spread net of Switzerland
B6: Abu Dhabi | C6: 0.0068 | D6: =IF(C6="NA","NA",IF(C6<$C$3,0,C6-$C$3)) -> 0.0051
B7: Algeria | C7: 0.014 | D7: =IF(C7="NA","NA",IF(C7<$C$3,0,C7-$C$3)) -> 0.0123
B8: Angola | C8: 0.0716 | D8: =IF(C8="NA","NA",IF(C8<$C$3,0,C8-$C$3)) -> 0.0699
B9: Argentina | C9: 0.0837 | D9: =IF(C9="NA","NA",IF(C9<$C$3,0,C9-$C$3)) -> 0.082
B10: Australia | C10: 0.0018 | D10: =IF(C10="NA","NA",IF(C10<$C$3,0,C10-$C$3)) -> 0.0001
B11: Austria | C11: 0.0032 | D11: =IF(C11="NA","NA",IF(C11<$C$3,0,C11-$C$3)) -> 0.0015
B12: Bahrain | C12: 0.0279 | D12: =IF(C12="NA","NA",IF(C12<$C$3,0,C12-$C$3)) -> 0.0262
B13: Belgium | C13: 0.005 | D13: =IF(C13="NA","NA",IF(C13<$C$3,0,C13-$C$3)) -> 0.0033
B14: Brazil | C14: 0.0255 | D14: =IF(C14="NA","NA",IF(C14<$C$3,0,C14-$C$3)) -> 0.0238
B15: Bulgaria | C15: 0.0112 | D15: =IF(C15="NA","NA",IF(C15<$C$3,0,C15-$C$3)) -> 0.0095
B16: Cameroon | C16: 0.0803 | D16: =IF(C16="NA","NA",IF(C16<$C$3,0,C16-$C$3)) -> 0.0786
B17: Canada | C17: 0.0037 | D17: =IF(C17="NA","NA",IF(C17<$C$3,0,C17-$C$3)) -> 0.002
... B30: Estonia | C30: 0.0093 | D30: =IF(C30="NA","NA",IF(C30<$C$3,0,C30-$C$3)) -> 0.0076
B31: Ethiopia | C31: NA | D31: =IF(C31="NA","NA",IF(C31<$C$3,0,C31-$C$3)) -> NA
B32: Finland | C32: 0.0032 | D32: =IF(C32="NA","NA",IF(C32<$C$3,0,C32-$C$3)) -> 0.0015
B33: France | C33: 0.0068 | D33: =IF(C33="NA","NA",IF(C33<$C$3,0,C33-$C$3)) -> 0.0051
B34: Gabon | C34: 0.0786 | D34: =IF(C34="NA","NA",IF(C34<$C$3,0,C34-$C$3)) -> 0.0769
B35: Germany | C35: 0.0024 | D35: =IF(C35="NA","NA",IF(C35<$C$3,0,C35-$C$3)) -> 0.0007
B36: Greece | C36: 0.0104 | D36: =IF(C36="NA","NA",IF(C36<$C$3,0,C36-$C$3)) -> 0.0087
B37: Guatemala | C37: 0.0221 | D37: =IF(C37="NA","NA",IF(C37<$C$3,0,C37-$C$3)) -> 0.0204
B38: Hong Kong | C38: 0.0059 | D38: =IF(C38="NA","NA",IF(C38<$C$3,0,C38-$C$3)) -> 0.0042
B39: Hungary | C39: 0.0183 | D39: =IF(C39="NA","NA",IF(C39<$C$3,0,C39-$C$3)) -> 0.0166
B40: Iceland | C40: 0.0047 | D40: =IF(C40="NA","NA",IF(C40<$C$3,0,C40-$C$3)) -> 0.003
B41: India | C41: 0.0084 | D41: =IF(C41="NA","NA",IF(C41<$C$3,0,C41-$C$3)) -> 0.0067
B42: Indonesia | C42: 0.0134 | D42: =IF(C42="NA","NA",IF(C42<$C$3,0,C42-$C$3)) -> 0.0117
B43: Iraq | C43: 0.0405 | D43: =IF(C43="NA","NA",IF(C43<$C$3,0,C43-$C$3)) -> 0.0388
... B52: Latvia | C52: 0.0098 | D52: =IF(C52="NA","NA",IF(C52<$C$3,0,C52-$C$3)) -> 0.0081
B53: Lebanon | C53: NA | D53: =IF(C53="NA","NA",IF(C53<$C$3,0,C53-$C$3)) -> NA
B54: Lithuania | C54: 0.009 | D54: =IF(C54="NA","NA",IF(C54<$C$3,0,C54-$C$3)) -> 0.0073
B55: Malaysia | C55: 0.0081 | D55: =IF(C55="NA","NA",IF(C55<$C$3,0,C55-$C$3)) -> 0.0064
B56: Mexico | C56: 0.0186 | D56: =IF(C56="NA","NA",IF(C56<$C$3,0,C56-$C$3)) -> 0.0169
B57: Mongolia | C57: 0.0438 | D57: =IF(C57="NA","NA",IF(C57<$C$3,0,C57-$C$3)) -> 0.0421
B58: Morocco | C58: 0.016 | D58: =IF(C58="NA","NA",IF(C58<$C$3,0,C58-$C$3)) -> 0.0143
B59: Namibia | C59: 0.0365 | D59: =IF(C59="NA","NA",IF(C59<$C$3,0,C59-$C$3)) -> 0.0348
B60: Netherlands | C60: 0.0025 | D60: =IF(C60="NA","NA",IF(C60<$C$3,0,C60-$C$3)) -> 0.0008
B61: New Zealand | C61: 0.0023 | D61: =IF(C61="NA","NA",IF(C61<$C$3,0,C61-$C$3)) -> 0.0006
B62: Nicaragua | C62: 0.0637 | D62: =IF(C62="NA","NA",IF(C62<$C$3,0,C62-$C$3)) -> 0.062
B63: Nigeria | C63: 0.0605 | D63: =IF(C63="NA","NA",IF(C63<$C$3,0,C63-$C$3)) -> 0.0588
...

Sheet Ratings
B2: Country | C2: Moody's Rating | D2: S&P Rating | E2: FITCH Rating
B4: Abu Dhabi | C4: Aa2 | D4: NR | E4: NR
B5: Albania | C5: Ba3 | D5: BB- | E5: NR
B6: Andorra (Principality of) | C6: Baa1 | D6: A- | E6: A-
B7: Angola | C7: B3 | D7: B- | E7: B-
B8: Argentina | C8: Ca | D8: CCC | E8: CCC
B9: Armenia | C9: Ba3 | D9: BB- | E9: B+
B10: Aruba | C10: Baa3 | D10: BBB | E10: NR
B11: Australia | C11: Aaa | D11: AAA | E11: AAA
B12: Austria | C12: Aa1 | D12: AA+ | E12: AA+
B13: Azerbaijan | C13: Ba1 | D13: BB+ | E13: BB+
B14: Bahamas | C14: B1 | D14: B+ | E14: NR
... B42: Croatia | C42: A3 | D42: A- | E42: BBB+
B43: Cuba | C43: Ca | D43: 0 | E43: NR
B44: Curacao | C44: Baa3 | D44: BBB- | E44: NR
B45: Cyprus | C45: A3 | D45: A- | E45: A-
B46: Czech Republic | C46: Aa3 | D46: AA- | E46: AA-
B47: Denmark | C47: Aaa | D47: AAA | E47: AAA
B48: Dominican Republic | C48: Ba3 | D48: BB | E48: BB-
B49: Ecuador | C49: Caa3 | D49: B- | E49: CCC+
B50: Egypt | C50: Caa1 | D50: B- | E50: B-
B51: El Salvador | C51: B3 | D51: B- | E51: CC
B52: Estonia | C52: A1 | D52: NR | E52: AA-
B53: Ethiopia | C53: Caa2 | D53: SD | E53: NR
B54: Fiji | C54: B1 | D54: B+ | E54: NR
B55: Finland | C55: Aa1 | D55: AA+ | E55: AA+
... B83: Kyrgyzstan | C83: B3 | D83: NR | E83: NR
B84: Laos | C84: Caa3 | D84: 0 | E84: CCC-
B85: Latvia | C85: A3 | D85: A | E85: A-
B86: Lebanon | C86: C | D86: D | E86: NR
B87: Liechtenstein | C87: Aaa | D87: AAA | E87: NR
B88: Lithuania | C88: A2 | D88: A | E88: A
B89: Luxembourg | C89: Aaa | D89: AAA | E89: AAA
B90: Macao | C90: Aa3 | D90: NR | E90: NR
B91: Macedonia | C91: Ba3 | D91: BB- | E91: NR
B92: Malaysia | C92: A3 | D92: A- | E92: BBB+
B93: Maldives | C93: Caa2 | D93: 0 | E93: CC
B94: Mali | C94: Caa2 | D94: 0 | E94: NR
B95: Malta | C95: A2 | D95: A- | E95: A+
B96: Mauritius | C96: Baa3 | D96: BBB- | E96: NR
...
