Workbook

Sheet ReadThis
B2: Model by: | C2: Jay Prakash
B3: Website: | C3: https://jay-finance.github.io/portfolio/

Sheet IntrinsicValue
C2: Valuing The | D2: S&P 500 INDEX | H2: Total Yield | I2: EPS Growth | J2: RFR | K2: ERP
B3: Index | C3: Previous Close | D3: Ticker Symbol | E3: Intrinsic Value | H3: 20 YRS | I3: 3YRS | J3: 20 YRS Bond Rate | K3: 15 YRS
H4: 15 YRS | I4: 5YRS | J4: 15 YRS Bond Rate | K4: 10YRS
B5: =D2 -> S&P 500 INDEX | C5: =C9 -> 6617.32 | D5: SPX | E5: =IF(OR(C9="",C10="",C11="",C12="",C13=""),"Provide Required Data",SUM(E17:E26)) -> 6017.3289 | H5: 10YRS | I5: 7YRS | J5: 10YRS Bond Rate | K5: 7 YRS
E6: =IF(OR(C9="",C10="",C11="",C12="",C13=""),"Provide Required Data",IF(E5>((1+0.05)*C5),"UNDERVALUED",IF(E5<((1-0.05)*C5),"OVERVALUED","FAIRLY VALUED"))) -> OVERVALUED | H6: 7 YRS | I6: 10YRS | J6: 7 YRS Bond Rate | K6: 5 YRS
B7: Key Inputs | D7: Assumptions | H7: 5 YRS | J7: 5 YRS Bond Rate
B8: Date | C8: =TODAY() -> 45980 | D8: =C8 -> 45980 | E8: =IF(OR(C9="",C10="",C11="",C12="",C13=""),"Provide Required Data","The Market Implied Fair Value of "&B5&" is "&TEXT(ROUNDUP(E5,0),"0,000")&". "&B5&" is Currently Trading at "&TEXT(ROUNDUP(C5,0),"0,000")&". A "&TEXT(ABS((C5-E5)/C5),"0.00%")&IF(E6="OVERVALUED"," Correction"," Appriciation")&" Expected from this Level.") -> The Market Implied Fair Value of S&P 500 INDEX is 6,018. S&P 500 INDEX is Currently Trading at 6,618. A 9.07% Correction Expected from this Level. | H8: Latest | J8: Latest Bond Rate
B9: ="Current "&D5&" Level" -> Current SPX Level | C9: 6617.32 | D9: =C9 -> 6617.32 | J9: Latest
B10: Total Yield | C10: 10YRS | D10: =VLOOKUP(C10,'ExpectedBB&Dividends'!Q4:R14,2,FALSE) -> 0.041998155
B11: Expected Growth | C11: 10YRS | D11: =VLOOKUP(C11,EPSGrowth!K4:L10,2,FALSE) -> 0.066775799
B12: Risk-Free Rate | C12: Latest | D12: =VLOOKUP(C12,RFRData!$M$8:$N$20,2,FALSE) -> 0.0411
B13: Equity Risk Premium | C13: 10YRS | D13: =VLOOKUP(C13,ERPData!$I$4:$J$11,2,FALSE) -> 0.054605
B14: Cost of Equity | D14: =D12+D13 -> 0.095705
B16: Year | C16: Expected Dividends &Buybacks | D16: Discounting Period | E16: Present Value of Expected Dividends & Buybacks
B17: =YEAR(C8) -> 2025 | C17: =$D$9*$D$10*(1+$D$11)^(B17-($B$17-1)) -> 296.47324 | D17: =MONTH($C$8)/12 -> 0.91666667 | E17: =(C17*D17)/(1+D14)^D17 -> 249.92581
B18: =B17+1 -> 2026 | C18: =$D$9*$D$10*(1+$D$11)^(B18-($B$17-1)) -> 316.27048 | D18: =D17+(B18-B17) -> 1.9166667 | E18: =C18/(1+$D$14)^D18 -> 265.44783
B19: =B18+1 -> 2027 | C19: =$D$9*$D$10*(1+$D$11)^(B19-($B$17-1)) -> 337.38969 | D19: =D18+(B19-B18) -> 2.9166667 | E19: =C19/(1+$D$14)^D19 -> 258.43938
B20: =B19+1 -> 2028 | C20: =$D$9*$D$10*(1+$D$11)^(B20-($B$17-1)) -> 359.91916 | D20: =D19+(B20-B19) -> 3.9166667 | E20: =C20/(1+$D$14)^D20 -> 251.61597
B21: =B20+1 -> 2029 | C21: =$D$9*$D$10*(1+$D$11)^(B21-($B$17-1)) -> 383.95305 | D21: =D20+(B21-B20) -> 4.9166667 | E21: =C21/(1+$D$14)^D21 -> 244.97271
B22: =B21+1 -> 2030 | C22: =$D$9*$D$10*(1+$D$11)^(B22-($B$17-1)) -> 409.59182 | D22: =D21+(B22-B21) -> 5.9166667 | E22: =C22/(1+$D$14)^D22 -> 238.50485
B23: =B22+1 -> 2031 | C23: =$D$9*$D$10*(1+$D$11)^(B23-($B$17-1)) -> 436.94264 | D23: =D22+(B23-B22) -> 6.9166667 | E23: =C23/(1+$D$14)^D23 -> 232.20776
B24: =B23+1 -> 2032 | C24: =$D$9*$D$10*(1+$D$11)^(B24-($B$17-1)) -> 466.11983 | D24: =D23+(B24-B23) -> 7.9166667 | E24: =C24/(1+$D$14)^D24 -> 226.07693
B25: =B24+1 -> 2033 | C25: =$D$9*$D$10*(1+$D$11)^(B25-($B$17-1)) -> 497.24536 | D25: =D24+(B25-B24) -> 8.9166667 | E25: =C25/(1+$D$14)^D25 -> 220.10796
B26: =B25+1 -> 2034 | C26: =C25*(1+D12)/(D14-D12) -> 9480.4898 | D26: =D25+(B26-B25) -> 9.9166667 | E26: =C26/(1+$D$14)^D26 -> 3830.0297

Sheet impliedERP
B2: Implied ERP S&P 500 INDEX
B3: Index | C3: Previous Close | D3: Ticker Symbol | E3: Intrinsic Value
B4: S&P 500 INDEX | C4: =IntrinsicValue!C9 -> 6617.32 | D4: SPX | E4: =SUM(E15:E24) -> 6617.32
B6: =IntrinsicValue!B12 -> Risk-Free Rate | C6: =IntrinsicValue!D12 -> 0.0411
B7: =IntrinsicValue!B13 -> Equity Risk Premium | C7: =IntrinsicValue!D13 -> 0.054605
B8: Cost of Equity 1 | C8: =C6+C7 -> 0.095705
B10: Cost of Equity 2 | C10: 0.082919701 | D10: < Hardcode the existing Ke, as goalseek doesn’t run on formulas.
B12: Implied ERP | C12: =C10-C6 -> 0.041819701
B14: Years | C14: Cash Flows | D14: Discounting Period | E14: PV of cash flows
B15: 1 | C15: =IntrinsicValue!C17 -> 296.47324 | D15: =IntrinsicValue!D17 -> 0.91666667 | E15: =(C15*D15)/(1+C10)^D15 -> 252.62929
B16: =B15+1 -> 2 | C16: =IntrinsicValue!C18 -> 316.27048 | D16: =IntrinsicValue!D18 -> 1.9166667 | E16: =C16/(1+$C$10)^D16 -> 271.48708
B17: =B16+1 -> 3 | C17: =IntrinsicValue!C19 -> 337.38969 | D17: =IntrinsicValue!D19 -> 2.9166667 | E17: =C17/(1+$C$10)^D17 -> 267.43982
B18: =B17+1 -> 4 | C18: =IntrinsicValue!C20 -> 359.91916 | D18: =IntrinsicValue!D20 -> 3.9166667 | E18: =C18/(1+$C$10)^D18 -> 263.45289
B19: =B18+1 -> 5 | C19: =IntrinsicValue!C21 -> 383.95305 | D19: =IntrinsicValue!D21 -> 4.9166667 | E19: =C19/(1+$C$10)^D19 -> 259.5254
B20: =B19+1 -> 6 | C20: =IntrinsicValue!C22 -> 409.59182 | D20: =IntrinsicValue!D22 -> 5.9166667 | E20: =C20/(1+$C$10)^D20 -> 255.65646
B21: =B20+1 -> 7 | C21: =IntrinsicValue!C23 -> 436.94264 | D21: =IntrinsicValue!D23 -> 6.9166667 | E21: =C21/(1+$C$10)^D21 -> 251.84519
B22: =B21+1 -> 8 | C22: =IntrinsicValue!C24 -> 466.11983 | D22: =IntrinsicValue!D24 -> 7.9166667 | E22: =C22/(1+$C$10)^D22 -> 248.09075
B23: =B22+1 -> 9 | C23: =IntrinsicValue!C25 -> 497.24536 | D23: =IntrinsicValue!D25 -> 8.9166667 | E23: =C23/(1+$C$10)^D23 -> 244.39227
B24: =B23+1 -> 10 | C24: =IntrinsicValue!C26 -> 9480.4898 | D24: =IntrinsicValue!D26 -> 9.9166667 | E24: =C24/(1+$C$10)^D24 -> 4302.8009

Sheet Data>

Sheet ExpectedBB&Dividends
B2: Dividends Data | G2: Buybacks Data | L2: Total Earnings Data
B3: Year | C3: S&P500 Price | D3: Dividends Yield | E3: Dividend Amount | G3: Year | H3: S&P500 Price | I3: Buybacks Amount | J3: Buybacks Yield | L3: Year | M3: Total Earnings | N3: Total Earnings Yield
B4: 2001 | C4: ='s&pAllData'!C44 -> 1148.09 | D4: ='s&pAllData'!F44 -> 0.0137 | E4: =D4*C4 -> 15.728833 | G4: 2001 | H4: ='s&pAllData'!C44 -> 1148.09 | I4: ='s&pAllData'!I44 -> 14.351167 | J4: =I4/H4 -> 0.012500037 | L4: =G4 -> 2001 | M4: =I4+E4 -> 30.08 | N4: =M4/H4 -> 0.026200037 | P4: Average S&P500 Earnings Yield- | Q4: 20 YRS | R4: =AVERAGE(N8:N27) -> 0.047254655
B5: =B4+1 -> 2002 | C5: ='s&pAllData'!C45 -> 879.82 | D5: ='s&pAllData'!F45 -> 0.0181 | E5: =D5*C5 -> 15.924742 | G5: =G4+1 -> 2002 | H5: ='s&pAllData'!C45 -> 879.82 | I5: ='s&pAllData'!I45 -> 13.905258 | J5: =I5/H5 -> 0.015804662 | L5: =G5 -> 2002 | M5: =I5+E5 -> 29.83 | N5: =M5/H5 -> 0.033904662
B6: =B5+1 -> 2003 | C6: ='s&pAllData'!C46 -> 1111.91 | D6: ='s&pAllData'!F46 -> 0.0161 | E6: =D6*C6 -> 17.901751 | G6: =G5+1 -> 2003 | H6: ='s&pAllData'!C46 -> 1111.91 | I6: ='s&pAllData'!I46 -> 13.678249 | J6: =I6/H6 -> 0.012301579 | L6: =G6 -> 2003 | M6: =I6+E6 -> 31.58 | N6: =M6/H6 -> 0.028401579 | P6: Average S&P500 Earnings Yield- | Q6: 15 YRS | R6: =AVERAGE(N13:N27) -> 0.044749679
B7: =B6+1 -> 2004 | C7: ='s&pAllData'!C47 -> 1211.92 | D7: ='s&pAllData'!F47 -> 0.0157 | E7: =D7*C7 -> 19.027144 | G7: =G6+1 -> 2004 | H7: ='s&pAllData'!C47 -> 1211.92 | I7: ='s&pAllData'!I47 -> 21.572856 | J7: =I7/H7 -> 0.017800561 | L7: =G7 -> 2004 | M7: =I7+E7 -> 40.6 | N7: =M7/H7 -> 0.033500561
B8: =B7+1 -> 2005 | C8: ='s&pAllData'!C48 -> 1248.29 | D8: ='s&pAllData'!F48 -> 0.0179 | E8: =D8*C8 -> 22.344391 | G8: =G7+1 -> 2005 | H8: ='s&pAllData'!C48 -> 1248.29 | I8: ='s&pAllData'!I48 -> 38.825609 | J8: =I8/H8 -> 0.031103036 | L8: =G8 -> 2005 | M8: =I8+E8 -> 61.17 | N8: =M8/H8 -> 0.049003036 | P8: Average S&P500 Earnings Yield- | Q8: 10YRS | R8: =AVERAGE(N18:N27) -> 0.041998155
B9: =B8+1 -> 2006 | C9: ='s&pAllData'!C49 -> 1418.3 | D9: ='s&pAllData'!F49 -> 0.0177 | E9: =D9*C9 -> 25.10391 | G9: =G8+1 -> 2006 | H9: ='s&pAllData'!C49 -> 1418.3 | I9: ='s&pAllData'!I49 -> 48.05609 | J9: =I9/H9 -> 0.033882881 | L9: =G9 -> 2006 | M9: =I9+E9 -> 73.16 | N9: =M9/H9 -> 0.051582881
B10: =B9+1 -> 2007 | C10: ='s&pAllData'!C50 -> 1468.36 | D10: ='s&pAllData'!F50 -> 0.0192 | E10: =D10*C10 -> 28.192512 | G10: =G9+1 -> 2007 | H10: ='s&pAllData'!C50 -> 1468.36 | I10: ='s&pAllData'!I50 -> 67.167488 | J10: =I10/H10 -> 0.045743202 | L10: =G10 -> 2007 | M10: =I10+E10 -> 95.36 | N10: =M10/H10 -> 0.064943202 | P10: Average S&P500 Earnings Yield- | Q10: 7 YRS | R10: =AVERAGE(N21:N27) -> 0.039861958
B11: =B10+1 -> 2008 | C11: ='s&pAllData'!C51 -> 903.25 | D11: ='s&pAllData'!F51 -> 0.0315 | E11: =D11*C11 -> 28.452375 | G11: =G10+1 -> 2008 | H11: ='s&pAllData'!C51 -> 903.25 | I11: ='s&pAllData'!I51 -> 39.067625 | J11: =I11/H11 -> 0.043252283 | L11: =G11 -> 2008 | M11: =I11+E11 -> 67.52 | N11: =M11/H11 -> 0.074752283
B12: =B11+1 -> 2009 | C12: ='s&pAllData'!C52 -> 1115.1 | D12: ='s&pAllData'!F52 -> 0.0197 | E12: =D12*C12 -> 21.96747 | G12: =G11+1 -> 2009 | H12: ='s&pAllData'!C52 -> 1115.1 | I12: ='s&pAllData'!I52 -> 15.46253 | J12: =I12/H12 -> 0.013866496 | L12: =G12 -> 2009 | M12: =I12+E12 -> 37.43 | N12: =M12/H12 -> 0.033566496 | P12: Average S&P500 Earnings Yield- | Q12: 5 YRS | R12: =AVERAGE(N23:N27) -> 0.035587977
B13: =B12+1 -> 2010 | C13: ='s&pAllData'!C53 -> 1257.64 | D13: ='s&pAllData'!F53 -> 0.018 | E13: =D13*C13 -> 22.63752 | G13: =G12+1 -> 2010 | H13: ='s&pAllData'!C53 -> 1257.64 | I13: ='s&pAllData'!I53 -> 32.89248 | J13: =I13/H13 -> 0.02615413 | L13: =G13 -> 2010 | M13: =I13+E13 -> 55.53 | N13: =M13/H13 -> 0.04415413
B14: =B13+1 -> 2011 | C14: ='s&pAllData'!C54 -> 1257.6 | D14: ='s&pAllData'!F54 -> 0.0211 | E14: =D14*C14 -> 26.53536 | G14: =G13+1 -> 2011 | H14: ='s&pAllData'!C54 -> 1257.6 | I14: ='s&pAllData'!I54 -> 44.74464 | J14: =I14/H14 -> 0.035579389 | L14: =G14 -> 2011 | M14: =I14+E14 -> 71.28 | N14: =M14/H14 -> 0.056679389 | P14: Average S&P500 Earnings Yield- | Q14: Latest | R14: =N27 -> 0.03107982
B15: =B14+1 -> 2012 | C15: ='s&pAllData'!C55 -> 1426.19 | D15: ='s&pAllData'!F55 -> 0.0219 | E15: =D15*C15 -> 31.233561 | G15: =G14+1 -> 2012 | H15: ='s&pAllData'!C55 -> 1426.19 | I15: ='s&pAllData'!I55 -> 44.666439 | J15: =I15/H15 -> 0.031318716 | L15: =G15 -> 2012 | M15: =I15+E15 -> 75.9 | N15: =M15/H15 -> 0.053218716
B16: =B15+1 -> 2013 | C16: ='s&pAllData'!C56 -> 1848.36 | D16: ='s&pAllData'!F56 -> 0.0189 | E16: =D16*C16 -> 34.934004 | G16: =G15+1 -> 2013 | H16: ='s&pAllData'!C56 -> 1848.36 | I16: ='s&pAllData'!I56 -> 53.195996 | J16: =I16/H16 -> 0.028780106 | L16: =G16 -> 2013 | M16: =I16+E16 -> 88.13 | N16: =M16/H16 -> 0.047680106
B17: =B16+1 -> 2014 | C17: ='s&pAllData'!C57 -> 2058.9 | D17: ='s&pAllData'!F57 -> 0.0192 | E17: =D17*C17 -> 39.53088 | G17: =G16+1 -> 2014 | H17: ='s&pAllData'!C57 -> 2058.9 | I17: ='s&pAllData'!I57 -> 62.44912 | J17: =I17/H17 -> 0.030331303 | L17: =G17 -> 2014 | M17: =I17+E17 -> 101.98 | N17: =M17/H17 -> 0.049531303
B18: =B17+1 -> 2015 | C18: ='s&pAllData'!C58 -> 2043.94 | D18: ='s&pAllData'!F58 -> 0.0212 | E18: =D18*C18 -> 43.331528 | G18: =G17+1 -> 2015 | H18: ='s&pAllData'!C58 -> 2043.94 | I18: ='s&pAllData'!I58 -> 62.768472 | J18: =I18/H18 -> 0.030709547 | L18: =G18 -> 2015 | M18: =I18+E18 -> 106.1 | N18: =M18/H18 -> 0.051909547
B19: =B18+1 -> 2016 | C19: ='s&pAllData'!C59 -> 2238.83 | D19: ='s&pAllData'!F59 -> 0.0204 | E19: =D19*C19 -> 45.672132 | G19: =G18+1 -> 2016 | H19: ='s&pAllData'!C59 -> 2238.83 | I19: ='s&pAllData'!I59 -> 62.997868 | J19: =I19/H19 -> 0.028138746 | L19: =G19 -> 2016 | M19: =I19+E19 -> 108.67 | N19: =M19/H19 -> 0.048538746
B20: =B19+1 -> 2017 | C20: ='s&pAllData'!C60 -> 2673.61 | D20: ='s&pAllData'!F60 -> 0.0183 | E20: =D20*C20 -> 48.927063 | G20: =G19+1 -> 2017 | H20: ='s&pAllData'!C60 -> 2673.61 | I20: ='s&pAllData'!I60 -> 59.352937 | J20: =I20/H20 -> 0.022199549 | L20: =G20 -> 2017 | M20: =I20+E20 -> 108.28 | N20: =M20/H20 -> 0.040499549
B21: =B20+1 -> 2018 | C21: ='s&pAllData'!C61 -> 2506.85 | D21: ='s&pAllData'!F61 -> 0.0214 | E21: =D21*C21 -> 53.64659 | G21: =G20+1 -> 2018 | H21: ='s&pAllData'!C61 -> 2506.85 | I21: ='s&pAllData'!I61 -> 83.00341 | J21: =I21/H21 -> 0.033110641 | L21: =G21 -> 2018 | M21: =I21+E21 -> 136.65 | N21: =M21/H21 -> 0.054510641
B22: =B21+1 -> 2019 | C22: ='s&pAllData'!C62 -> 3230.78 | D22: ='s&pAllData'!F62 -> 0.0182 | E22: =D22*C22 -> 58.800196 | G22: =G21+1 -> 2019 | H22: ='s&pAllData'!C62 -> 3230.78 | I22: ='s&pAllData'!I62 -> 91.699804 | J22: =I22/H22 -> 0.028383178 | L22: =G22 -> 2019 | M22: =I22+E22 -> 150.5 | N22: =M22/H22 -> 0.046583178
B23: =B22+1 -> 2020 | C23: ='s&pAllData'!C63 -> 3756.07 | D23: ='s&pAllData'!F63 -> 0.0151 | E23: =D23*C23 -> 56.716657 | G23: =G22+1 -> 2020 | H23: ='s&pAllData'!C63 -> 3756.07 | I23: ='s&pAllData'!I63 -> 71.063343 | J23: =I23/H23 -> 0.0189196 | L23: =G23 -> 2020 | M23: =I23+E23 -> 127.78 | N23: =M23/H23 -> 0.0340196
B24: =B23+1 -> 2021 | C24: ='s&pAllData'!C64 -> 4766.18 | D24: ='s&pAllData'!F64 -> 0.0124 | E24: =D24*C24 -> 59.100632 | G24: =G23+1 -> 2021 | H24: ='s&pAllData'!C64 -> 4766.18 | I24: ='s&pAllData'!I64 -> 88.139368 | J24: =I24/H24 -> 0.018492665 | L24: =G24 -> 2021 | M24: =I24+E24 -> 147.24 | N24: =M24/H24 -> 0.030892665
B25: =B24+1 -> 2022 | C25: ='s&pAllData'!C65 -> 3839.5 | D25: ='s&pAllData'!F65 -> 0.0178 | E25: =D25*C25 -> 68.3431 | G25: =G24+1 -> 2022 | H25: ='s&pAllData'!C65 -> 3839.5 | I25: ='s&pAllData'!I65 -> 113.6469 | J25: =I25/H25 -> 0.029599401 | L25: =G25 -> 2022 | M25: =I25+E25 -> 181.99 | N25: =M25/H25 -> 0.047399401
B26: =B25+1 -> 2023 | C26: ='s&pAllData'!C66 -> 4769.83 | D26: ='s&pAllData'!F66 -> 0.0147 | E26: =D26*C26 -> 70.116501 | G26: =G25+1 -> 2023 | H26: ='s&pAllData'!C66 -> 4769.83 | I26: ='s&pAllData'!I66 -> 94.673499 | J26: =I26/H26 -> 0.019848401 | L26: =G26 -> 2023 | M26: =I26+E26 -> 164.79 | N26: =M26/H26 -> 0.034548401
B27: =B26+1 -> 2024 | C27: ='s&pAllData'!C67 -> 5881.63 | D27: ='s&pAllData'!F67 -> 0.0125 | E27: =D27*C27 -> 73.520375 | G27: =G26+1 -> 2024 | H27: ='s&pAllData'!C67 -> 5881.63 | I27: ='s&pAllData'!I67 -> 109.27963 | J27: =I27/H27 -> 0.01857982 | L27: =G27 -> 2024 | M27: =I27+E27 -> 182.8 | N27: =M27/H27 -> 0.03107982

Sheet EPSGrowth
B2: S&P 500 EPS Growth
B3: Year | C3: S&P 500 | D3: EPS | E3: EPS 3 YR CAGR | F3: EPS 5 YR CAGR | G3: EPS 7 YR CAGR | H3: EPS 10 YR CAGR
B4: 1960 | C4: ='s&pAllData'!C3 -> 58.11 | D4: ='s&pAllData'!E3 -> 3.103074 | E4: - | F4: - | G4: - | H4: - | J4: Average EPS CAGR- | K4: 3YRS | L4: =AVERAGE(E7:E67) -> 0.073866373
B5: =B4+1 -> 1961 | C5: ='s&pAllData'!C4 -> 71.55 | D5: ='s&pAllData'!E4 -> 3.370005 | E5: - | F5: - | G5: - | H5: -
B6: =B5+1 -> 1962 | C6: ='s&pAllData'!C5 -> 63.1 | D6: ='s&pAllData'!E5 -> 3.66611 | E6: - | F6: - | G6: - | H6: - | J6: Average EPS CAGR- | K6: 5YRS | L6: =AVERAGE(F9:F67) -> 0.069508701
B7: =B6+1 -> 1963 | C7: ='s&pAllData'!C6 -> 75.02 | D7: ='s&pAllData'!E6 -> 4.133602 | E7: =_xlfn.RRI(3,D4,D7) -> 0.10030269 | F7: - | G7: - | H7: -
B8: =B7+1 -> 1964 | C8: ='s&pAllData'!C7 -> 84.75 | D8: ='s&pAllData'!E7 -> 4.76295 | E8: =_xlfn.RRI(3,D5,D8) -> 0.12222987 | F8: - | G8: - | H8: - | J8: Average EPS CAGR- | K8: 7YRS | L8: =AVERAGE(G11:G67) -> 0.067742412
B9: =B8+1 -> 1965 | C9: ='s&pAllData'!C8 -> 92.43 | D9: ='s&pAllData'!E8 -> 5.296239 | E9: =_xlfn.RRI(3,D6,D9) -> 0.13045695 | F9: =_xlfn.RRI(5,D4,D9) -> 0.11284605 | G9: - | H9: -
B10: =B9+1 -> 1966 | C10: ='s&pAllData'!C9 -> 80.33 | D10: ='s&pAllData'!E9 -> 5.414242 | E10: =_xlfn.RRI(3,D7,D10) -> 0.09413187 | F10: =_xlfn.RRI(5,D5,D10) -> 0.099465038 | G10: - | H10: - | J10: Average EPS CAGR- | K10: 10YRS | L10: =AVERAGE(H14:H67) -> 0.066775799
B11: =B10+1 -> 1967 | C11: ='s&pAllData'!C10 -> 96.47 | D11: ='s&pAllData'!E10 -> 5.460202 | E11: =_xlfn.RRI(3,D8,D11) -> 0.046592366 | F11: =_xlfn.RRI(5,D6,D11) -> 0.082930645 | G11: =_xlfn.RRI(7,D4,D11) -> 0.084075454 | H11: -
B12: =B11+1 -> 1968 | C12: ='s&pAllData'!C11 -> 103.86 | D12: ='s&pAllData'!E11 -> 5.722686 | E12: =_xlfn.RRI(3,D9,D12) -> 0.026149837 | F12: =_xlfn.RRI(5,D7,D12) -> 0.067220728 | G12: =_xlfn.RRI(7,D5,D12) -> 0.078581004 | H12: -
B13: =B12+1 -> 1969 | C13: ='s&pAllData'!C12 -> 92.06 | D13: ='s&pAllData'!E12 -> 6.103578 | E13: =_xlfn.RRI(3,D10,D13) -> 0.040756052 | F13: =_xlfn.RRI(5,D8,D13) -> 0.050852339 | G13: =_xlfn.RRI(7,D6,D13) -> 0.075537538 | H13: -
B14: =B13+1 -> 1970 | C14: ='s&pAllData'!C13 -> 92.15 | D14: ='s&pAllData'!E13 -> 5.51057 | E14: =_xlfn.RRI(3,D11,D14) -> 0.0030654491 | F14: =_xlfn.RRI(5,D9,D14) -> 0.0079657834 | G14: =_xlfn.RRI(7,D7,D14) -> 0.041929337 | H14: =_xlfn.RRI(10,D4,D14) -> 0.059108465
B15: =B14+1 -> 1971 | C15: ='s&pAllData'!C14 -> 102.09 | D15: ='s&pAllData'!E14 -> 5.574114 | E15: =_xlfn.RRI(3,D12,D15) -> -0.0087299688 | F15: =_xlfn.RRI(5,D10,D15) -> 0.005837068 | G15: =_xlfn.RRI(7,D8,D15) -> 0.022720868 | H15: =_xlfn.RRI(10,D5,D15) -> 0.051609571
B16: =B15+1 -> 1972 | C16: ='s&pAllData'!C15 -> 118.05 | D16: ='s&pAllData'!E15 -> 6.174015 | E16: =_xlfn.RRI(3,D13,D16) -> 0.0038320566 | F16: =_xlfn.RRI(5,D11,D16) -> 0.024877111 | G16: =_xlfn.RRI(7,D9,D16) -> 0.022149218 | H16: =_xlfn.RRI(10,D6,D16) -> 0.053504073
B17: =B16+1 -> 1973 | C17: ='s&pAllData'!C16 -> 97.55 | D17: ='s&pAllData'!E16 -> 7.96008 | E17: =_xlfn.RRI(3,D14,D17) -> 0.13042122 | F17: =_xlfn.RRI(5,D12,D17) -> 0.068226883 | G17: =_xlfn.RRI(7,D10,D17) -> 0.05660192 | H17: =_xlfn.RRI(10,D7,D17) -> 0.067723687
B18: =B17+1 -> 1974 | C18: ='s&pAllData'!C17 -> 68.56 | D18: ='s&pAllData'!E17 -> 9.351584 | E18: =_xlfn.RRI(3,D15,D18) -> 0.18823711 | F18: =_xlfn.RRI(5,D13,D18) -> 0.089080886 | G18: =_xlfn.RRI(7,D11,D18) -> 0.079897045 | H18: =_xlfn.RRI(10,D8,D18) -> 0.069795867
B19: =B18+1 -> 1975 | C19: ='s&pAllData'!C18 -> 90.19 | D19: ='s&pAllData'!E18 -> 7.711245 | E19: =_xlfn.RRI(3,D16,D19) -> 0.076925368 | F19: =_xlfn.RRI(5,D14,D19) -> 0.069511837 | G19: =_xlfn.RRI(7,D12,D19) -> 0.043526572 | H19: =_xlfn.RRI(10,D9,D19) -> 0.038282879
B20: =B19+1 -> 1976 | C20: ='s&pAllData'!C19 -> 107.46 | D20: ='s&pAllData'!E19 -> 9.746622 | E20: =_xlfn.RRI(3,D17,D20) -> 0.069823738 | F20: =_xlfn.RRI(5,D15,D20) -> 0.11824163 | G20: =_xlfn.RRI(7,D13,D20) -> 0.069149698 | H20: =_xlfn.RRI(10,D10,D20) -> 0.060551215
B21: =B20+1 -> 1977 | C21: ='s&pAllData'!C20 -> 95.1 | D21: ='s&pAllData'!E20 -> 10.86993 | E21: =_xlfn.RRI(3,D18,D21) -> 0.051430383 | F21: =_xlfn.RRI(5,D16,D21) -> 0.1197777 | G21: =_xlfn.RRI(7,D14,D21) -> 0.10191267 | H21: =_xlfn.RRI(10,D11,D21) -> 0.071277057
B22: =B21+1 -> 1978 | C22: ='s&pAllData'!C21 -> 96.11 | D22: ='s&pAllData'!E21 -> 11.638921 | E22: =_xlfn.RRI(3,D19,D22) -> 0.14708625 | F22: =_xlfn.RRI(5,D17,D22) -> 0.078944381 | G22: =_xlfn.RRI(7,D15,D22) -> 0.11090442 | H22: =_xlfn.RRI(10,D12,D22) -> 0.073572258
B23: =B22+1 -> 1979 | C23: ='s&pAllData'!C22 -> 107.94 | D23: ='s&pAllData'!E22 -> 14.550312 | E23: =_xlfn.RRI(3,D20,D23) -> 0.14289428 | F23: =_xlfn.RRI(5,D18,D23) -> 0.092439577 | G23: =_xlfn.RRI(7,D16,D23) -> 0.13028086 | H23: =_xlfn.RRI(10,D13,D23) -> 0.090758939
B24: =B23+1 -> 1980 | C24: ='s&pAllData'!C23 -> 135.76 | D24: ='s&pAllData'!E23 -> 14.987904 | E24: =_xlfn.RRI(3,D21,D24) -> 0.11302449 | F24: =_xlfn.RRI(5,D19,D24) -> 0.14215036 | G24: =_xlfn.RRI(7,D17,D24) -> 0.094612733 | H24: =_xlfn.RRI(10,D14,D24) -> 0.10523451
B25: =B24+1 -> 1981 | C25: ='s&pAllData'!C24 -> 122.55 | D25: ='s&pAllData'!E24 -> 15.183945 | E25: =_xlfn.RRI(3,D22,D25) -> 0.092674062 | F25: =_xlfn.RRI(5,D20,D25) -> 0.092712974 | G25: =_xlfn.RRI(7,D18,D25) -> 0.071695356 | H25: =_xlfn.RRI(10,D15,D25) -> 0.10540361
... B68: =B67+1 -> 2024 | C68: ='s&pAllData'!C67 -> 5881.63 | D68: ='s&pAllData'!E67 -> 243.49948 | E68: =_xlfn.RRI(3,D65,D68) -> 0.056687496 | F68: =_xlfn.RRI(5,D63,D68) -> 0.084237775 | G68: =_xlfn.RRI(7,D61,D68) -> 0.10045791 | H68: =_xlfn.RRI(10,D58,D68) -> 0.076857825

Sheet RFRData
B2: Monthly Historical US RFR
B3: Date | C3: Price | D3: Open | E3: High | F3: Low | G3: Change % | I3: Year | J3: Yearly Average
B4: 45659 | C4: 0.04202 | D4: 0.04563 | E4: 0.0466 | F4: 0.04193 | G4: -0.0749 | I4: 1996 | J4: =AVERAGEIFS($C$4:$C$353,$B$4:$B$353,">="&DATE(I4,1,1),$B$4:$B$353,"<="&DATE(I4,12,31)) -> 0.0646 | P4: Damodaran Lookup Table- Rating Based Default Spread
B5: 45658 | C5: 0.04542 | D5: 0.04571 | E5: 0.04809 | F5: 0.04486 | G5: -0.0066 | I5: =I4+1 -> 1997 | J5: =AVERAGEIFS($C$4:$C$353,$B$4:$B$353,">="&DATE(I5,1,1),$B$4:$B$353,"<="&DATE(I5,12,31)) -> 0.06313 | L5: US Rating Based Default Spread- | N5: =R6 -> 0 | P5: S&P | Q5: Moody's | R5: Default Spread
B6: 45303 | C6: 0.04572 | D6: 0.04207 | E6: 0.04641 | F6: 0.04126 | G6: 0.0945 | I6: =I5+1 -> 1998 | J6: =AVERAGEIFS($C$4:$C$353,$B$4:$B$353,">="&DATE(I6,1,1),$B$4:$B$353,"<="&DATE(I6,12,31)) -> 0.052140833 | P6: AAA | Q6: Aaa | R6: 0
B7: 45302 | C7: 0.04177 | D7: 0.04292 | E7: 0.04505 | F7: 0.04172 | G7: -0.0243 | I7: =I6+1 -> 1999 | J7: =AVERAGEIFS($C$4:$C$353,$B$4:$B$353,">="&DATE(I7,1,1),$B$4:$B$353,"<="&DATE(I7,12,31)) -> 0.0569675 | P7: AA+ | Q7: Aa1 | R7: 39.577444
B8: 45301 | C8: 0.04281 | D8: 0.03779 | E8: 0.04339 | F8: 0.03696 | G8: 0.1309 | I8: =I7+1 -> 2000 | J8: =AVERAGEIFS($C$4:$C$353,$B$4:$B$353,">="&DATE(I8,1,1),$B$4:$B$353,"<="&DATE(I8,12,31)) -> 0.059609167 | L8: Average Govt. Bond Rate- | M8: 20 YRS Bond Rate | N8: =AVERAGE(J14:J33) -> 0.028723333 | P8: AA | Q8: Aa2 | R8: 48.889784
B9: 45300 | C9: 0.03786 | D9: 0.03928 | E9: 0.03932 | F9: 0.03599 | G9: -0.0316 | I9: =I8+1 -> 2001 | J9: =AVERAGEIFS($C$4:$C$353,$B$4:$B$353,">="&DATE(I9,1,1),$B$4:$B$353,"<="&DATE(I9,12,31)) -> 0.04964 | P9: AA- | Q9: Aa3 | R9: 59.366167
B10: 45299 | C10: 0.03909 | D10: 0.04056 | E10: 0.04066 | F10: 0.03667 | G10: -0.0308 | I10: =I9+1 -> 2002 | J10: =AVERAGEIFS($C$4:$C$353,$B$4:$B$353,">="&DATE(I10,1,1),$B$4:$B$353,"<="&DATE(I10,12,31)) -> 0.045318333 | L10: Average Govt. Bond Rate- | M10: 15 YRS Bond Rate | N10: =AVERAGE(J19:J33) -> 0.025404167 | P10: A+ | Q10: A1 | R10: 69.842549
B11: 45298 | C11: 0.04033 | D11: 0.04412 | E11: 0.04493 | F11: 0.04031 | G11: -0.0817 | I11: =I10+1 -> 2003 | J11: =AVERAGEIFS($C$4:$C$353,$B$4:$B$353,">="&DATE(I11,1,1),$B$4:$B$353,"<="&DATE(I11,12,31)) -> 0.039910833 | P11: A | Q11: A2 | R11: 83.811059
B12: 45297 | C12: 0.04392 | D12: 0.04493 | E12: 0.04501 | F12: 0.04188 | G12: -0.0245 | I12: =I11+1 -> 2004 | J12: =AVERAGEIFS($C$4:$C$353,$B$4:$B$353,">="&DATE(I12,1,1),$B$4:$B$353,"<="&DATE(I12,12,31)) -> 0.042634167 | L12: Average Govt. Bond Rate- | M12: 10YRS Bond Rate | N12: =AVERAGE(J24:J33) -> 0.0267055 | P12: A- | Q12: A3 | R12: 118.73233
B13: 45296 | C13: 0.04503 | D13: 0.04682 | E13: 0.04694 | F13: 0.04313 | G13: -0.0383 | I13: =I12+1 -> 2005 | J13: =AVERAGEIFS($C$4:$C$353,$B$4:$B$353,">="&DATE(I13,1,1),$B$4:$B$353,"<="&DATE(I13,12,31)) -> 0.042649167 | P13: BBB+ | Q13: Baa1 | R13: 158.30978
B14: 45295 | C14: 0.04682 | D14: 0.0419 | E14: 0.04739 | F14: 0.04188 | G14: 0.1131 | I14: =I13+1 -> 2006 | J14: =AVERAGEIFS($C$4:$C$353,$B$4:$B$353,">="&DATE(I14,1,1),$B$4:$B$353,"<="&DATE(I14,12,31)) -> 0.047810833 | L14: Average Govt. Bond Rate- | M14: 7 YRS Bond Rate | N14: =AVERAGE(J27:J33) -> 0.028080119 | P14: BBB | Q14: Baa2 | R14: 188.57488
B15: 45294 | C15: 0.04206 | D15: 0.04254 | E15: 0.04348 | F15: 0.04038 | G15: -0.0113 | I15: =I14+1 -> 2007 | J15: =AVERAGEIFS($C$4:$C$353,$B$4:$B$353,">="&DATE(I15,1,1),$B$4:$B$353,"<="&DATE(I15,12,31)) -> 0.0457475 | P15: BBB- | Q15: Baa3 | R15: 217.67594
B16: 45293 | C16: 0.04254 | D16: 0.03931 | E16: 0.04354 | F16: 0.03816 | G16: 0.0858 | I16: =I15+1 -> 2008 | J16: =AVERAGEIFS($C$4:$C$353,$B$4:$B$353,">="&DATE(I16,1,1),$B$4:$B$353,"<="&DATE(I16,12,31)) -> 0.0358625 | L16: Average Govt. Bond Rate- | M16: 5 YRS Bond Rate | N16: =AVERAGE(J29:J33) -> 0.033511167 | P16: BB+ | Q16: Ba1 | R16: 247.94105
B17: 45292 | C17: 0.03918 | D17: 0.03899 | E17: 0.04198 | F17: 0.03881 | G17: 0.0135 | I17: =I16+1 -> 2009 | J17: =AVERAGEIFS($C$4:$C$353,$B$4:$B$353,">="&DATE(I17,1,1),$B$4:$B$353,"<="&DATE(I17,12,31)) -> 0.032723333 | P17: BB | Q17: Ba2 | R17: 297.99488
B18: 44938 | C18: 0.03866 | D18: 0.04321 | E18: 0.04349 | F18: 0.03783 | G18: -0.1072 | I18: =I17+1 -> 2010 | J18: =AVERAGEIFS($C$4:$C$353,$B$4:$B$353,">="&DATE(I18,1,1),$B$4:$B$353,"<="&DATE(I18,12,31)) -> 0.03126 | L18: Average Govt. Bond Rate- | M18: Latest Bond Rate | N18: =J33 -> 0.0411 | P18: BB- | Q18: Ba3 | R18: 356.197
B19: 44937 | C19: 0.0433 | D19: 0.04926 | E19: 0.04935 | F19: 0.04247 | G19: -0.121 | I19: =I18+1 -> 2011 | J19: =AVERAGEIFS($C$4:$C$353,$B$4:$B$353,">="&DATE(I19,1,1),$B$4:$B$353,"<="&DATE(I19,12,31)) -> 0.027319167 | P19: B+ | Q19: B1 | R19: 445.82827
B20: 44936 | C20: 0.04926 | D20: 0.04614 | E20: 0.05021 | F20: 0.0453 | G20: 0.0758 | I20: =I19+1 -> 2012 | J20: =AVERAGEIFS($C$4:$C$353,$B$4:$B$353,">="&DATE(I20,1,1),$B$4:$B$353,"<="&DATE(I20,12,31)) -> 0.017355 | L20: Risk-Free Rate- | M20: Latest | N20: =N18-N5 -> 0.0411 | P20: B | Q20: B2 | R20: 544.77188
B21: 44935 | C21: 0.04579 | D21: 0.04114 | E21: 0.04688 | F21: 0.0406 | G21: 0.1152 | I21: =I20+1 -> 2013 | J21: =AVERAGEIFS($C$4:$C$353,$B$4:$B$353,">="&DATE(I21,1,1),$B$4:$B$353,"<="&DATE(I21,12,31)) -> 0.023605 | P21: B- | Q21: B3 | R21: 643.71549
B22: 44934 | C22: 0.04106 | D22: 0.03965 | E22: 0.04366 | F22: 0.03949 | G22: 0.0351 | I22: =I21+1 -> 2014 | J22: =AVERAGEIFS($C$4:$C$353,$B$4:$B$353,">="&DATE(I22,1,1),$B$4:$B$353,"<="&DATE(I22,12,31)) -> 0.0247875 | P22: CCC+ | Q22: Caa1 | R22: 742.6591
B23: 44933 | C23: 0.03967 | D23: 0.03845 | E23: 0.04094 | F23: 0.03727 | G23: 0.0329 | I23: =I22+1 -> 2015 | J23: =AVERAGEIFS($C$4:$C$353,$B$4:$B$353,">="&DATE(I23,1,1),$B$4:$B$353,"<="&DATE(I23,12,31)) -> 0.020940833 | L23: Source: investing.com | P23: CCC | Q23: Caa2 | R23: 891.65654
B24: 44932 | C24: 0.03841 | D24: 0.03639 | E24: 0.03892 | F24: 0.0357 | G24: 0.0533 | I24: =I23+1 -> 2016 | J24: =AVERAGEIFS($C$4:$C$353,$B$4:$B$353,">="&DATE(I24,1,1),$B$4:$B$353,"<="&DATE(I24,12,31)) -> 0.018233333 | P24: CCC- | Q24: Caa3 | R24: 990.60015
B25: 44931 | C25: 0.03646 | D25: 0.0345 | E25: 0.03859 | F25: 0.03296 | G25: 0.0621 | I25: =I24+1 -> 2017 | J25: =AVERAGEIFS($C$4:$C$353,$B$4:$B$353,">="&DATE(I25,1,1),$B$4:$B$353,"<="&DATE(I25,12,31)) -> 0.0233375 | P25: CC | Q25: Ca | R25: 1188.4874
B26: 44930 | C26: 0.03433 | D26: 0.03524 | E26: 0.03639 | F26: 0.03253 | G26: -0.0115 | I26: =I25+1 -> 2018 | J26: =AVERAGEIFS($C$4:$C$353,$B$4:$B$353,">="&DATE(I26,1,1),$B$4:$B$353,"<="&DATE(I26,12,31)) -> 0.028923333 | P26: C | Q26: Ca | R26: 1188.4874
B27: 44929 | C27: 0.03473 | D27: 0.03938 | E27: 0.04091 | F27: 0.03285 | G27: -0.1157 | I27: =I26+1 -> 2019 | J27: =AVERAGEIFS($C$4:$C$353,$B$4:$B$353,">="&DATE(I27,1,1),$B$4:$B$353,"<="&DATE(I27,12,31)) -> 0.020796667 | P27: D | Q27: C | R27: 1750
B28: 44928 | C28: 0.03928 | D28: 0.03516 | E28: 0.03983 | F28: 0.03333 | G28: 0.1189 | I28: =I27+1 -> 2020 | J28: =AVERAGEIFS($C$4:$C$353,$B$4:$B$353,">="&DATE(I28,1,1),$B$4:$B$353,"<="&DATE(I28,12,31)) -> 0.0082083333 | P28: NR | Q28: NR | R28: NA
B29: 44927 | C29: 0.0351 | D29: 0.03848 | E29: 0.03848 | F29: 0.03321 | G29: -0.0949 | I29: =I28+1 -> 2021 | J29: =AVERAGEIFS($C$4:$C$353,$B$4:$B$353,">="&DATE(I29,1,1),$B$4:$B$353,"<="&DATE(I29,12,31)) -> 0.0145425
B30: 44573 | C30: 0.03879 | D30: 0.0362 | E30: 0.03905 | F30: 0.03402 | G30: 0.0741 | I30: =I29+1 -> 2022 | J30: =AVERAGEIFS($C$4:$C$353,$B$4:$B$353,">="&DATE(I30,1,1),$B$4:$B$353,"<="&DATE(I30,12,31)) -> 0.029981667 | P30: Source: NYU Stern website, by Prof. Aswath Damodarn
B31: 44572 | C31: 0.03611 | D31: 0.04058 | E31: 0.04243 | F31: 0.036 | G31: -0.1084 | I31: =I30+1 -> 2023 | J31: =AVERAGEIFS($C$4:$C$353,$B$4:$B$353,">="&DATE(I31,1,1),$B$4:$B$353,"<="&DATE(I31,12,31)) -> 0.039670833
B32: 44571 | C32: 0.0405 | D32: 0.03813 | E32: 0.04338 | F32: 0.03562 | G32: 0.0578 | I32: =I31+1 -> 2024 | J32: =AVERAGEIFS($C$4:$C$353,$B$4:$B$353,">="&DATE(I32,1,1),$B$4:$B$353,"<="&DATE(I32,12,31)) -> 0.042260833
B33: 44570 | C33: 0.03829 | D33: 0.03198 | E33: 0.04019 | F33: 0.03174 | G33: 0.1978 | I33: =I32+1 -> 2025 | J33: 0.0411
B34: 44569 | C34: 0.03196 | D34: 0.02669 | E34: 0.03198 | F34: 0.02516 | G34: 0.2027
B35: 44568 | C35: 0.02658 | D35: 0.03024 | E35: 0.03103 | F35: 0.02618 | G35: -0.119
B36: 44567 | C36: 0.03017 | D36: 0.02864 | E36: 0.03498 | F36: 0.02833 | G36: 0.0586
B37: 44566 | C37: 0.02849 | D37: 0.02932 | E37: 0.03203 | F37: 0.02706 | G37: -0.03
B38: 44565 | C38: 0.02938 | D38: 0.02352 | E38: 0.02981 | F38: 0.02352 | G38: 0.2526
B39: 44564 | C39: 0.02345 | D39: 0.0184 | E39: 0.02557 | F39: 0.01668 | G39: 0.2874
B40: 44563 | C40: 0.01822 | D40: 0.01787 | E40: 0.02065 | F40: 0.01739 | G40: 0.0212
B41: 44562 | C41: 0.01784 | D41: 0.01531 | E41: 0.01902 | F41: 0.01529 | G41: 0.1799
...

Sheet ERPData
B2: Historical Implied ERP of US
B3: Year | C3: Implied ERP | E3: Year | F3: Yearly Average ERP
B4: 39721 | C4: 0.0422 | E4: 2008 | F4: =AVERAGEIFS($C$4:$C$201,$B$4:$B$201,">="&DATE(E4,1,1),$B$4:$B$201,"<="&DATE(E4,12,31)) -> 0.053075 | H4: Average Implied ERP- | I4: 15 YRS | J4: =AVERAGE(F6:F20) -> 0.055121667
B5: =EOMONTH(B4,1) -> 39752 | C5: 0.0451 | E5: =E4+1 -> 2009 | F5: =AVERAGEIFS($C$4:$C$201,$B$4:$B$201,">="&DATE(E5,1,1),$B$4:$B$201,"<="&DATE(E5,12,31)) -> 0.059525
B6: =EOMONTH(B5,1) -> 39782 | C6: 0.059 | E6: =E5+1 -> 2010 | F6: =AVERAGEIFS($C$4:$C$201,$B$4:$B$201,">="&DATE(E6,1,1),$B$4:$B$201,"<="&DATE(E6,12,31)) -> 0.047775 | H6: Average Implied ERP- | I6: 10YRS | J6: =AVERAGE(F11:F20) -> 0.054605
B7: =EOMONTH(B6,1) -> 39813 | C7: 0.066 | E7: =E6+1 -> 2011 | F7: =AVERAGEIFS($C$4:$C$201,$B$4:$B$201,">="&DATE(E7,1,1),$B$4:$B$201,"<="&DATE(E7,12,31)) -> 0.057983333
B8: =EOMONTH(B7,1) -> 39844 | C8: 0.0643 | E8: =E7+1 -> 2012 | F8: =AVERAGEIFS($C$4:$C$201,$B$4:$B$201,">="&DATE(E8,1,1),$B$4:$B$201,"<="&DATE(E8,12,31)) -> 0.067133333 | H8: Average Implied ERP- | I8: 7 YRS | J8: =AVERAGE(F14:F20) -> 0.053184524
B9: =EOMONTH(B8,1) -> 39872 | C9: 0.0687 | E9: =E8+1 -> 2013 | F9: =AVERAGEIFS($C$4:$C$201,$B$4:$B$201,">="&DATE(E9,1,1),$B$4:$B$201,"<="&DATE(E9,12,31)) -> 0.055833333
B10: =EOMONTH(B9,1) -> 39903 | C10: 0.0768 | E10: =E9+1 -> 2014 | F10: =AVERAGEIFS($C$4:$C$201,$B$4:$B$201,">="&DATE(E10,1,1),$B$4:$B$201,"<="&DATE(E10,12,31)) -> 0.05205 | H10: Average Implied ERP- | I10: 5 YRS | J10: =AVERAGE(F16:F20) -> 0.052785
B11: =EOMONTH(B10,1) -> 39933 | C11: 0.0701 | E11: =E10+1 -> 2015 | F11: =AVERAGEIFS($C$4:$C$201,$B$4:$B$201,">="&DATE(E11,1,1),$B$4:$B$201,"<="&DATE(E11,12,31)) -> 0.059758333
B12: =EOMONTH(B11,1) -> 39964 | C12: 0.0632 | E12: =E11+1 -> 2016 | F12: =AVERAGEIFS($C$4:$C$201,$B$4:$B$201,">="&DATE(E12,1,1),$B$4:$B$201,"<="&DATE(E12,12,31)) -> 0.062091667
B13: =EOMONTH(B12,1) -> 39994 | C13: 0.0594 | E13: =E12+1 -> 2017 | F13: =AVERAGEIFS($C$4:$C$201,$B$4:$B$201,">="&DATE(E13,1,1),$B$4:$B$201,"<="&DATE(E13,12,31)) -> 0.051908333
B14: =EOMONTH(B13,1) -> 40025 | C14: 0.0586 | E14: =E13+1 -> 2018 | F14: =AVERAGEIFS($C$4:$C$201,$B$4:$B$201,">="&DATE(E14,1,1),$B$4:$B$201,"<="&DATE(E14,12,31)) -> 0.0522
B15: =EOMONTH(B14,1) -> 40056 | C15: 0.0546 | E15: =E14+1 -> 2019 | F15: =AVERAGEIFS($C$4:$C$201,$B$4:$B$201,">="&DATE(E15,1,1),$B$4:$B$201,"<="&DATE(E15,12,31)) -> 0.056166667
B16: =EOMONTH(B15,1) -> 40086 | C16: 0.053 | E16: =E15+1 -> 2020 | F16: =AVERAGEIFS($C$4:$C$201,$B$4:$B$201,">="&DATE(E16,1,1),$B$4:$B$201,"<="&DATE(E16,12,31)) -> 0.052233333
B17: =EOMONTH(B16,1) -> 40117 | C17: 0.0486 | E17: =E16+1 -> 2021 | F17: =AVERAGEIFS($C$4:$C$201,$B$4:$B$201,">="&DATE(E17,1,1),$B$4:$B$201,"<="&DATE(E17,12,31)) -> 0.04345
B18: =EOMONTH(B17,1) -> 40147 | C18: 0.0497 | E18: =E17+1 -> 2022 | F18: =AVERAGEIFS($C$4:$C$201,$B$4:$B$201,">="&DATE(E18,1,1),$B$4:$B$201,"<="&DATE(E18,12,31)) -> 0.051933333
B19: =EOMONTH(B18,1) -> 40178 | C19: 0.0473 | E19: =E18+1 -> 2023 | F19: =AVERAGEIFS($C$4:$C$201,$B$4:$B$201,">="&DATE(E19,1,1),$B$4:$B$201,"<="&DATE(E19,12,31)) -> 0.056641667
B20: =EOMONTH(B19,1) -> 40209 | C20: 0.0436 | E20: =E19+1 -> 2024 | F20: =AVERAGEIFS($C$4:$C$201,$B$4:$B$201,">="&DATE(E20,1,1),$B$4:$B$201,"<="&DATE(E20,12,31)) -> 0.059666667
B21: =EOMONTH(B20,1) -> 40237 | C21: 0.0456
B22: =EOMONTH(B21,1) -> 40268 | C22: 0.0444 | E22: Source: NYU Stern website, by Prof. Aswath Damodarn
B23: =EOMONTH(B22,1) -> 40298 | C23: 0.0416
B24: =EOMONTH(B23,1) -> 40329 | C24: 0.0454
B25: =EOMONTH(B24,1) -> 40359 | C25: 0.0479
B26: =EOMONTH(B25,1) -> 40390 | C26: 0.051
B27: =EOMONTH(B26,1) -> 40421 | C27: 0.0478
B28: =EOMONTH(B27,1) -> 40451 | C28: 0.051
B29: =EOMONTH(B28,1) -> 40482 | C29: 0.0531
B30: =EOMONTH(B29,1) -> 40512 | C30: 0.0511
B31: =EOMONTH(B30,1) -> 40543 | C31: 0.0508
B32: =EOMONTH(B31,1) -> 40574 | C32: 0.052
B33: =EOMONTH(B32,1) -> 40602 | C33: 0.0507
B34: =EOMONTH(B33,1) -> 40633 | C34: 0.049
... B201: =EOMONTH(B200,1) -> 45716 | C201: 0.0606

Sheet s&pAllData
B2: Year | C2: S&P 500 | D2: Earnings Yield | E2: EPS | F2: Dividend Yield | G2: Dividend Amount | H2: Dividend + Buybacks | I2: Buyback Amount | J2: Buback Yield
B3: 1960 | C3: 58.11 | D3: 0.0534 | E3: =C3*D3 -> 3.103074 | F3: 0.0341 | G3: =F3*C3 -> 1.981551 | H3: - | I3: - | J3: -
B4: =B3+1 -> 1961 | C4: 71.55 | D4: 0.0471 | E4: =C4*D4 -> 3.370005 | F4: 0.0285 | G4: =F4*C4 -> 2.039175 | H4: - | I4: - | J4: -
B5: =B4+1 -> 1962 | C5: 63.1 | D5: 0.0581 | E5: =C5*D5 -> 3.66611 | F5: 0.034 | G5: =F5*C5 -> 2.1454 | H5: - | I5: - | J5: -
B6: =B5+1 -> 1963 | C6: 75.02 | D6: 0.0551 | E6: =C6*D6 -> 4.133602 | F6: 0.0313 | G6: =F6*C6 -> 2.348126 | H6: - | I6: - | J6: -
B7: =B6+1 -> 1964 | C7: 84.75 | D7: 0.0562 | E7: =C7*D7 -> 4.76295 | F7: 0.0305 | G7: =F7*C7 -> 2.584875 | H7: - | I7: - | J7: -
B8: =B7+1 -> 1965 | C8: 92.43 | D8: 0.0573 | E8: =C8*D8 -> 5.296239 | F8: 0.0306 | G8: =F8*C8 -> 2.828358 | H8: - | I8: - | J8: -
B9: =B8+1 -> 1966 | C9: 80.33 | D9: 0.0674 | E9: =C9*D9 -> 5.414242 | F9: 0.0359 | G9: =F9*C9 -> 2.883847 | H9: - | I9: - | J9: -
B10: =B9+1 -> 1967 | C10: 96.47 | D10: 0.0566 | E10: =C10*D10 -> 5.460202 | F10: 0.0309 | G10: =F10*C10 -> 2.980923 | H10: - | I10: - | J10: -
B11: =B10+1 -> 1968 | C11: 103.86 | D11: 0.0551 | E11: =C11*D11 -> 5.722686 | F11: 0.0293 | G11: =F11*C11 -> 3.043098 | H11: - | I11: - | J11: -
B12: =B11+1 -> 1969 | C12: 92.06 | D12: 0.0663 | E12: =C12*D12 -> 6.103578 | F12: 0.0352 | G12: =F12*C12 -> 3.240512 | H12: - | I12: - | J12: -
B13: =B12+1 -> 1970 | C13: 92.15 | D13: 0.0598 | E13: =C13*D13 -> 5.51057 | F13: 0.0346 | G13: =F13*C13 -> 3.18839 | H13: - | I13: - | J13: -
B14: =B13+1 -> 1971 | C14: 102.09 | D14: 0.0546 | E14: =C14*D14 -> 5.574114 | F14: 0.031 | G14: =F14*C14 -> 3.16479 | H14: - | I14: - | J14: -
B15: =B14+1 -> 1972 | C15: 118.05 | D15: 0.0523 | E15: =C15*D15 -> 6.174015 | F15: 0.027 | G15: =F15*C15 -> 3.18735 | H15: - | I15: - | J15: -
... B43: =B42+1 -> 2000 | C43: 1320.28 | D43: 0.0425 | E43: =C43*D43 -> 56.1119 | F43: 0.0123 | G43: =F43*C43 -> 16.239444 | H43: - | I43: - | J43: -
B44: =B43+1 -> 2001 | C44: 1148.09 | D44: 0.0338 | E44: =C44*D44 -> 38.805442 | F44: 0.0137 | G44: =F44*C44 -> 15.728833 | H44: 30.08 | I44: =H44-G44 -> 14.351167 | J44: =I44/C44 -> 0.012500037
B45: =B44+1 -> 2002 | C45: 879.82 | D45: 0.0523 | E45: =C45*D45 -> 46.014586 | F45: 0.0181 | G45: =F45*C45 -> 15.924742 | H45: 29.83 | I45: =H45-G45 -> 13.905258 | J45: =I45/C45 -> 0.015804662
B46: =B45+1 -> 2003 | C46: 1111.91 | D46: 0.0492 | E46: =C46*D46 -> 54.705972 | F46: 0.0161 | G46: =F46*C46 -> 17.901751 | H46: 31.58 | I46: =H46-G46 -> 13.678249 | J46: =I46/C46 -> 0.012301579
B47: =B46+1 -> 2004 | C47: 1211.92 | D47: 0.0558 | E47: =C47*D47 -> 67.625136 | F47: 0.0157 | G47: =F47*C47 -> 19.027144 | H47: 40.6 | I47: =H47-G47 -> 21.572856 | J47: =I47/C47 -> 0.017800561
B48: =B47+1 -> 2005 | C48: 1248.29 | D48: 0.0612 | E48: =C48*D48 -> 76.395348 | F48: 0.0179 | G48: =F48*C48 -> 22.344391 | H48: 61.17 | I48: =H48-G48 -> 38.825609 | J48: =I48/C48 -> 0.031103036
B49: =B48+1 -> 2006 | C49: 1418.3 | D49: 0.0618 | E49: =C49*D49 -> 87.65094 | F49: 0.0177 | G49: =F49*C49 -> 25.10391 | H49: 73.16 | I49: =H49-G49 -> 48.05609 | J49: =I49/C49 -> 0.033882881
B50: =B49+1 -> 2007 | C50: 1468.36 | D50: 0.0562 | E50: =C50*D50 -> 82.521832 | F50: 0.0192 | G50: =F50*C50 -> 28.192512 | H50: 95.36 | I50: =H50-G50 -> 67.167488 | J50: =I50/C50 -> 0.045743202
B51: =B50+1 -> 2008 | C51: 903.25 | D51: 0.0548 | E51: =C51*D51 -> 49.4981 | F51: 0.0315 | G51: =F51*C51 -> 28.452375 | H51: 67.52 | I51: =H51-G51 -> 39.067625 | J51: =I51/C51 -> 0.043252283
B52: =B51+1 -> 2009 | C52: 1115.1 | D52: 0.051 | E52: =C52*D52 -> 56.8701 | F52: 0.0197 | G52: =F52*C52 -> 21.96747 | H52: 37.43 | I52: =H52-G52 -> 15.46253 | J52: =I52/C52 -> 0.013866496
B53: =B52+1 -> 2010 | C53: 1257.64 | D53: 0.0666 | E53: =C53*D53 -> 83.758824 | F53: 0.018 | G53: =F53*C53 -> 22.63752 | H53: 55.53 | I53: =H53-G53 -> 32.89248 | J53: =I53/C53 -> 0.02615413
B54: =B53+1 -> 2011 | C54: 1257.6 | D54: 0.0767 | E54: =C54*D54 -> 96.45792 | F54: 0.0211 | G54: =F54*C54 -> 26.53536 | H54: 71.28 | I54: =H54-G54 -> 44.74464 | J54: =I54/C54 -> 0.035579389
B55: =B54+1 -> 2012 | C55: 1426.19 | D55: 0.0679 | E55: =C55*D55 -> 96.838301 | F55: 0.0219 | G55: =F55*C55 -> 31.233561 | H55: 75.9 | I55: =H55-G55 -> 44.666439 | J55: =I55/C55 -> 0.031318716
... B67: =B66+1 -> 2024 | C67: 5881.63 | D67: 0.0414 | E67: =C67*D67 -> 243.49948 | F67: 0.0125 | G67: =F67*C67 -> 73.520375 | H67: 182.8 | I67: =H67-G67 -> 109.27963 | J67: =I67/C67 -> 0.01857982
B69: Source: NYU Stern website, by Prof. Aswath Damodarn
